Workbook

Sheet Master Overview
A1: Robin - Site Audit & Analysis | Master Sheet
A2: Priority list (revenue, markets, flags) as provided by the user; audit columns pull live from the Issue Tracker. Blue = typed inputs, black = formulas.
A4: # | B4: Ahrefs project | C4: D2C net rev TTM (€k) | D4: Brand total, all ch. (€k) | E4: Brand total note | F4: Focus markets | G4: Flag | H4: D2C share of brand | I4: Audit status | J4: Audit deliverables | K4: Issues logged | L4: Open issues | M4: High / Critical open | N4: Affected URLs / rows | O4: Worksheet tabs in this file | P4: Key finding
A5: 1 | B5: Open Goaaal USA | C5: 1661 | D5: 3036 | E5: both stores | F5: US | G5: Only 21 kw tracked | H5: =IF(AND(ISNUMBER(C5),ISNUMBER(D5),D5<>0),C5/D5,"-") -> 0.54710145 | I5: =IF(K5=0,"Not started",IF(L5=0,"Complete","Audit delivered")) -> Audit delivered | J5: Blog content sheet + GSC countries; Duplicate content report; Site audit doc (images only) | K5: =COUNTIF('Issue Tracker'!$B$5:$B$84,B5) -> 1 | L5: =K5-COUNTIFS('Issue Tracker'!$B$5:$B$84,B5,'Issue Tracker'!$J$5:$J$84,"Fixed")-COUNTIFS('Issue Tracker'!$B$5:$B$84,B5,'Issue Tracker'!$J$5:$J$84,"Already Fixed") -> 1 | M5: =COUNTIFS('Issue Tracker'!$B$5:$B$84,B5,'Issue Tracker'!$I$5:$I$84,"High",'Issue Tracker'!$J$5:$J$84,"<>Fixed",'Issue Tracker'!$J$5:$J$84,"<>Already Fixed")+COUNTIFS('Issue Tracker'!$B$5:$B$84,B5,'Issue Tracker'!$I$5:$I$84,"Critical",'Issue Tracker'!$J$5:$J$84,"<>Fixed",'Issue Tracker'!$J$5:$J$84,"<>Already Fixed") -> 1 | N5: =SUMIF('Issue Tracker'!$B$5:$B$84,B5,'Issue Tracker'!$G$5:$G$84) -> 3 | O5: OGU_Blog Pages, OGU_Countries, OGU_Filters | P5: Duplicate blog content vs opengoaaal.com already triggered a penalty; US clicks 4.3k vs 10.4k prior 6 mo
A6: 2 | B6: Bigbatbox (WildYard) | C6: 325 | D6: 1650 | F6: US 49, DE 7 | G6: Unverified | H6: =IF(AND(ISNUMBER(C6),ISNUMBER(D6),D6<>0),C6/D6,"-") -> 0.1969697 | I6: =IF(K6=0,"Not started",IF(L6=0,"Complete","Audit delivered")) -> Audit delivered | J6: Site audit workbook (16 tabs); Site audit doc; Issues doc (translation) | K6: =COUNTIF('Issue Tracker'!$B$5:$B$84,B6) -> 19 | L6: =K6-COUNTIFS('Issue Tracker'!$B$5:$B$84,B6,'Issue Tracker'!$J$5:$J$84,"Fixed")-COUNTIFS('Issue Tracker'!$B$5:$B$84,B6,'Issue Tracker'!$J$5:$J$84,"Already Fixed") -> 19 | M6: =COUNTIFS('Issue Tracker'!$B$5:$B$84,B6,'Issue Tracker'!$I$5:$I$84,"High",'Issue Tracker'!$J$5:$J$84,"<>Fixed",'Issue Tracker'!$J$5:$J$84,"<>Already Fixed")+COUNTIFS('Issue Tracker'!$B$5:$B$84,B6,'Issue Tracker'!$I$5:$I$84,"Critical",'Issue Tracker'!$J$5:$J$84,"<>Fixed",'Issue Tracker'!$J$5:$J$84,"<>Already Fixed") -> 10 | N6: =SUMIF('Issue Tracker'!$B$5:$B$84,B6,'Issue Tracker'!$G$5:$G$84) -> 4912 | O6: BBB_Master Checklist, BBB_Broken Links, BBB_Broken Internal Link, BBB_Pages Marked No Index, BBB_Not submitted to IndexNow, BBB_Page has links to broken pa, BBB_Redirecting URLs, BBB_Too Long Meta Title, BBB_Too Long Meta Description, BBB_Missing H1 Tag, BBB_Missing Meta Description, BBB_Multiple H1 Tag, BBB_Page and SERP titles do not, BBB_Twitter and Open Graph tags, BBB_Image file size too large, BBB_Images Missing ALT text | P6: Manual action for thin content; 170/761 pages not indexed; 'bat house' impressions down
A7: 3 | B7: Luonkos Finland (.fi) | C7: 323 | D7: 513 | E7: both stores | F7: FI | H7: =IF(AND(ISNUMBER(C7),ISNUMBER(D7),D7<>0),C7/D7,"-") -> 0.62962963 | I7: =IF(K7=0,"Not started",IF(L7=0,"Complete","Audit delivered")) -> Audit delivered | J7: Audit & Analysis doc; Merge 404 report; Draft audit (not final) | K7: =COUNTIF('Issue Tracker'!$B$5:$B$84,B7) -> 6 | L7: =K7-COUNTIFS('Issue Tracker'!$B$5:$B$84,B7,'Issue Tracker'!$J$5:$J$84,"Fixed")-COUNTIFS('Issue Tracker'!$B$5:$B$84,B7,'Issue Tracker'!$J$5:$J$84,"Already Fixed") -> 6 | M7: =COUNTIFS('Issue Tracker'!$B$5:$B$84,B7,'Issue Tracker'!$I$5:$I$84,"High",'Issue Tracker'!$J$5:$J$84,"<>Fixed",'Issue Tracker'!$J$5:$J$84,"<>Already Fixed")+COUNTIFS('Issue Tracker'!$B$5:$B$84,B7,'Issue Tracker'!$I$5:$I$84,"Critical",'Issue Tracker'!$J$5:$J$84,"<>Fixed",'Issue Tracker'!$J$5:$J$84,"<>Already Fixed") -> 4 | N7: =SUMIF('Issue Tracker'!$B$5:$B$84,B7,'Issue Tracker'!$G$5:$G$84) -> 0 | O7: - | P7: After .fi/.com merge, EN & SV URLs with traffic return 404 - redirect map needed
A8: 4 | B8: Senseball | C8: 119 | D8: 682 | F8: US 40, +UK/DE/FR/ES/IT | G8: Declining fast (H2 39k vs H1 79k) | H8: =IF(AND(ISNUMBER(C8),ISNUMBER(D8),D8<>0),C8/D8,"-") -> 0.1744868 | I8: =IF(K8=0,"Not started",IF(L8=0,"Complete","Audit delivered")) -> Not started | J8: No audit file in folder | K8: =COUNTIF('Issue Tracker'!$B$5:$B$84,B8) -> 0 | L8: =K8-COUNTIFS('Issue Tracker'!$B$5:$B$84,B8,'Issue Tracker'!$J$5:$J$84,"Fixed")-COUNTIFS('Issue Tracker'!$B$5:$B$84,B8,'Issue Tracker'!$J$5:$J$84,"Already Fixed") -> 0 | M8: =COUNTIFS('Issue Tracker'!$B$5:$B$84,B8,'Issue Tracker'!$I$5:$I$84,"High",'Issue Tracker'!$J$5:$J$84,"<>Fixed",'Issue Tracker'!$J$5:$J$84,"<>Already Fixed")+COUNTIFS('Issue Tracker'!$B$5:$B$84,B8,'Issue Tracker'!$I$5:$I$84,"Critical",'Issue Tracker'!$J$5:$J$84,"<>Fixed",'Issue Tracker'!$J$5:$J$84,"<>Already Fixed") -> 0 | N8: =SUMIF('Issue Tracker'!$B$5:$B$84,B8,'Issue Tracker'!$G$5:$G$84) -> 0 | O8: -
A9: 5 | B9: Indo | C9: 117 | D9: 1750 | F9: US, UK, FI, CA, AU, DE, PL, FR, DK, CZ | G9: Unverified; 10 markets on 86 kw = thin | H9: =IF(AND(ISNUMBER(C9),ISNUMBER(D9),D9<>0),C9/D9,"-") -> 0.066857143 | I9: =IF(K9=0,"Not started",IF(L9=0,"Complete","Audit delivered")) -> Not started | J9: No audit file in folder | K9: =COUNTIF('Issue Tracker'!$B$5:$B$84,B9) -> 0 | L9: =K9-COUNTIFS('Issue Tracker'!$B$5:$B$84,B9,'Issue Tracker'!$J$5:$J$84,"Fixed")-COUNTIFS('Issue Tracker'!$B$5:$B$84,B9,'Issue Tracker'!$J$5:$J$84,"Already Fixed") -> 0 | M9: =COUNTIFS('Issue Tracker'!$B$5:$B$84,B9,'Issue Tracker'!$I$5:$I$84,"High",'Issue Tracker'!$J$5:$J$84,"<>Fixed",'Issue Tracker'!$J$5:$J$84,"<>Already Fixed")+COUNTIFS('Issue Tracker'!$B$5:$B$84,B9,'Issue Tracker'!$I$5:$I$84,"Critical",'Issue Tracker'!$J$5:$J$84,"<>Fixed",'Issue Tracker'!$J$5:$J$84,"<>Already Fixed") -> 0 | N9: =SUMIF('Issue Tracker'!$B$5:$B$84,B9,'Issue Tracker'!$G$5:$G$84) -> 0 | O9: -
A10: 6 | B10: Opengoaaal UK-EU | C10: 91 | F10: UK 20, DE/FR/SE/IT/ES | G10: 70 kw for 5% of Open Goaaal D2C | H10: =IF(AND(ISNUMBER(C10),ISNUMBER(D10),D10<>0),C10/D10,"-") -> - | I10: =IF(K10=0,"Not started",IF(L10=0,"Complete","Audit delivered")) -> Audit delivered | J10: Duplicate content report (shared with USA) | K10: =COUNTIF('Issue Tracker'!$B$5:$B$84,B10) -> 1 | L10: =K10-COUNTIFS('Issue Tracker'!$B$5:$B$84,B10,'Issue Tracker'!$J$5:$J$84,"Fixed")-COUNTIFS('Issue Tracker'!$B$5:$B$84,B10,'Issue Tracker'!$J$5:$J$84,"Already Fixed") -> 1 | M10: =COUNTIFS('Issue Tracker'!$B$5:$B$84,B10,'Issue Tracker'!$I$5:$I$84,"High",'Issue Tracker'!$J$5:$J$84,"<>Fixed",'Issue Tracker'!$J$5:$J$84,"<>Already Fixed")+COUNTIFS('Issue Tracker'!$B$5:$B$84,B10,'Issue Tracker'!$I$5:$I$84,"Critical",'Issue Tracker'!$J$5:$J$84,"<>Fixed",'Issue Tracker'!$J$5:$J$84,"<>Already Fixed") -> 1 | N10: =SUMIF('Issue Tracker'!$B$5:$B$84,B10,'Issue Tracker'!$G$5:$G$84) -> 3 | O10: - | P10: Duplicate blog content shared with opengoaaalusa.com
A11: 7 | B11: Bodyotics | C11: 71 | D11: 1404 | F11: US, UK, DE, FI | H11: =IF(AND(ISNUMBER(C11),ISNUMBER(D11),D11<>0),C11/D11,"-") -> 0.050569801 | I11: =IF(K11=0,"Not started",IF(L11=0,"Complete","Audit delivered")) -> Audit delivered | J11: Analysis doc | K11: =COUNTIF('Issue Tracker'!$B$5:$B$84,B11) -> 2 | L11: =K11-COUNTIFS('Issue Tracker'!$B$5:$B$84,B11,'Issue Tracker'!$J$5:$J$84,"Fixed")-COUNTIFS('Issue Tracker'!$B$5:$B$84,B11,'Issue Tracker'!$J$5:$J$84,"Already Fixed") -> 2 | M11: =COUNTIFS('Issue Tracker'!$B$5:$B$84,B11,'Issue Tracker'!$I$5:$I$84,"High",'Issue Tracker'!$J$5:$J$84,"<>Fixed",'Issue Tracker'!$J$5:$J$84,"<>Already Fixed")+COUNTIFS('Issue Tracker'!$B$5:$B$84,B11,'Issue Tracker'!$I$5:$I$84,"Critical",'Issue Tracker'!$J$5:$J$84,"<>Fixed",'Issue Tracker'!$J$5:$J$84,"<>Already Fixed") -> 1 | N11: =SUMIF('Issue Tracker'!$B$5:$B$84,B11,'Issue Tracker'!$G$5:$G$84) -> 0 | O11: - | P11: Wrong language URLs ranking in DE / NL / FR
A12: 8 | B12: ANSWR US (3P) | C12: 60 | D12: 232 | F12: US | G12: 3P - keep out of 1P totals | H12: =IF(AND(ISNUMBER(C12),ISNUMBER(D12),D12<>0),C12/D12,"-") -> 0.25862069 | I12: =IF(K12=0,"Not started",IF(L12=0,"Complete","Audit delivered")) -> Not started | J12: No audit file in folder | K12: =COUNTIF('Issue Tracker'!$B$5:$B$84,B12) -> 0 | L12: =K12-COUNTIFS('Issue Tracker'!$B$5:$B$84,B12,'Issue Tracker'!$J$5:$J$84,"Fixed")-COUNTIFS('Issue Tracker'!$B$5:$B$84,B12,'Issue Tracker'!$J$5:$J$84,"Already Fixed") -> 0 | M12: =COUNTIFS('Issue Tracker'!$B$5:$B$84,B12,'Issue Tracker'!$I$5:$I$84,"High",'Issue Tracker'!$J$5:$J$84,"<>Fixed",'Issue Tracker'!$J$5:$J$84,"<>Already Fixed")+COUNTIFS('Issue Tracker'!$B$5:$B$84,B12,'Issue Tracker'!$I$5:$I$84,"Critical",'Issue Tracker'!$J$5:$J$84,"<>Fixed",'Issue Tracker'!$J$5:$J$84,"<>Already Fixed") -> 0 | N12: =SUMIF('Issue Tracker'!$B$5:$B$84,B12,'Issue Tracker'!$G$5:$G$84) -> 0 | O12: -
A13: 9 | B13: Angles90 | C13: 56 | D13: 352 | F13: US 40, DE 8 | H13: =IF(AND(ISNUMBER(C13),ISNUMBER(D13),D13<>0),C13/D13,"-") -> 0.15909091 | I13: =IF(K13=0,"Not started",IF(L13=0,"Complete","Audit delivered")) -> Not started | J13: No audit file in folder | K13: =COUNTIF('Issue Tracker'!$B$5:$B$84,B13) -> 0 | L13: =K13-COUNTIFS('Issue Tracker'!$B$5:$B$84,B13,'Issue Tracker'!$J$5:$J$84,"Fixed")-COUNTIFS('Issue Tracker'!$B$5:$B$84,B13,'Issue Tracker'!$J$5:$J$84,"Already Fixed") -> 0 | M13: =COUNTIFS('Issue Tracker'!$B$5:$B$84,B13,'Issue Tracker'!$I$5:$I$84,"High",'Issue Tracker'!$J$5:$J$84,"<>Fixed",'Issue Tracker'!$J$5:$J$84,"<>Already Fixed")+COUNTIFS('Issue Tracker'!$B$5:$B$84,B13,'Issue Tracker'!$I$5:$I$84,"Critical",'Issue Tracker'!$J$5:$J$84,"<>Fixed",'Issue Tracker'!$J$5:$J$84,"<>Already Fixed") -> 0 | N13: =SUMIF('Issue Tracker'!$B$5:$B$84,B13,'Issue Tracker'!$G$5:$G$84) -> 0 | O13: -
A14: 10 | B14: Happy Sinks | C14: 54 | D14: 668 | F14: US 50 | G14: Unverified | H14: =IF(AND(ISNUMBER(C14),ISNUMBER(D14),D14<>0),C14/D14,"-") -> 0.080838323 | I14: =IF(K14=0,"Not started",IF(L14=0,"Complete","Audit delivered")) -> Audit delivered | J14: URL report workbook (5 tabs); SEO audit doc | K14: =COUNTIF('Issue Tracker'!$B$5:$B$84,B14) -> 8 | L14: =K14-COUNTIFS('Issue Tracker'!$B$5:$B$84,B14,'Issue Tracker'!$J$5:$J$84,"Fixed")-COUNTIFS('Issue Tracker'!$B$5:$B$84,B14,'Issue Tracker'!$J$5:$J$84,"Already Fixed") -> 8 | M14: =COUNTIFS('Issue Tracker'!$B$5:$B$84,B14,'Issue Tracker'!$I$5:$I$84,"High",'Issue Tracker'!$J$5:$J$84,"<>Fixed",'Issue Tracker'!$J$5:$J$84,"<>Already Fixed")+COUNTIFS('Issue Tracker'!$B$5:$B$84,B14,'Issue Tracker'!$I$5:$I$84,"Critical",'Issue Tracker'!$J$5:$J$84,"<>Fixed",'Issue Tracker'!$J$5:$J$84,"<>Already Fixed") -> 2 | N14: =SUMIF('Issue Tracker'!$B$5:$B$84,B14,'Issue Tracker'!$G$5:$G$84) -> 1704 | O14: HS_Missing H1 Tag, HS_Multiple H1 Tag, HS_Too Long Meta Title, HS_Too Long Meta Description, HS_Pages droped from top 10 Pos | P14: Pages dropped out of top 10 (homepage 249 -> 0 traffic); slow site; untranslated slugs
A15: 11 | B15: Striking Viking | C15: 53 | D15: 4107 | F15: US 31, DE 8 | G15: Biggest brand, 1.3% D2C | H15: =IF(AND(ISNUMBER(C15),ISNUMBER(D15),D15<>0),C15/D15,"-") -> 0.012904797 | I15: =IF(K15=0,"Not started",IF(L15=0,"Complete","Audit delivered")) -> Audit delivered | J15: Issues workbook (12 tabs) | K15: =COUNTIF('Issue Tracker'!$B$5:$B$84,B15) -> 12 | L15: =K15-COUNTIFS('Issue Tracker'!$B$5:$B$84,B15,'Issue Tracker'!$J$5:$J$84,"Fixed")-COUNTIFS('Issue Tracker'!$B$5:$B$84,B15,'Issue Tracker'!$J$5:$J$84,"Already Fixed") -> 12 | M15: =COUNTIFS('Issue Tracker'!$B$5:$B$84,B15,'Issue Tracker'!$I$5:$I$84,"High",'Issue Tracker'!$J$5:$J$84,"<>Fixed",'Issue Tracker'!$J$5:$J$84,"<>Already Fixed")+COUNTIFS('Issue Tracker'!$B$5:$B$84,B15,'Issue Tracker'!$I$5:$I$84,"Critical",'Issue Tracker'!$J$5:$J$84,"<>Fixed",'Issue Tracker'!$J$5:$J$84,"<>Already Fixed") -> 5 | N15: =SUMIF('Issue Tracker'!$B$5:$B$84,B15,'Issue Tracker'!$G$5:$G$84) -> 3127 | O15: SV_4xx, SV_3xx Redirection, SV_Page has links to broken pag, SV_Meta description too long, SV_Title too long, SV_Missing H1, SV_Meta description too short, SV_Meta description tag missing, SV_Multiple H1 tags, SV_Pages have high AI content l, SV_Missing alt text, SV_External 4XX | P15: 4xx / broken links incl. external 404s; 1.2k long meta descriptions
A16: 12 | B16: Luxsports (LUX) | C16: 50 | D16: 2004 | F16: US, UK, DE, ES, FR | H16: =IF(AND(ISNUMBER(C16),ISNUMBER(D16),D16<>0),C16/D16,"-") -> 0.0249501 | I16: =IF(K16=0,"Not started",IF(L16=0,"Complete","Audit delivered")) -> Audit delivered | J16: Technical SEO audit doc | K16: =COUNTIF('Issue Tracker'!$B$5:$B$84,B16) -> 9 | L16: =K16-COUNTIFS('Issue Tracker'!$B$5:$B$84,B16,'Issue Tracker'!$J$5:$J$84,"Fixed")-COUNTIFS('Issue Tracker'!$B$5:$B$84,B16,'Issue Tracker'!$J$5:$J$84,"Already Fixed") -> 8 | M16: =COUNTIFS('Issue Tracker'!$B$5:$B$84,B16,'Issue Tracker'!$I$5:$I$84,"High",'Issue Tracker'!$J$5:$J$84,"<>Fixed",'Issue Tracker'!$J$5:$J$84,"<>Already Fixed")+COUNTIFS('Issue Tracker'!$B$5:$B$84,B16,'Issue Tracker'!$I$5:$I$84,"Critical",'Issue Tracker'!$J$5:$J$84,"<>Fixed",'Issue Tracker'!$J$5:$J$84,"<>Already Fixed") -> 4 | N16: =SUMIF('Issue Tracker'!$B$5:$B$84,B16,'Issue Tracker'!$G$5:$G$84) -> 3 | O16: - | P16: en-NZ hreflang points to /en-au; overlapping & empty collections
A17: - | B17: Babysunnies | G17: Not on priority list - audit delivered | H17: =IF(AND(ISNUMBER(C17),ISNUMBER(D17),D17<>0),C17/D17,"-") -> - | I17: =IF(K17=0,"Not started",IF(L17=0,"Complete","Audit delivered")) -> Audit delivered | J17: Technical SEO audit doc (3 versions - latest used) | K17: =COUNTIF('Issue Tracker'!$B$5:$B$84,B17) -> 10 | L17: =K17-COUNTIFS('Issue Tracker'!$B$5:$B$84,B17,'Issue Tracker'!$J$5:$J$84,"Fixed")-COUNTIFS('Issue Tracker'!$B$5:$B$84,B17,'Issue Tracker'!$J$5:$J$84,"Already Fixed") -> 10 | M17: =COUNTIFS('Issue Tracker'!$B$5:$B$84,B17,'Issue Tracker'!$I$5:$I$84,"High",'Issue Tracker'!$J$5:$J$84,"<>Fixed",'Issue Tracker'!$J$5:$J$84,"<>Already Fixed")+COUNTIFS('Issue Tracker'!$B$5:$B$84,B17,'Issue Tracker'!$I$5:$I$84,"Critical",'Issue Tracker'!$J$5:$J$84,"<>Fixed",'Issue Tracker'!$J$5:$J$84,"<>Already Fixed") -> 1 | N17: =SUMIF('Issue Tracker'!$B$5:$B$84,B17,'Issue Tracker'!$G$5:$G$84) -> 150 | O17: - | P17: robots.txt keeps 120 dead URLs indexed
A18: - | B18: Coachsoak | G18: Not on priority list - audit delivered | H18: =IF(AND(ISNUMBER(C18),ISNUMBER(D18),D18<>0),C18/D18,"-") -> - | I18: =IF(K18=0,"Not started",IF(L18=0,"Complete","Audit delivered")) -> Audit delivered | J18: SEO audit & analysis doc | K18: =COUNTIF('Issue Tracker'!$B$5:$B$84,B18) -> 12 | L18: =K18-COUNTIFS('Issue Tracker'!$B$5:$B$84,B18,'Issue Tracker'!$J$5:$J$84,"Fixed")-COUNTIFS('Issue Tracker'!$B$5:$B$84,B18,'Issue Tracker'!$J$5:$J$84,"Already Fixed") -> 12 | M18: =COUNTIFS('Issue Tracker'!$B$5:$B$84,B18,'Issue Tracker'!$I$5:$I$84,"High",'Issue Tracker'!$J$5:$J$84,"<>Fixed",'Issue Tracker'!$J$5:$J$84,"<>Already Fixed")+COUNTIFS('Issue Tracker'!$B$5:$B$84,B18,'Issue Tracker'!$I$5:$I$84,"Critical",'Issue Tracker'!$J$5:$J$84,"<>Fixed",'Issue Tracker'!$J$5:$J$84,"<>Already Fixed") -> 5 | N18: =SUMIF('Issue Tracker'!$B$5:$B$84,B18,'Issue Tracker'!$G$5:$G$84) -> 5 | O18: - | P18: Sep clicks -40% vs Jul; broken sitemap in GSC
B19: Total priority list (1P, excl. ANSWR 3P) | C19: =SUM(C5:C16)-C12 -> 2920 | D19: =SUM(D5:D16)-D12 -> 16166 | H19: =IF(D19<>0,C19/D19,"-") -> 0.18062601 | K19: =SUM(K5:K18) -> 80 | L19: =SUM(L5:L18) -> 79 | M19: =SUM(M5:M18) -> 34 | N19: =SUM(N5:N18) -> 9907
B20: Brand total for Opengoaaal UK-EU is blank in the source list; Open Goaaal USA / Luonkos brand totals cover both stores. Revenue, markets and flags: from the user's priority list screenshot (12-Oct-2026).
B22: Issue status summary
B23: Status | C23: Issues | D23: Share
B24: Need to Fix | C24: =COUNTIF('Issue Tracker'!$J$5:$J$84,B24) -> 78 | D24: =IF($C$30=0,0,C24/$C$30) -> 0.975
B25: In Progress | C25: =COUNTIF('Issue Tracker'!$J$5:$J$84,B25) -> 0 | D25: =IF($C$30=0,0,C25/$C$30) -> 0
B26: To Validate | C26: =COUNTIF('Issue Tracker'!$J$5:$J$84,B26) -> 1 | D26: =IF($C$30=0,0,C26/$C$30) -> 0.0125
B27: Fixed | C27: =COUNTIF('Issue Tracker'!$J$5:$J$84,B27) -> 0 | D27: =IF($C$30=0,0,C27/$C$30) -> 0
B28: Already Fixed | C28: =COUNTIF('Issue Tracker'!$J$5:$J$84,B28) -> 1 | D28: =IF($C$30=0,0,C28/$C$30) -> 0.0125
B29: Won't Fix | C29: =COUNTIF('Issue Tracker'!$J$5:$J$84,B29) -> 0 | D29: =IF($C$30=0,0,C29/$C$30) -> 0
B30: Total | C30: =SUM(C24:C29) -> 80 | D30: =SUM(D24:D29) -> 1
B31: Legend: blue = typed input from source; black = formula; yellow cells on Issue Tracker = edit Priority / Status / Owner / Due date / Notes.

Sheet Issue Tracker
A1: Issue Tracker - all projects
A2: One row per issue. Counts in black are live formulas on the project tabs; blue counts are typed from the Word reports. Edit Priority / Status / Owner / Notes (yellow).
A4: # | B4: Project | C4: Issue | D4: Category | E4: Source | F4: Source file | G4: Affected URLs / rows | H4: Open tab | I4: Priority | J4: Status | K4: Owner | L4: Due date | M4: Notes
A5: 1 | B5: Bigbatbox (WildYard) | C5: Broken links (4xx pages) | D5: Links & Status Codes | E5: Sheet | F5: Bigbatbox - Site Audit.xlsx | G5: =COUNTA('BBB_Broken Links'!B2:B32) -> 31 | H5: =HYPERLINK("#'BBB_Broken Links'!A1","BBB_Broken Links") -> BBB_Broken Links | I5: High | J5: Need to Fix
A6: 2 | B6: Bigbatbox (WildYard) | C6: Broken Internal Link | D6: Links & Status Codes | E6: Sheet | F6: Bigbatbox - Site Audit.xlsx | G6: =COUNTA('BBB_Broken Internal Link'!B2:B32) -> 31 | H6: =HYPERLINK("#'BBB_Broken Internal Link'!A1","BBB_Broken Internal Link") -> BBB_Broken Internal Link | I6: High | J6: Need to Fix
A7: 3 | B7: Bigbatbox (WildYard) | C7: Pages Marked No Index | D7: Indexing / Intl / Content | E7: Sheet | F7: Bigbatbox - Site Audit.xlsx | G7: =COUNTA('BBB_Pages Marked No Index'!B2:B6) -> 5 | H7: =HYPERLINK("#'BBB_Pages Marked No Index'!A1","BBB_Pages Marked No Index") -> BBB_Pages Marked No Index | I7: High | J7: Need to Fix
A8: 4 | B8: Bigbatbox (WildYard) | C8: URLs not submitted to IndexNow | D8: Indexing / Intl / Content | E8: Sheet | F8: Bigbatbox - Site Audit.xlsx | G8: =COUNTA('BBB_Not submitted to IndexNow'!B2:B2111) -> 2110 | H8: =HYPERLINK("#'BBB_Not submitted to IndexNow'!A1","BBB_Not submitted to IndexNow") -> BBB_Not submitted to IndexNow | I8: High | J8: Need to Fix
A9: 5 | B9: Bigbatbox (WildYard) | C9: Page has links to broken page | D9: Links & Status Codes | E9: Sheet | F9: Bigbatbox - Site Audit.xlsx | G9: =COUNTA('BBB_Page has links to broken pa'!B2:B28) -> 27 | H9: =HYPERLINK("#'BBB_Page has links to broken pa'!A1","BBB_Page has links to broken pa") -> BBB_Page has links to broken pa | I9: High | J9: Need to Fix
A10: 6 | B10: Bigbatbox (WildYard) | C10: Redirecting URLs | D10: Links & Status Codes | E10: Sheet | F10: Bigbatbox - Site Audit.xlsx | G10: =COUNTA('BBB_Redirecting URLs'!B2:B33) -> 32 | H10: =HYPERLINK("#'BBB_Redirecting URLs'!A1","BBB_Redirecting URLs") -> BBB_Redirecting URLs | I10: High | J10: Need to Fix
A11: 7 | B11: Bigbatbox (WildYard) | C11: Too Long Meta Title | D11: On-page Meta & Headings | E11: Sheet | F11: Bigbatbox - Site Audit.xlsx | G11: =COUNTA('BBB_Too Long Meta Title'!B2:B1747) -> 1746 | H11: =HYPERLINK("#'BBB_Too Long Meta Title'!A1","BBB_Too Long Meta Title") -> BBB_Too Long Meta Title | I11: Medium | J11: Need to Fix
A12: 8 | B12: Bigbatbox (WildYard) | C12: Too Long Meta Description | D12: On-page Meta & Headings | E12: Sheet | F12: Bigbatbox - Site Audit.xlsx | G12: =COUNTA('BBB_Too Long Meta Description'!B2:B193) -> 192 | H12: =HYPERLINK("#'BBB_Too Long Meta Description'!A1","BBB_Too Long Meta Description") -> BBB_Too Long Meta Description | I12: Medium | J12: Need to Fix
A13: 9 | B13: Bigbatbox (WildYard) | C13: Missing H1 Tag | D13: On-page Meta & Headings | E13: Sheet | F13: Bigbatbox - Site Audit.xlsx | G13: =COUNTA('BBB_Missing H1 Tag'!B2:B109) -> 108 | H13: =HYPERLINK("#'BBB_Missing H1 Tag'!A1","BBB_Missing H1 Tag") -> BBB_Missing H1 Tag | I13: Medium | J13: Need to Fix
A14: 10 | B14: Bigbatbox (WildYard) | C14: Missing Meta Description | D14: On-page Meta & Headings | E14: Sheet | F14: Bigbatbox - Site Audit.xlsx | G14: =COUNTA('BBB_Missing Meta Description'!B2:B7) -> 6 | H14: =HYPERLINK("#'BBB_Missing Meta Description'!A1","BBB_Missing Meta Description") -> BBB_Missing Meta Description | I14: Medium | J14: Need to Fix
A15: 11 | B15: Bigbatbox (WildYard) | C15: Multiple H1 Tag | D15: On-page Meta & Headings | E15: Sheet | F15: Bigbatbox - Site Audit.xlsx | G15: =COUNTA('BBB_Multiple H1 Tag'!B2:B291) -> 290 | H15: =HYPERLINK("#'BBB_Multiple H1 Tag'!A1","BBB_Multiple H1 Tag") -> BBB_Multiple H1 Tag | I15: Medium | J15: Need to Fix
A16: 12 | B16: Bigbatbox (WildYard) | C16: Page and SERP titles do not match | D16: On-page Meta & Headings | E16: Sheet | F16: Bigbatbox - Site Audit.xlsx | G16: =COUNTA('BBB_Page and SERP titles do not'!B2:B30) -> 29 | H16: =HYPERLINK("#'BBB_Page and SERP titles do not'!A1","BBB_Page and SERP titles do not") -> BBB_Page and SERP titles do not | I16: Medium | J16: Need to Fix
A17: 13 | B17: Bigbatbox (WildYard) | C17: Twitter & Open Graph tags incomplete | D17: Media / Markup | E17: Sheet | F17: Bigbatbox - Site Audit.xlsx | G17: =COUNTA('BBB_Twitter and Open Graph tags'!B2:B7) -> 6 | H17: =HYPERLINK("#'BBB_Twitter and Open Graph tags'!A1","BBB_Twitter and Open Graph tags") -> BBB_Twitter and Open Graph tags | I17: Low | J17: Need to Fix
A18: 14 | B18: Bigbatbox (WildYard) | C18: Image file size too large | D18: Performance & Media | E18: Sheet | F18: Bigbatbox - Site Audit.xlsx | G18: =COUNTA('BBB_Image file size too large'!B2:B96) -> 95 | H18: =HYPERLINK("#'BBB_Image file size too large'!A1","BBB_Image file size too large") -> BBB_Image file size too large | I18: Medium | J18: Need to Fix
A19: 15 | B19: Bigbatbox (WildYard) | C19: Images Missing ALT text | D19: Performance & Media | E19: Sheet | F19: Bigbatbox - Site Audit.xlsx | G19: =COUNTA('BBB_Images Missing ALT text'!B2:B7) -> 6 | H19: =HYPERLINK("#'BBB_Images Missing ALT text'!A1","BBB_Images Missing ALT text") -> BBB_Images Missing ALT text | I19: Medium | J19: Need to Fix
A20: 16 | B20: Happy Sinks | C20: Missing H1 Tag | D20: On-page Meta & Headings | E20: Sheet | F20: https_happy-sinks.com_ - URL Report.xlsx | G20: =COUNTA('HS_Missing H1 Tag'!A2:A175) -> 174 | H20: =HYPERLINK("#'HS_Missing H1 Tag'!A1","HS_Missing H1 Tag") -> HS_Missing H1 Tag | I20: Medium | J20: Need to Fix
A21: 17 | B21: Happy Sinks | C21: Multiple H1 Tag | D21: On-page Meta & Headings | E21: Sheet | F21: https_happy-sinks.com_ - URL Report.xlsx | G21: =COUNTA('HS_Multiple H1 Tag'!A2:A103) -> 102 | H21: =HYPERLINK("#'HS_Multiple H1 Tag'!A1","HS_Multiple H1 Tag") -> HS_Multiple H1 Tag | I21: Medium | J21: Need to Fix
A22: 18 | B22: Happy Sinks | C22: Too Long Meta Title | D22: On-page Meta & Headings | E22: Sheet | F22: https_happy-sinks.com_ - URL Report.xlsx | G22: =COUNTA('HS_Too Long Meta Title'!A2:A335) -> 334 | H22: =HYPERLINK("#'HS_Too Long Meta Title'!A1","HS_Too Long Meta Title") -> HS_Too Long Meta Title | I22: Medium | J22: Need to Fix
A23: 19 | B23: Happy Sinks | C23: Too Long Meta Description | D23: On-page Meta & Headings | E23: Sheet | F23: https_happy-sinks.com_ - URL Report.xlsx | G23: =COUNTA('HS_Too Long Meta Description'!A2:A997) -> 996 | H23: =HYPERLINK("#'HS_Too Long Meta Description'!A1","HS_Too Long Meta Description") -> HS_Too Long Meta Description | I23: Medium | J23: Need to Fix
A24: 20 | B24: Happy Sinks | C24: Pages dropped from top-10 positions | D24: Indexing / Intl / Content | E24: Sheet | F24: https_happy-sinks.com_ - URL Report.xlsx | G24: =COUNTA('HS_Pages droped from top 10 Pos'!A2:A99) -> 98 | H24: =HYPERLINK("#'HS_Pages droped from top 10 Pos'!A1","HS_Pages droped from top 10 Pos") -> HS_Pages droped from top 10 Pos | I24: High | J24: Need to Fix
A25: 21 | B25: Striking Viking | C25: 4xx | D25: Links & Status Codes | E25: Sheet | F25: striking-viking - Issues.xlsx | G25: =COUNTA(SV_4xx!B5:B85) -> 81 | H25: =HYPERLINK("#'SV_4xx'!A1","SV_4xx") -> SV_4xx | I25: High | J25: Need to Fix
A26: 22 | B26: Striking Viking | C26: 3xx Redirection | D26: Links & Status Codes | E26: Sheet | F26: striking-viking - Issues.xlsx | G26: =COUNTA('SV_3xx Redirection'!A6:A215) -> 210 | H26: =HYPERLINK("#'SV_3xx Redirection'!A1","SV_3xx Redirection") -> SV_3xx Redirection | I26: High | J26: Need to Fix
A27: 23 | B27: Striking Viking | C27: Page has links to broken page | D27: Links & Status Codes | E27: Sheet | F27: striking-viking - Issues.xlsx | G27: =COUNTA('SV_Page has links to broken pag'!B5:B70) -> 66 | H27: =HYPERLINK("#'SV_Page has links to broken pag'!A1","SV_Page has links to broken pag") -> SV_Page has links to broken pag | I27: High | J27: Need to Fix
A28: 24 | B28: Striking Viking | C28: Meta description too long | D28: On-page Meta & Headings | E28: Sheet | F28: striking-viking - Issues.xlsx | G28: =COUNTA('SV_Meta description too long'!C5:C1220) -> 1216 | H28: =HYPERLINK("#'SV_Meta description too long'!A1","SV_Meta description too long") -> SV_Meta description too long | I28: Medium | J28: Need to Fix
A29: 25 | B29: Striking Viking | C29: Title too long | D29: On-page Meta & Headings | E29: Sheet | F29: striking-viking - Issues.xlsx | G29: =COUNTA('SV_Title too long'!B4:B775) -> 772 | H29: =HYPERLINK("#'SV_Title too long'!A1","SV_Title too long") -> SV_Title too long | I29: Medium | J29: Need to Fix
A30: 26 | B30: Striking Viking | C30: Missing H1 | D30: On-page Meta & Headings | E30: Sheet | F30: striking-viking - Issues.xlsx | G30: =COUNTA('SV_Missing H1'!C4:C91) -> 88 | H30: =HYPERLINK("#'SV_Missing H1'!A1","SV_Missing H1") -> SV_Missing H1 | I30: Medium | J30: Need to Fix
A31: 27 | B31: Striking Viking | C31: Meta description too short | D31: On-page Meta & Headings | E31: Sheet | F31: striking-viking - Issues.xlsx | G31: =COUNTA('SV_Meta description too short'!C5:C48) -> 44 | H31: =HYPERLINK("#'SV_Meta description too short'!A1","SV_Meta description too short") -> SV_Meta description too short | I31: Medium | J31: Need to Fix
A32: 28 | B32: Striking Viking | C32: Meta description tag missing or empty | D32: On-page Meta & Headings | E32: Sheet | F32: striking-viking - Issues.xlsx | G32: =COUNTA('SV_Meta description tag missing'!C6:C15) -> 10 | H32: =HYPERLINK("#'SV_Meta description tag missing'!A1","SV_Meta description tag missing") -> SV_Meta description tag missing | I32: Medium | J32: Need to Fix
A33: 29 | B33: Striking Viking | C33: Multiple H1 tags | D33: On-page Meta & Headings | E33: Sheet | F33: striking-viking - Issues.xlsx | G33: =COUNTA('SV_Multiple H1 tags'!C4:C255) -> 252 | H33: =HYPERLINK("#'SV_Multiple H1 tags'!A1","SV_Multiple H1 tags") -> SV_Multiple H1 tags | I33: Medium | J33: Need to Fix
A34: 30 | B34: Striking Viking | C34: Pages have high AI content levels | D34: Indexing / Intl / Content | E34: Sheet | F34: striking-viking - Issues.xlsx | G34: =COUNTA('SV_Pages have high AI content l'!C5:C5) -> 1 | H34: =HYPERLINK("#'SV_Pages have high AI content l'!A1","SV_Pages have high AI content l") -> SV_Pages have high AI content l | I34: High | J34: Need to Fix
A35: 31 | B35: Striking Viking | C35: Missing alt text | D35: Media / Markup | E35: Sheet | F35: striking-viking - Issues.xlsx | G35: =COUNTA('SV_Missing alt text'!C4:C324) -> 321 | H35: =HYPERLINK("#'SV_Missing alt text'!A1","SV_Missing alt text") -> SV_Missing alt text | I35: Low | J35: Need to Fix
A36: 32 | B36: Striking Viking | C36: External 4XX | D36: Links & Status Codes | E36: Sheet | F36: striking-viking - Issues.xlsx | G36: =COUNTA('SV_External 4XX'!B6:B71) -> 66 | H36: =HYPERLINK("#'SV_External 4XX'!A1","SV_External 4XX") -> SV_External 4XX | I36: High | J36: Need to Fix
A37: 33 | B37: Bigbatbox (WildYard) | C37: Pages not indexed in Google (GSC) | D37: Indexing / Intl / Content | E37: Report | F37: Site Audit & Analysis - Bigbatbox.docx | G37: 170 | I37: High | J37: Need to Fix | M37: 170 of 761 pages not indexed
A38: 34 | B38: Bigbatbox (WildYard) | C38: Manual action: thin content with little or no added value | D38: Indexing / Intl / Content | E38: Report | F38: Site Audit & Analysis - Bigbatbox.docx | I38: Critical | J38: Need to Fix | M38: Google manual spam action on /blogs section - top priority
A39: 35 | B39: Bigbatbox (WildYard) | C39: Organic traffic drop on key product/category pages | D39: Indexing / Intl / Content | E39: Report | F39: Site Audit & Analysis - Bigbatbox.docx | G39: 10 | I39: High | J39: Need to Fix | M39: Homepage -435 clicks; 'bat house' impressions -12.5k
A40: 36 | B40: Bigbatbox (WildYard) | C40: Translation issue: /de /es /fr /it /en-ca blog URLs still show English | D40: Indexing / Intl / Content | E40: Report | F40: Big Bat Box - Issues.docx | G40: 18 | I40: High | J40: Need to Fix | M40: 18 example URLs listed in report
A41: 37 | B41: Luonkos Finland (.fi) | C41: English pages not fully localized (Finnish text / Finnish slugs) | D41: Other | E41: Report | F41: Luonkos - Audit & Analysis.docx | I41: Medium | J41: Need to Fix | M41: luonkos.fi/en
...

Sheet File Inventory
A1: File Inventory - Robin - Site Audit & Analysis folder
A2: Every file in the uploaded zip, what it contains, and where it lives in this master sheet.
A4: # | B4: File | C4: Type | D4: Project | E4: Last modified | F4: Contents | G4: In master as | H4: Note
A5: 1 | B5: Bigbatbox - Site Audit.xlsx | C5: xlsx | D5: Bigbatbox (WildYard) | E5: 46276 | F5: Master checklist + 15 Ahrefs issue tabs | G5: BBB_Master Checklist, BBB_Broken Links, BBB_Broken Internal Link, BBB_Pages Marked No Index, BBB_Not submitted to IndexNow, BBB_Page has links to broken pa, BBB_Redirecting URLs, BBB_Too Long Meta Title, BBB_Too Long Meta Description, BBB_Missing H1 Tag, BBB_Missing Meta Description, BBB_Multiple H1 Tag, BBB_Page and SERP titles do not, BBB_Twitter and Open Graph tags, BBB_Image file size too large, BBB_Images Missing ALT text
A6: 2 | B6: Site Audit & Analysis - Bigbatbox.docx | C6: docx | D6: Bigbatbox (WildYard) | E6: 46279 | F6: GSC indexing, traffic drop, manual action, tech issues | G6: Issue Tracker (Source = Report)
A7: 3 | B7: Big Bat Box - Issues.docx | C7: docx | D7: Bigbatbox (WildYard) | E7: 46280 | F7: Translation issue - language URLs show English | G7: Issue Tracker (Source = Report)
A8: 4 | B8: https_happy-sinks.com_ - URL Report.xlsx | C8: xlsx | D8: Happy Sinks | E8: 46304 | F8: H1, meta title/description, pages dropped from top 10 | G8: HS_Missing H1 Tag, HS_Multiple H1 Tag, HS_Too Long Meta Title, HS_Too Long Meta Description, HS_Pages droped from top 10 Pos
A9: 5 | B9: https_happy-sinks.com_ - SEO Audit & Analysis Report.docx | C9: docx | D9: Happy Sinks | E9: 46304 | F9: Speed, translation, hreflang, sitemap, headings, meta, GSC | G9: Issue Tracker (Source = Report)
A10: 6 | B10: opengoaaalusa.com - Blog Content_.xlsx | C10: xlsx | D10: Open Goaaal USA | E10: 46280 | F10: Blog pages clicks/impressions (6 mo vs prior), GSC countries, filters | G10: OGU_Blog Pages, OGU_Countries, OGU_Filters
A11: 7 | B11: Site Audit & Analysis - opengoaaalusa.com.docx | C11: docx | D11: Open Goaaal USA | E11: 46275 | F11: Screenshots only - no text | G11: - | H11: No text content to extract
A12: 8 | B12: Opengoaaal - Duplicate Content Report.docx | C12: docx | D12: Open Goaaal USA / UK-EU | E12: 46280 | F12: Duplicate blog content across the two stores (3 cases) | G12: Issue Tracker (Source = Report)
A13: 9 | B13: striking-viking - Issues.xlsx | C13: xlsx | D13: Striking Viking | E13: 46299 | F13: 12 Ahrefs issue tabs with Status column | G13: SV_4xx, SV_3xx Redirection, SV_Page has links to broken pag, SV_Meta description too long, SV_Title too long, SV_Missing H1, SV_Meta description too short, SV_Meta description tag missing, SV_Multiple H1 tags, SV_Pages have high AI content l, SV_Missing alt text, SV_External 4XX
A14: 10 | B14: Luonkos - Audit & Analysis.docx | C14: docx | D14: Luonkos Finland (.fi) | E14: 46283 | F14: hreflang & canonical review, localization, regional indexing | G14: Issue Tracker (Source = Report)
A15: 11 | B15: Luonkos-audit-------- Not Final.docx | C15: docx | D15: Luonkos Finland (.fi) | E15: 46282 | F15: Draft long-form audit + duplication assessment | G15: - | H15: Draft - superseded by 'Luonkos - Audit & Analysis'
A16: 12 | B16: Luonkos_Merge_404_Report.docx | C16: docx | D16: Luonkos Finland (.fi) | E16: 46288 | F16: Post-merge 404s on EN/SV URLs, hreflang, redirect map | G16: Issue Tracker (Source = Report)
A17: 13 | B17: Bodyotics Analysis.docx | C17: docx | D17: Bodyotics | E17: 46287 | F17: Wrong-language URLs ranking in DE / NL / FR | G17: Issue Tracker (Source = Report)
A18: 14 | B18: https_luxsports.co_.docx | C18: docx | D18: Luxsports (LUX) | E18: 46302 | F18: 9 technical/international SEO issues | G18: Issue Tracker (Source = Report)
A19: 15 | B19: Babysunnies.com _ Technical SEO Audit(1).docx | C19: docx | D19: Babysunnies | E19: 46304 | F19: 10 technical SEO issues | G19: Issue Tracker (Source = Report) | H19: Version used in tracker (states 120 dead URLs)
A20: 16 | B20: Babysunnies.com _ Technical SEO Audit.docx | C20: docx | D20: Babysunnies | E20: 46304 | F20: Same audit, alternate version | G20: - | H20: Duplicate version - consolidate
A21: 17 | B21: babysunnies.com Technical SEO Audit--.docx | C21: docx | D21: Babysunnies | E21: 46304 | F21: Same audit, alternate version | G21: - | H21: Duplicate version - consolidate
A22: 18 | B22: coachsoak.com - SEO Audit & Analysis Report.docx | C22: docx | D22: Coachsoak | E22: 46303 | F22: 13 GSC / on-page / technical issues | G22: Issue Tracker (Source = Report)
A23: 19 | B23: Untitled spreadsheet.xlsx | C23: xlsx | D23: - | E23: 46275 | F23: Empty sheet | G23: - | H23: Empty - can be deleted
A24: 20 | B24: Coach/ (folder) | C24: folder | D24: Coachsoak | F24: Empty folder | G24: - | H24: Empty

Sheet BBB_Master Checklist
A1: Project Name - Bigbatbox | E1: =HYPERLINK("#'Master Overview'!A1","<< Master Overview") -> << Master Overview
A2: Website URL - https://www.bigbatbox.com/ | E2: Source: Bigbatbox - Site Audit.xlsx / Master Checklist
A3: Task - SEO Audit
A7: S.No | B7: Issues | C7: Status
A8: 1 | B8: Broken Links | C8: Need to Fix
A9: 2 | B9: Broken Internal Links | C9: Need to Fix
A10: 3 | B10: Pages Marked No Index | C10: Need to Fix
A11: 4 | B11: URLs Not Submitted to Index Now | C11: Need to Fix
A12: 5 | B12: Page has links to broken page | C12: Need to Fix
A13: 6 | B13: Redirecting URLs | C13: Need to Fix
A14: 7 | B14: Too Long Meta Title | C14: Need to Fix
A15: 8 | B15: Too Long Meta Description | C15: Need to Fix
A16: 9 | B16: Missing H1 Tag | C16: Need to Fix
A17: 10 | B17: Missing Meta Description | C17: Need to Fix
A18: 11 | B18: Multiple H1 Tag | C18: Need to Fix
A19: 12 | B19: Page and SERP titles do not match | C19: Need to Fix
... A22: 15 | B22: Images Missing ALT text | C22: Need to Fix

Sheet BBB_Broken Links
A1: S.No | B1: URL | D1: =HYPERLINK("#'Master Overview'!A1","<< Master Overview") -> << Master Overview
A2: 1 | B2: https://www.bigbatbox.com/blogs/all-about-bats/big-bat-box-comparison | D2: Source: Bigbatbox - Site Audit.xlsx / Broken Links
A3: 2 | B3: https://www.bigbatbox.com/blogs/all-about-bees/how-to-maintain-your-bee-house-through-the-seasons
A4: 3 | B4: https://www.bigbatbox.com/blogs/all-about-bats/14-fascinating-facts-about-bats
A5: 4 | B5: https://www.bigbatbox.com/blogs/all-about-bats/the-surprising-benefits-of-bat-boxes-and-why-you-should-have-one
A6: 5 | B6: https://www.bigbatbox.com/blogs/news/introducing-the-wildyard-x-angry-birds%E2%84%A2-collection-turn-your-garden-into-a-wildlife-habitat
A7: 6 | B7: https://www.bigbatbox.com/it/products/bee-house-big-bee-box
A8: 7 | B8: https://www.bigbatbox.com/collections/3-chamber-bat-houses
A9: 8 | B9: https://www.bigbatbox.com/products/bee-house-big-bee-box
A10: 9 | B10: https://www.bigbatbox.com/en-ca/products/bee-house-big-bee-box
A11: 10 | B11: https://www.bigbatbox.com/fr/collections/3-chamber-bat-houses
A12: 11 | B12: https://www.bigbatbox.com/es/products/big-bat-barn-certified-bat-house
A13: 12 | B13: https://www.bigbatbox.com/de/blogs/all-about-bats/how-to-attract-bats-to-your-backyard
A14: 13 | B14: https://www.bigbatbox.com/en-ca/collections/3-chamber-bat-houses
... A32: 31 | B32: https://www.bigbatbox.com/de/collections/3-chamber-bat-houses

Sheet BBB_Broken Internal Link
A1: S.No | B1: URL | C1: Broken Internal Link | E1: =HYPERLINK("#'Master Overview'!A1","<< Master Overview") -> << Master Overview
A2: 1 | B2: https://www.bigbatbox.com/de/blogs/habitat-of-bats/some-interesting-busted-myths-and-facts-about-bats | C2: https://www.bigbatbox.com/blogs/all-about-bats/big-bat-box-comparison | E2: Source: Bigbatbox - Site Audit.xlsx / Broken Internal Link
A3: 2 | B3: https://www.bigbatbox.com/de/blogs/bee-species/bee-wise-how-bee-houses-and-hotels-can-help-save-bees-the-environment | C3: https://www.bigbatbox.com/blogs/all-about-bees/how-to-maintain-your-bee-house-through-the-seasons
A4: 3 | B4: https://www.bigbatbox.com/de/blogs/habitat-of-bats/9-fantastic-bat-facts-you-need-to-know | C4: https://www.bigbatbox.com/blogs/all-about-bats/14-fascinating-facts-about-bats
A5: 4 | B5: https://www.bigbatbox.com/de/blogs/habitat-of-bats/eco-friendly-bat-house-for-backyard-the-complete-guide | C5: https://www.bigbatbox.com/blogs/all-about-bats/the-surprising-benefits-of-bat-boxes-and-why-you-should-have-one
A6: 5 | B6: https://www.bigbatbox.com/products/angry-birds-wildyard-diy-birdhouse-kit | C6: https://www.bigbatbox.com/blogs/news/introducing-the-wildyard-x-angry-birds%E2%84%A2-collection-turn-your-garden-into-a-wildlife-habitat
A7: 6 | B7: https://www.bigbatbox.com/it/blogs/habitat-of-bats/bat-box-casetta-pipistrelli-guida | C7: https://www.bigbatbox.com/it/products/bee-house-big-bee-box
A8: 7 | B8: https://www.bigbatbox.com/blogs/habitat-of-bats/how-to-hang-a-bat-house-complete-guide | C8: https://www.bigbatbox.com/collections/3-chamber-bat-houses
A9: 8 | B9: https://www.bigbatbox.com/blogs/habitat-of-bats/how-to-hang-a-bat-house-complete-guide | C9: https://www.bigbatbox.com/products/bee-house-big-bee-box
A10: 9 | B10: https://www.bigbatbox.com/en-ca/blogs/habitat-of-bats/how-to-hang-a-bat-house-complete-guide | C10: https://www.bigbatbox.com/en-ca/products/bee-house-big-bee-box
A11: 10 | B11: https://www.bigbatbox.com/fr/blogs/habitat-of-bats/nichoir-chauve-souris-guide-installation | C11: https://www.bigbatbox.com/fr/collections/3-chamber-bat-houses
A12: 11 | B12: https://www.bigbatbox.com/es/blogs/habitat-of-bats/how-to-hang-a-bat-house-complete-guide | C12: https://www.bigbatbox.com/es/products/big-bat-barn-certified-bat-house
A13: 12 | B13: https://www.bigbatbox.com/de/blogs/habitat-of-bats/the-definitive-guide-to-backyard-mosquito-control | C13: https://www.bigbatbox.com/de/blogs/all-about-bats/how-to-attract-bats-to-your-backyard
A14: 13 | B14: https://www.bigbatbox.com/en-ca/blogs/habitat-of-bats/how-to-hang-a-bat-house-complete-guide | C14: https://www.bigbatbox.com/en-ca/collections/3-chamber-bat-houses
... A32: 31 | B32: https://www.bigbatbox.com/de/blogs/habitat-of-bats/fledermauskasten-aufhaengen-leitfaden | C32: https://www.bigbatbox.com/de/collections/3-chamber-bat-houses

Sheet BBB_Pages Marked No Index
A1: S.No | B1: URL | D1: =HYPERLINK("#'Master Overview'!A1","<< Master Overview") -> << Master Overview
A2: 1 | B2: https://www.bigbatbox.com/products/discreet-packaging | D2: Source: Bigbatbox - Site Audit.xlsx / Pages Marked No Index
A3: 2 | B3: https://www.bigbatbox.com/de/products/discreet-packaging
A4: 3 | B4: https://www.bigbatbox.com/fr/products/discreet-packaging
A5: 4 | B5: https://www.bigbatbox.com/it/products/discreet-packaging
A6: 5 | B6: https://www.bigbatbox.com/es/products/discreet-packaging

Sheet BBB_Not submitted to IndexNow
A1: S.No | B1: URL | D1: =HYPERLINK("#'Master Overview'!A1","<< Master Overview") -> << Master Overview
A2: 1 | B2: https://www.bigbatbox.com/en-ca | D2: Source: Bigbatbox - Site Audit.xlsx / Not submitted to IndexNow
A3: 2 | B3: https://www.bigbatbox.com/en-ca/products/squirrel-house-hideout-feeder
A4: 3 | B4: https://www.bigbatbox.com/en-ca/products/squirrel-feeder
A5: 4 | B5: https://www.bigbatbox.com/en-ca/products/owl-box
A6: 5 | B6: https://www.bigbatbox.com/en-ca/cart
A7: 6 | B7: https://www.bigbatbox.com/de/search
A8: 7 | B8: https://www.bigbatbox.com/it/blogs/wildyard-learn
A9: 8 | B9: https://www.bigbatbox.com/fr/products/squirrel-feeder
A10: 9 | B10: https://www.bigbatbox.com/en-ca/collections/angry-birds-x-wildyard-birdhouses
A11: 10 | B11: https://www.bigbatbox.com/fr/pages/warranty-registration
A12: 11 | B12: https://www.bigbatbox.com/it/pages/work-with-us
A13: 12 | B13: https://www.bigbatbox.com/fr/products/owl-box
A14: 13 | B14: https://www.bigbatbox.com/es/cart
... A2111: 2110 | B2111: https://www.bigbatbox.com/fr/blogs/fun-facts-about-owls/tagged/ecological-balance

Sheet BBB_Page has links to broken pa
A1: S.No | B1: URL | C1: Internal outlinks to 4xx | E1: =HYPERLINK("#'Master Overview'!A1","<< Master Overview") -> << Master Overview
A2: 1 | B2: https://www.bigbatbox.com/products/angry-birds-wildyard-diy-birdhouse-kit | C2: https://www.bigbatbox.com/blogs/news/introducing-the-wildyard-x-angry-birds%E2%84%A2-collection-turn-your-garden-into-a-wildlife-habitat | E2: Source: Bigbatbox - Site Audit.xlsx / Page has links to broken page
A3: 2 | B3: https://www.bigbatbox.com/products/angry-birds-wildyard-flowerpot-birdhouse | C3: https://www.bigbatbox.com/blogs/news/introducing-the-wildyard-x-angry-birds%E2%84%A2-collection-turn-your-garden-into-a-wildlife-habitat
A4: 3 | B4: https://www.bigbatbox.com/es/products/angry-birds-wildyard-diy-birdhouse-kit | C4: https://www.bigbatbox.com/es/blogs/news/introducing-the-wildyard-x-angry-birds%E2%84%A2-collection-turn-your-garden-into-a-wildlife-habitat
A5: 4 | B5: https://www.bigbatbox.com/es/products/angry-birds-wildyard-flowerpot-birdhouse | C5: https://www.bigbatbox.com/es/blogs/news/introducing-the-wildyard-x-angry-birds%E2%84%A2-collection-turn-your-garden-into-a-wildlife-habitat
A6: 5 | B6: https://www.bigbatbox.com/fr/products/angry-birds-wildyard-diy-birdhouse-kit | C6: https://www.bigbatbox.com/fr/blogs/news/introducing-the-wildyard-x-angry-birds%E2%84%A2-collection-turn-your-garden-into-a-wildlife-habitat
A7: 6 | B7: https://www.bigbatbox.com/de/products/angry-birds-wildyard-diy-birdhouse-kit | C7: https://www.bigbatbox.com/de/blogs/news/introducing-the-wildyard-x-angry-birds%E2%84%A2-collection-turn-your-garden-into-a-wildlife-habitat
A8: 7 | B8: https://www.bigbatbox.com/it/products/angry-birds-wildyard-flowerpot-birdhouse | C8: https://www.bigbatbox.com/it/blogs/news/introducing-the-wildyard-x-angry-birds%E2%84%A2-collection-turn-your-garden-into-a-wildlife-habitat
A9: 8 | B9: https://www.bigbatbox.com/it/products/angry-birds-wildyard-diy-birdhouse-kit | C9: https://www.bigbatbox.com/it/blogs/news/introducing-the-wildyard-x-angry-birds%E2%84%A2-collection-turn-your-garden-into-a-wildlife-habitat
A10: 9 | B10: https://www.bigbatbox.com/fr/products/angry-birds-wildyard-flowerpot-birdhouse | C10: https://www.bigbatbox.com/fr/blogs/news/introducing-the-wildyard-x-angry-birds%E2%84%A2-collection-turn-your-garden-into-a-wildlife-habitat
A11: 10 | B11: https://www.bigbatbox.com/en-ca/products/angry-birds-wildyard-flowerpot-birdhouse | C11: https://www.bigbatbox.com/en-ca/blogs/news/introducing-the-wildyard-x-angry-birds%E2%84%A2-collection-turn-your-garden-into-a-wildlife-habitat
A12: 11 | B12: https://www.bigbatbox.com/de/products/angry-birds-wildyard-flowerpot-birdhouse | C12: https://www.bigbatbox.com/de/blogs/news/introducing-the-wildyard-x-angry-birds%E2%84%A2-collection-turn-your-garden-into-a-wildlife-habitat
A13: 12 | B13: https://www.bigbatbox.com/en-ca/products/angry-birds-wildyard-diy-birdhouse-kit | C13: https://www.bigbatbox.com/en-ca/blogs/news/introducing-the-wildyard-x-angry-birds%E2%84%A2-collection-turn-your-garden-into-a-wildlife-habitat
A14: 13 | B14: https://www.bigbatbox.com/blogs/habitat-of-bats/how-to-hang-a-bat-house-complete-guide | C14: https://www.bigbatbox.com/collections/3-chamber-bat-houses https://www.bigbatbox.com/products/bee-house-big-bee-box https://www.bigbatbox.com/products/big-bat-barn-certified-bat-house
... A28: 27 | B28: https://www.bigbatbox.com/it/blogs/habitat-of-bats/bat-box-casetta-pipistrelli-guida | C28: https://www.bigbatbox.com/it/collections/3-chamber-bat-houses https://www.bigbatbox.com/it/products/bee-house-big-bee-box https://www.bigbatbox.com/it/products/big-bat-barn-certified-bat-house

Sheet BBB_Redirecting URLs
A1: S.No | B1: URL | C1: Internal outlinks to 3xx | D1: Internal outlinks codes (3xx) | F1: =HYPERLINK("#'Master Overview'!A1","<< Master Overview") -> << Master Overview
A2: 1 | B2: https://www.bigbatbox.com/products/discreet-packaging | C2: https://www.bigbatbox.com/customer_authentication/redirect?locale=en&region_country=US | D2: 302 | F2: Source: Bigbatbox - Site Audit.xlsx / Redirecting URLs
A3: 2 | B3: https://www.bigbatbox.com/collections/ | C3: https://www.bigbatbox.com/customer_authentication/redirect?locale=en&region_country=US | D3: 302
A4: 3 | B4: https://www.bigbatbox.com/es/blogs/bee-species?page=1 | C4: https://www.bigbatbox.com/customer_authentication/redirect?locale=es&region_country=US https://www.bigbatbox.com/es/account | D4: 302 302
A5: 4 | B5: https://www.bigbatbox.com/blogs/fun-facts-about-owls?page=1 | C5: https://www.bigbatbox.com/customer_authentication/redirect?locale=en&region_country=US | D5: 302
A6: 5 | B6: https://www.bigbatbox.com/fr/blogs/bee-species?page=1 | C6: https://www.bigbatbox.com/customer_authentication/redirect?locale=fr&region_country=US https://www.bigbatbox.com/fr/account | D6: 302 302
A7: 6 | B7: https://www.bigbatbox.com/en-ca/blogs/bee-species?page=1 | C7: https://www.bigbatbox.com/customer_authentication/redirect?locale=en&region_country=CA https://www.bigbatbox.com/en-ca/account | D7: 302 302
A8: 7 | B8: https://www.bigbatbox.com/en-ca/blogs/fun-facts-about-owls?page=1 | C8: https://www.bigbatbox.com/customer_authentication/redirect?locale=en&region_country=CA https://www.bigbatbox.com/en-ca/account | D8: 302 302
A9: 8 | B9: https://www.bigbatbox.com/de/products/discreet-packaging | C9: https://www.bigbatbox.com/customer_authentication/redirect?locale=de&region_country=US https://www.bigbatbox.com/de/account https://www.bigbatbox.com/de/products/owl-box | D9: 302 302 301
A10: 9 | B10: https://www.bigbatbox.com/fr/products/discreet-packaging | C10: https://www.bigbatbox.com/customer_authentication/redirect?locale=fr&region_country=US https://www.bigbatbox.com/fr/account | D10: 302 302
A11: 10 | B11: https://www.bigbatbox.com/blogs/habitat-of-bats?page=1 | C11: https://www.bigbatbox.com/customer_authentication/redirect?locale=en&region_country=US | D11: 302
A12: 11 | B12: https://www.bigbatbox.com/fr/blogs/habitat-of-bats?page=1 | C12: https://www.bigbatbox.com/customer_authentication/redirect?locale=fr&region_country=US https://www.bigbatbox.com/fr/account https://www.bigbatbox.com/fr/blogs/habitat-of-bats/how-to-attract-bats-to-a-bat-house https://www.bigbatbox.com/fr/blogs/habitat-of-bats/how-to-hang-a-bat-house-complete-guide | D12: 302 302 301 301
A13: 12 | B13: https://www.bigbatbox.com/blogs/fun-facts-about-owls/owl-nesting-boxes-providing-safe-havens-for-nighttime-raptors?_pos=1&_ss=r | C13: https://www.bigbatbox.com/customer_authentication/redirect?locale=en&region_country=US | D13: 302
A14: 13 | B14: https://www.bigbatbox.com/blogs/habitat-of-bats/the-night-guardians-the-importance-of-bats-to-our-world?_pos=1&_ss=r | C14: https://www.bigbatbox.com/collections/shop-our-bat-houses https://www.bigbatbox.com/customer_authentication/redirect?locale=en&region_country=US | D14: 301 302
A15: 14 | B15: https://www.bigbatbox.com/de/blogs/fun-facts-about-owls?page=1 | C15: https://www.bigbatbox.com/customer_authentication/redirect?locale=de&region_country=US https://www.bigbatbox.com/de/account https://www.bigbatbox.com/de/products/owl-box | D15: 302 302 301
A16: 15 | B16: https://www.bigbatbox.com/es/blogs/habitat-of-bats?page=1 | C16: https://www.bigbatbox.com/customer_authentication/redirect?locale=es&region_country=US https://www.bigbatbox.com/es/account https://www.bigbatbox.com/es/blogs/habitat-of-bats/how-to-attract-bats-to-a-bat-house | D16: 302 302 301
A17: 16 | B17: https://www.bigbatbox.com/it/blogs/fun-facts-about-owls?page=1 | C17: https://www.bigbatbox.com/customer_authentication/redirect?locale=it&region_country=US https://www.bigbatbox.com/it/account | D17: 302 302
A18: 17 | B18: https://www.bigbatbox.com/it/blogs/habitat-of-bats?page=1 | C18: https://www.bigbatbox.com/customer_authentication/redirect?locale=it&region_country=US https://www.bigbatbox.com/it/account https://www.bigbatbox.com/it/blogs/habitat-of-bats/how-to-attract-bats-to-a-bat-house https://www.bigbatbox.com/it/blogs/habitat-of-bats/how-to-hang-a-bat-house-complete-guide | D18: 302 302 301 301
A19: 18 | B19: https://www.bigbatbox.com/it/products/discreet-packaging | C19: https://www.bigbatbox.com/customer_authentication/redirect?locale=it&region_country=US https://www.bigbatbox.com/it/account | D19: 302 302
A20: 19 | B20: https://www.bigbatbox.com/fr/blogs/fun-facts-about-owls?page=1 | C20: https://www.bigbatbox.com/customer_authentication/redirect?locale=fr&region_country=US https://www.bigbatbox.com/fr/account | D20: 302 302
A21: 20 | B21: https://www.bigbatbox.com/es/blogs/fun-facts-about-owls?page=1 | C21: https://www.bigbatbox.com/customer_authentication/redirect?locale=es&region_country=US https://www.bigbatbox.com/es/account | D21: 302 302
A22: 21 | B22: https://www.bigbatbox.com/it/blogs/bee-species?page=1 | C22: https://www.bigbatbox.com/customer_authentication/redirect?locale=it&region_country=US https://www.bigbatbox.com/it/account | D22: 302 302
A23: 22 | B23: https://www.bigbatbox.com/blogs/habitat-of-bats/a-brief-guide-to-building-and-installing-bat-boxes?_pos=5&_ss=r | C23: https://www.bigbatbox.com/customer_authentication/redirect?locale=en&region_country=US | D23: 302
A24: 23 | B24: https://www.bigbatbox.com/en-ca/blogs/habitat-of-bats?page=1 | C24: https://www.bigbatbox.com/customer_authentication/redirect?locale=en&region_country=CA https://www.bigbatbox.com/en-ca/account | D24: 302 302
A25: 24 | B25: https://www.bigbatbox.com/blogs/habitat-of-bats/5-best-tips-for-bat-house-maintenance?_pos=16&_ss=r | C25: https://www.bigbatbox.com/collections/shop-our-bat-houses https://www.bigbatbox.com/customer_authentication/redirect?locale=en&region_country=US | D25: 301 302
A26: 25 | B26: https://www.bigbatbox.com/de/blogs/bee-species?page=1 | C26: https://www.bigbatbox.com/customer_authentication/redirect?locale=de&region_country=US https://www.bigbatbox.com/de/account https://www.bigbatbox.com/de/products/owl-box | D26: 302 302 301
A27: 26 | B27: https://www.bigbatbox.com/blogs/bee-species?page=1 | C27: https://www.bigbatbox.com/customer_authentication/redirect?locale=en&region_country=US | D27: 302
A28: 27 | B28: https://www.bigbatbox.com/blogs/habitat-of-bats/how-to-get-bats-in-a-bat-house?_pos=1&_ss=r | C28: https://www.bigbatbox.com/customer_authentication/redirect?locale=en&region_country=US https://www.bigbatbox.com/products/big-bat-box | D28: 302 301
A29: 28 | B29: https://www.bigbatbox.com/es/products/discreet-packaging | C29: https://www.bigbatbox.com/customer_authentication/redirect?locale=es&region_country=US https://www.bigbatbox.com/es/account | D29: 302 302
A30: 29 | B30: https://www.bigbatbox.com/blogs/fun-facts-about-owls/the-silent-hunters-why-owl-boxes-and-bat-boxes-shouldnt-mix?_pos=1&_ss=r | C30: https://www.bigbatbox.com/collections/shop-our-bat-houses https://www.bigbatbox.com/customer_authentication/redirect?locale=en&region_country=US https://www.bigbatbox.com/products/owl-house | D30: 301 302 301
A31: 30 | B31: https://www.bigbatbox.com/products/squirrel-house-hideout-feeder?view=squirrel-house | C31: https://www.bigbatbox.com/customer_authentication/redirect?locale=en&region_country=US | D31: 302
A32: 31 | B32: https://www.bigbatbox.com/blogs/habitat-of-bats/how-to-attract-bats-your-go-to-guide?_pos=1&_ss=r | C32: https://www.bigbatbox.com/collections/bat-house-kits https://www.bigbatbox.com/customer_authentication/redirect?locale=en&region_country=US | D32: 301 302
A33: 32 | B33: https://www.bigbatbox.com/de/blogs/habitat-of-bats?page=1 | C33: https://www.bigbatbox.com/customer_authentication/redirect?locale=de&region_country=US https://www.bigbatbox.com/de/account https://www.bigbatbox.com/de/blogs/habitat-of-bats/how-to-attract-bats-to-a-bat-house https://www.bigbatbox.com/de/blogs/habitat-of-bats/how-to-hang-a-bat-house-complete-guide https://www.bigbatbox.com/de/products/owl-box | D33: 302 302 301 301 301

Sheet BBB_Too Long Meta Title
A1: S.No | B1: URL | C1: Title | D1: Title length | F1: =HYPERLINK("#'Master Overview'!A1","<< Master Overview") -> << Master Overview
A2: 1 | B2: https://www.bigbatbox.com/pages/faq | C2: Wildyard FAQ — Box Installation, Mounting & Care | Wildyard – Big Bat Box | D2: 73 | F2: Source: Bigbatbox - Site Audit.xlsx / Too Long Meta Title
A3: 2 | B3: https://www.bigbatbox.com/blogs/fun-facts-about-owls | C3: Fun Facts About Owls: Their Mysteries and Habits Unveiled – Big Bat Box | D3: 71
A4: 3 | B4: https://www.bigbatbox.com/products/angry-birds-wildyard-diy-birdhouse-kit | C4: WildYard X Angry Birds™ DIY Birdhouse Kit – Build & Paint | Big Bat Box | D4: 71
A5: 4 | B5: https://www.bigbatbox.com/products/squirrel-house-hideout-feeder | C5: Squirrel House - Hideout & Feeder Cedar Outdoor Nesting Box – Big Bat Box | D5: 73
A6: 5 | B6: https://www.bigbatbox.com/pages/1-for-the-planet | C6: Wildyard x 1% for the Planet I Giving Back to Protect Wildlife & Earth – Big Bat Box | D6: 84
A7: 6 | B7: https://www.bigbatbox.com/en-ca/products/squirrel-house-hideout-feeder | C7: Squirrel House - Hideout & Feeder Cedar Outdoor Nesting Box – Big Bat Box | D7: 73
A8: 7 | B8: https://www.bigbatbox.com/es/products/angry-birds-wildyard-diy-birdhouse-kit | C8: WildYard X Angry Birds™ DIY Birdhouse Kit – Build & Paint | Big Bat Box | D8: 71
A9: 8 | B9: https://www.bigbatbox.com/fr/blogs/fun-facts-about-owls | C9: Fun Facts About Owls: Their Mysteries and Habits Unveiled – Big Bat Box | D9: 71
A10: 9 | B10: https://www.bigbatbox.com/es/blogs/fun-facts-about-owls | C10: Fun Facts About Owls: Their Mysteries and Habits Unveiled – Big Bat Box | D10: 71
A11: 10 | B11: https://www.bigbatbox.com/es/products/squirrel-house-hideout-feeder | C11: Squirrel House - Hideout & Feeder Cedar Outdoor Nesting Box – Big Bat Box | D11: 73
A12: 11 | B12: https://www.bigbatbox.com/de/pages/1-for-the-planet | C12: Wildyard x 1 % für den Planeten I Wir geben etwas zurück, um die Tierwelt und die Erde zu schützen – Big Bat Box | D12: 112
A13: 12 | B13: https://www.bigbatbox.com/fr/pages/1-for-the-planet | C13: Wildyard x 1% for the Planet I Giving Back to Protect Wildlife & Earth – Big Bat Box | D13: 84
A14: 13 | B14: https://www.bigbatbox.com/fr/products/angry-birds-wildyard-diy-birdhouse-kit | C14: WildYard X Angry Birds™ DIY Birdhouse Kit – Build & Paint | Big Bat Box | D14: 71
... A1747: 1746 | B1747: https://www.bigbatbox.com/fr/blogs/fun-facts-about-owls/tagged/ecological-balance | C1747: Fun Facts About Owls: Their Mysteries and Habits Unveiled – Étiqueter "ecological balance" – Big Bat Box | D1747: 104

Sheet BBB_Too Long Meta Description
A1: S.No | B1: URL | C1: Title | D1: Meta description | E1: Meta description length | G1: =HYPERLINK("#'Master Overview'!A1","<< Master Overview") -> << Master Overview
A2: 1 | B2: https://www.bigbatbox.com/ | C2: Bat Houses, Owl Boxes & Bee Hotels | Big Bat Box | D2: Shop Big Bat Box for premium cedar bat houses, owl boxes, and bee hotels. Eco-friendly, handcrafted by WildYard — built to attract wildlife and control pests naturally. | E2: 168 | G2: Source: Bigbatbox - Site Audit.xlsx / Too Long Meta Description
A3: 2 | B3: https://www.bigbatbox.com/products/owl-box | C3: Owl Box — Cedar Owl House for Screech & Saw-Whet Owls | Big Bat Box | D3: Attract Eastern Screech Owls, Saw-Whet & Boreal Owls naturally. Handcrafted cedar owl box, easy to mount, built for real backyard wildlife. Ships to US & Canada. | E3: 161
A4: 3 | B4: https://www.bigbatbox.com/pages/faq | C4: Wildyard FAQ — Box Installation, Mounting & Care | Wildyard – Big Bat Box | D4: Find answers to questions about the bat box, owl box, and bee box. Learn installation tips, maintenance advice, wildlife benefits, shipping, returns, and more from Wildyard. | E4: 173
A5: 4 | B5: https://www.bigbatbox.com/products/double-chamber-bat-house-black | C5: Two Chamber Black Bat House — Holds 75 Bats | Big Bat Box | D5: Black cedar two-chamber bat house holds up to 75 bats. Heat-retentive design ideal for cooler climates — natural pest control for your backyard. Shop Big Bat Box. | E5: 162
A6: 5 | B6: https://www.bigbatbox.com/products/bat-house-single-chamber-black | C6: Single Chamber Black Bat House — Holds 50 Bats | Big Bat Box | D6: Cedar black bat house holds up to 50 bats. Weather-resistant, heat-retentive, and eco-friendly — ideal for natural mosquito control in any backyard. By Big Bat Box. | E6: 164
A7: 6 | B7: https://www.bigbatbox.com/pages/collab | C7: Collabs – Big Bat Box | D7: Shop Big Bat Box for premium cedar bat houses, owl boxes, and bee hotels. Eco-friendly, handcrafted by WildYard — built to attract wildlife and control pests naturally. | E7: 168
A8: 7 | B8: https://www.bigbatbox.com/en-ca | C8: Bat Houses, Owl Boxes & Bee Hotels | Big Bat Box | D8: Shop Big Bat Box for premium cedar bat houses, owl boxes, and bee hotels. Eco-friendly, handcrafted by WildYard — built to attract wildlife and control pests naturally. | E8: 168
A9: 8 | B9: https://www.bigbatbox.com/en-ca/products/owl-box | C9: Owl Box — Cedar Owl House for Screech & Saw-Whet Owls | Big Bat Box | D9: Attract Eastern Screech Owls, Saw-Whet & Boreal Owls naturally. Handcrafted cedar owl box, easy to mount, built for real backyard wildlife. Ships to US & Canada. | E9: 161
A10: 9 | B10: https://www.bigbatbox.com/en-ca/cart | C10: Your Shopping Cart – Big Bat Box | D10: Shop Big Bat Box for premium cedar bat houses, owl boxes, and bee hotels. Eco-friendly, handcrafted by WildYard — built to attract wildlife and control pests naturally. | E10: 168
A11: 10 | B11: https://www.bigbatbox.com/de/search | C11: Suche – Big Bat Box | D11: Shop Big Bat Box for premium cedar bat houses, owl boxes, and bee hotels. Eco-friendly, handcrafted by WildYard — built to attract wildlife and control pests naturally. | E11: 168
A12: 11 | B12: https://www.bigbatbox.com/de/blogs/wildyard-learn | C12: Blog - Große Fledermausbox – Big Bat Box | D12: In unserem Blog haben wir alle wichtigen Informationen rund um Fledermäuse und Fledermaushäuser zusammengestellt – von den Vorteilen bis zur Installation. Lesen Sie unsere Artikel! | E12: 180
A13: 12 | B13: https://www.bigbatbox.com/es/products/owl-box | C13: Owl Box — Cedar Owl House for Screech & Saw-Whet Owls | Big Bat Box | D13: Attract Eastern Screech Owls, Saw-Whet & Boreal Owls naturally. Handcrafted cedar owl box, easy to mount, built for real backyard wildlife. Ships to US & Canada. | E13: 161
A14: 13 | B14: https://www.bigbatbox.com/fr/products/owl-box | C14: Owl Box — Cedar Owl House for Screech & Saw-Whet Owls | Big Bat Box | D14: Attract Eastern Screech Owls, Saw-Whet & Boreal Owls naturally. Handcrafted cedar owl box, easy to mount, built for real backyard wildlife. Ships to US & Canada. | E14: 161
