Workbook

Sheet preferredfencesolutions.com
B1: Week | C1: Planned Date | D1: Day | E1: Category | F1: Post Title | G1: GBP Post Copy | H1: CTA | I1: Landing Page | J1: Tracked CTA URL | K1: Banner | L1: Banner Overlay Text | M1: Banner File | N1: Banner Photo Source | O1: Image Rights | P1: Offer Dates / Terms | Q1: Publishing Status
B2: 1 | C2: 46328 | D2: =TEXT(C2,"ddd") -> Mon | E2: Service | F2: Fence Repair After Wind and Storm Damage | G2: Leaning posts, broken panels or a gate that will not latch after the last windstorm? Preferred Fence Solutions repairs fences across the OKC metro, from a single leaning post to multi-section storm damage. We check whether a post can be reset and reinforced or needs replacing, and when we rebuild wood sections we use steel posts so the fence can stand up to Oklahoma wind. We give honest recommendations on repair versus replacement and free estimates on every job. Tap Learn more to schedule yours. | H2: Learn more | I2: https://preferredfencesolutions.com/fence-repair-okc/ | J2: =I2&"?utm_source="&Settings!$C$5&"&utm_medium="&Settings!$C$6&"&utm_campaign="&Settings!$C$7&"&utm_content="&Settings!C13 -> https://preferredfencesolutions.com/fence-repair-okc/?utm_source=google&utm_medium=organic&utm_campaign=gbp-posts-nov-2026&utm_content=nov26-01-fence-repair | L2: Tag: Fence Repair Headline: Storm-Damaged Fence? We Rebuild It. Sub-line: Repairs and rebuilds across the OKC metro Button: Free Repair Estimate | M2: 2026-11-02_gbp-post-01_1200x900.png | N2: https://unsplash.com/photos/km_VQEFOV20 (Unsplash licence) | O2: Unsplash License: free for commercial use, no permission or credit needed. | Q2: Not Published
B3: 1 | C3: 46329 | D3: =TEXT(C3,"ddd") -> Tue | E3: Promotional | F3: Free On-Site Fence Estimate | G3: Planning a new fence or a fence replacement before spring? Book a free on-site estimate with Preferred Fence Solutions. We measure your yard, talk through materials, height and gates, and give you a clear written quote. Wood, vinyl, ornamental iron, chain link and SimTek options are available across Oklahoma City, Edmond, Yukon, Mustang and Nichols Hills. Financing is available for larger projects. Tap View offer to request your free estimate. | H3: View offer | I3: https://preferredfencesolutions.com/ | J3: =I3&"?utm_source="&Settings!$C$5&"&utm_medium="&Settings!$C$6&"&utm_campaign="&Settings!$C$7&"&utm_content="&Settings!C14 -> https://preferredfencesolutions.com/?utm_source=google&utm_medium=organic&utm_campaign=gbp-posts-nov-2026&utm_content=nov26-02-free-estimate | L3: Tag: Free Estimate Headline: Your New Fence Starts Here Sub-line: On-site measure, clear written quote Button: Book Your Free Estimate | M3: 2026-11-03_gbp-post-02_1200x900.png | N3: https://preferredfencesolutions.com/wp-content/uploads/2022/05/IMG_5913.jpg | O3: Business's own photo from its website (client to confirm ownership). | P3: Offer dates: Nov 3 to Nov 30, 2026 (confirm). Terms: free estimate on all fence and gate projects (as stated on the website); no obligation. Financing available for larger projects. | Q3: Not Published
B4: 1 | C4: 46330 | D4: =TEXT(C4,"ddd") -> Wed | E4: FAQ | F4: FAQ: How Tall Can My Fence Be in OKC? | G4: FAQ: How tall can my fence be in Oklahoma City? Residential fences in Oklahoma City can be up to 8 feet tall in most cases, and 6 feet is the most common choice for backyard privacy. HOA rules often add their own limits, especially in Edmond, Nichols Hills and newer neighborhoods, so check with your HOA before you build. Not sure what is allowed on your property? Our team can help you plan the right height and style. Tap Learn more to read more fence FAQs. | H4: Learn more | I4: https://preferredfencesolutions.com/faq/ | J4: =I4&"?utm_source="&Settings!$C$5&"&utm_medium="&Settings!$C$6&"&utm_campaign="&Settings!$C$7&"&utm_content="&Settings!C15 -> https://preferredfencesolutions.com/faq/?utm_source=google&utm_medium=organic&utm_campaign=gbp-posts-nov-2026&utm_content=nov26-03-faq-fence-height | L4: Tag: Fence FAQ Headline: How Tall Can My Fence Be? Sub-line: Up to 8 ft in most OKC yards. 6 ft is the most popular. Always check your HOA. Button: More Fence FAQs | M4: 2026-11-04_gbp-post-03_1200x900.png | N4: https://preferredfencesolutions.com/wp-content/uploads/2022/10/Stained-Western-Red-Cedar-with-Cap-and-Trim-with-a-1x6-Kickboard.jpg | O4: Business's own photo from its website (client to confirm ownership). | Q4: Not Published
B5: 1 | C5: 46331 | D5: =TEXT(C5,"ddd") -> Thu | E5: Local | F5: Fence Installation in Edmond, OK | G5: Building a fence in Edmond? Preferred Fence Solutions has installed fences for Edmond homeowners for years, with local projects and references available. We install wood privacy fences, metal and decorative fencing, and custom gates, using materials chosen for Oklahoma weather. We keep job sites clean, give clear timelines, and walk the fence line with you at the end so you are 100% happy. Licensed and insured. Tap Learn more to get a free estimate for your Edmond home. | H5: Learn more | I5: https://preferredfencesolutions.com/fence-installation-edmond-ok/ | J5: =I5&"?utm_source="&Settings!$C$5&"&utm_medium="&Settings!$C$6&"&utm_campaign="&Settings!$C$7&"&utm_content="&Settings!C16 -> https://preferredfencesolutions.com/fence-installation-edmond-ok/?utm_source=google&utm_medium=organic&utm_campaign=gbp-posts-nov-2026&utm_content=nov26-04-edmond-installation | L5: Tag: Edmond, OK Headline: Edmond's Fence Crew Sub-line: Wood, metal and custom gates for Edmond homes Button: Free Estimate | M5: 2026-11-05_gbp-post-04_1200x900.png | N5: https://preferredfencesolutions.com/wp-content/uploads/2022/01/IMG_01991-2.jpg | O5: Business's own photo from its website (client to confirm ownership). | Q5: Not Published
B6: 1 | C6: 46332 | D6: =TEXT(C6,"ddd") -> Fri | E6: Service | F6: Western Red Cedar Stockade Fences Built in Our Shop | G6: Our wood stockade fences are built for Oklahoma. Preferred Fence Solutions custom builds every wood fence panel and gate in our shop using Western Red Cedar, which is naturally rot and pest resistant. Each fence is installed on heavy-duty steel posts set in concrete 2 feet below grade, and we never dry set our posts. Choose dog ear, cap and trim, board on board, shadowbox, horizontal and more. Tap Learn more to see the styles. | H6: Learn more | I6: https://preferredfencesolutions.com/stockade-wood-fence/ | J6: =I6&"?utm_source="&Settings!$C$5&"&utm_medium="&Settings!$C$6&"&utm_campaign="&Settings!$C$7&"&utm_content="&Settings!C17 -> https://preferredfencesolutions.com/stockade-wood-fence/?utm_source=google&utm_medium=organic&utm_campaign=gbp-posts-nov-2026&utm_content=nov26-05-cedar-stockade | L6: Tag: Cedar Stockade Fences Headline: Real Cedar. Steel Posts. Sub-line: Panels built by hand in our shop Button: See Fence Styles | M6: 2026-11-06_gbp-post-05_1200x900.png | N6: https://preferredfencesolutions.com/wp-content/uploads/2022/03/6-tall-Cap-and-Trim-Total-Privacy-Board-on-Board.-.jpeg | O6: Business's own photo from its website (client to confirm ownership). | Q6: Not Published
B7: 2 | C7: 46335 | D7: =TEXT(C7,"ddd") -> Mon | E7: FAQ | F7: FAQ: Should I Repair or Replace My Fence? | G7: FAQ: Should I repair my fence or replace it? A quick rule of thumb: repair usually makes sense when the damage is limited to a few areas and the rest of the fence is still sound. Replacement is usually the smarter choice when several posts are leaning, rails are failing or sections keep moving over time. Walk your fence line and look for leaning posts, loose rails and rot at the base. Not sure what you are seeing? We will tell you honestly. Tap Learn more to read our full guide. | H7: Learn more | I7: https://preferredfencesolutions.com/fence-repair-vs-replacement-oklahoma-city/ | J7: =I7&"?utm_source="&Settings!$C$5&"&utm_medium="&Settings!$C$6&"&utm_campaign="&Settings!$C$7&"&utm_content="&Settings!C18 -> https://preferredfencesolutions.com/fence-repair-vs-replacement-oklahoma-city/?utm_source=google&utm_medium=organic&utm_campaign=gbp-posts-nov-2026&utm_content=nov26-06-faq-repair-vs-replace | L7: Tag: Fence FAQ Headline: Repair or Replace? Sub-line: Limited damage: repair. Several leaning posts or failing rails: replace. Button: Read the Guide | M7: 2026-11-09_gbp-post-06_1200x900.png | N7: https://preferredfencesolutions.com/wp-content/uploads/2022/06/new-vs-old.jpeg | O7: Business's own photo from its website (client to confirm ownership). | Q7: Not Published
B8: 2 | C8: 46336 | D8: =TEXT(C8,"ddd") -> Tue | E8: Service | F8: Ameristar Ornamental Iron Fences and Gates | G8: Looking for security that still looks elegant from the street? Preferred Fence Solutions installs Ameristar ornamental iron fences and gates for homes in Oklahoma City, Edmond and the surrounding metro. We have installed iron fences from 4 to 6 feet tall and can add decorative finials, scrolls and custom gates. Ameristar products come backed by a 20-year warranty. Ornamental iron is a popular choice for front yards, pools and retaining walls. Tap Learn more to see recent projects. | H8: Learn more | I8: https://preferredfencesolutions.com/ornamental-iron-fence/ | J8: =I8&"?utm_source="&Settings!$C$5&"&utm_medium="&Settings!$C$6&"&utm_campaign="&Settings!$C$7&"&utm_content="&Settings!C19 -> https://preferredfencesolutions.com/ornamental-iron-fence/?utm_source=google&utm_medium=organic&utm_campaign=gbp-posts-nov-2026&utm_content=nov26-07-ornamental-iron | L8: Tag: Ornamental Iron Headline: Security With Curb Appeal Sub-line: Ameristar iron fences and custom gates Button: See Recent Projects | M8: 2026-11-10_gbp-post-07_1200x900.png | N8: https://preferredfencesolutions.com/wp-content/uploads/2022/05/Arched-ornamental-iron-double-gate-custom-Letter-2.jpg | O8: Business's own photo from its website (client to confirm ownership). | Q8: Not Published
B9: 2 | C9: 46337 | D9: =TEXT(C9,"ddd") -> Wed | E9: Local | F9: The Best Fence for Oklahoma Wind | G9: Oklahoma wind is hard on fences. Between spring storms, sudden gusts and shifting clay soil, the wrong fence or install method can lead to leaning posts and broken panels. For homes in Oklahoma City, Edmond and Yukon, the biggest difference usually comes from how the fence is built: post type, post depth and concrete, plus a material that suits your yard. We wrote a local guide on what actually holds up in OKC weather. Tap Learn more to read it. | H9: Learn more | I9: https://preferredfencesolutions.com/best-fence-oklahoma-wind-okc/ | J9: =I9&"?utm_source="&Settings!$C$5&"&utm_medium="&Settings!$C$6&"&utm_campaign="&Settings!$C$7&"&utm_content="&Settings!C20 -> https://preferredfencesolutions.com/best-fence-oklahoma-wind-okc/?utm_source=google&utm_medium=organic&utm_campaign=gbp-posts-nov-2026&utm_content=nov26-08-oklahoma-wind | L9: Tag: Oklahoma Weather Headline: Built for Oklahoma Wind Sub-line: Post depth, concrete and the right material Button: Read the Local Guide | M9: 2026-11-11_gbp-post-08_1200x900.png | N9: https://preferredfencesolutions.com/wp-content/uploads/2021/12/IMG_8799-scaled.jpg | O9: Business's own photo from its website (client to confirm ownership). | Q9: Not Published
B10: 2 | C10: 46338 | D10: =TEXT(C10,"ddd") -> Thu | E10: FAQ | F10: FAQ: Why Do Fence Posts Lean in Oklahoma? | G10: FAQ: Why do fence posts lean in Oklahoma? Oklahoma clay soil expands and contracts as it gets wet and dries out, which loosens post footings over time. Strong wind adds more load, so a small lean can turn into a failing section. That is why we set heavy-duty steel posts in concrete 2 feet below grade on our wood fences. If your posts are already leaning, we can tell you whether they can be reset or need replacing. Tap Learn more to read the full article. | H10: Learn more | I10: https://preferredfencesolutions.com/why-fence-posts-fail-oklahoma-soil/ | J10: =I10&"?utm_source="&Settings!$C$5&"&utm_medium="&Settings!$C$6&"&utm_campaign="&Settings!$C$7&"&utm_content="&Settings!C21 -> https://preferredfencesolutions.com/why-fence-posts-fail-oklahoma-soil/?utm_source=google&utm_medium=organic&utm_campaign=gbp-posts-nov-2026&utm_content=nov26-09-faq-post-failure | L10: Tag: Fence FAQ Headline: Why Do Fence Posts Lean? Sub-line: Clay soil swells and shrinks. We set steel posts in concrete 2 ft below grade. Button: Read the Article | M10: 2026-11-12_gbp-post-09_1200x900.png | N10: https://preferredfencesolutions.com/wp-content/uploads/2021/12/IMG_5922.jpg | O10: Business's own photo from its website (client to confirm ownership). | Q10: Not Published
B11: 2 | C11: 46339 | D11: =TEXT(C11,"ddd") -> Fri | E11: Service | F11: Sheet Metal Fence for Commercial Properties | G11: Need privacy and security for a storage yard, equipment area or commercial lot? Preferred Fence Solutions installs sheet metal and ribbed panel metal fences for commercial properties across Oklahoma City. The panels do not rot, warp or absorb moisture, which makes them a practical, low-maintenance choice for storage facilities, industrial sites and utility screening. Tap Learn more to request a free commercial fence estimate. | H11: Learn more | I11: https://preferredfencesolutions.com/sheet-metal-fence-oklahoma-city/ | J11: =I11&"?utm_source="&Settings!$C$5&"&utm_medium="&Settings!$C$6&"&utm_campaign="&Settings!$C$7&"&utm_content="&Settings!C22 -> https://preferredfencesolutions.com/sheet-metal-fence-oklahoma-city/?utm_source=google&utm_medium=organic&utm_campaign=gbp-posts-nov-2026&utm_content=nov26-10-sheet-metal-commercial | L11: Tag: Commercial Fencing Headline: Privacy That Won't Rot Sub-line: Sheet metal and ribbed panel fences for commercial sites Button: Commercial Estimate | M11: 2026-11-13_gbp-post-10_1200x900.png | N11: https://preferredfencesolutions.com/wp-content/uploads/2026/05/4800-S-Sunnylane-Rd_Completed-Pic-5-scaled.jpg | O11: Business's own photo from its website (client to confirm ownership). | Q11: Not Published
B12: 3 | C12: 46342 | D12: =TEXT(C12,"ddd") -> Mon | E12: Promotional | F12: Add a Custom Doggie Window to Your Fence | G12: Give your dog a view of the neighborhood. Ask about adding a custom doggie window to any stockade fence we build. It is a small add-on that dogs love and owners enjoy, and it fits into the fence design so it looks finished, not added on later. We build every panel in our shop, so the window can be placed exactly where your dog likes to watch. Tap Learn more to see doggie windows in our fence gallery. | H12: Learn more | I12: https://preferredfencesolutions.com/fence-gallery/ | J12: =I12&"?utm_source="&Settings!$C$5&"&utm_medium="&Settings!$C$6&"&utm_campaign="&Settings!$C$7&"&utm_content="&Settings!C23 -> https://preferredfencesolutions.com/fence-gallery/?utm_source=google&utm_medium=organic&utm_campaign=gbp-posts-nov-2026&utm_content=nov26-11-doggie-window | L12: Tag: Pet-Friendly Add-On Headline: A Window for Your Best Friend Sub-line: Custom doggie windows for any stockade fence Button: See Doggie Windows | M12: 2026-11-16_gbp-post-11_1200x900.png | N12: https://preferredfencesolutions.com/wp-content/uploads/2022/07/bassethound-doggie-window.jpeg | O12: Business's own photo from its website (client to confirm ownership). | Q12: Not Published
B13: 3 | C13: 46343 | D13: =TEXT(C13,"ddd") -> Tue | E13: Service | F13: Chain Link Fencing: Galvanized or Black Vinyl-Coated | G13: Chain link is one of the most affordable ways to secure a yard or a business. Preferred Fence Solutions installs galvanized and black vinyl-coated chain link for homes and commercial properties across OKC and Edmond. We can add walk-through gates, double drive gates, cantilever gates, automatic gate operators and telephone entry systems. We also repair existing chain link fences. Tap Learn more to get a free quote. | H13: Learn more | I13: https://preferredfencesolutions.com/chain-link-fence/ | J13: =I13&"?utm_source="&Settings!$C$5&"&utm_medium="&Settings!$C$6&"&utm_campaign="&Settings!$C$7&"&utm_content="&Settings!C24 -> https://preferredfencesolutions.com/chain-link-fence/?utm_source=google&utm_medium=organic&utm_campaign=gbp-posts-nov-2026&utm_content=nov26-12-chain-link | L13: Tag: Chain Link Fencing Headline: Affordable, Secure, Built to Last Sub-line: Galvanized or black vinyl-coated, with gates Button: Get a Free Quote | M13: 2026-11-17_gbp-post-12_1200x900.png | N13: https://preferredfencesolutions.com/wp-content/uploads/2022/01/4-black-chain-link.jpg | O13: Business's own photo from its website (client to confirm ownership). | Q13: Not Published
B14: 3 | C14: 46344 | D14: =TEXT(C14,"ddd") -> Wed | E14: FAQ | F14: FAQ: What Is the Most Affordable Fence in OKC? | G14: FAQ: What is the most affordable fence option in OKC? Galvanized chain link is our most budget-friendly option for both homes and businesses. If you want wood, our most affordable choice is Western Red Cedar on metal posts. We do not install cheaper woods like white spruce because the quality is not there, and cedar is naturally pest resistant and lasts longer. Tap Learn more to see more answers, or request a free estimate for your yard. | H14: Learn more | I14: https://preferredfencesolutions.com/faq/ | J14: =I14&"?utm_source="&Settings!$C$5&"&utm_medium="&Settings!$C$6&"&utm_campaign="&Settings!$C$7&"&utm_content="&Settings!C25 -> https://preferredfencesolutions.com/faq/?utm_source=google&utm_medium=organic&utm_campaign=gbp-posts-nov-2026&utm_content=nov26-13-faq-affordable-fence | L14: Tag: Fence FAQ Headline: What's the Most Affordable Fence? Sub-line: Galvanized chain link. For wood, Western Red Cedar on metal posts. Button: Get a Free Estimate | M14: 2026-11-18_gbp-post-13_1200x900.png | N14: https://preferredfencesolutions.com/wp-content/uploads/2022/03/1x4x6-Western-Red-Cedar-with-Cap-and-Trim-scaled.jpg | O14: Business's own photo from its website (client to confirm ownership). | Q14: Not Published
B15: 3 | C15: 46345 | D15: =TEXT(C15,"ddd") -> Thu | E15: Local | F15: North OKC Fence Installation and Repair | G15: Preferred Fence Solutions is based just north of OKC, and North OKC homeowners are some of our longest-standing customers. We custom make each fence panel in our shop, install stockade fences on heavy-duty metal posts, use 100% USA fence products and back every fence and gate with a 1-year warranty. We never turn away a job because of its size. Tap Learn more to get a free estimate for your North OKC fence. | H15: Learn more | I15: https://preferredfencesolutions.com/fence-installation-repair-north-okc/ | J15: =I15&"?utm_source="&Settings!$C$5&"&utm_medium="&Settings!$C$6&"&utm_campaign="&Settings!$C$7&"&utm_content="&Settings!C26 -> https://preferredfencesolutions.com/fence-installation-repair-north-okc/?utm_source=google&utm_medium=organic&utm_campaign=gbp-posts-nov-2026&utm_content=nov26-14-north-okc | L15: Tag: North OKC Headline: Hand-Built in Our North OKC Shop Sub-line: 100% USA fence products. 1-year warranty. Button: Free Estimate | M15: 2026-11-19_gbp-post-14_1200x900.png | N15: https://preferredfencesolutions.com/wp-content/uploads/2021/12/IMG_5879.jpg | O15: Business's own photo from its website (client to confirm ownership). | Q15: Not Published
B16: 3 | C16: 46346 | D16: =TEXT(C16,"ddd") -> Fri | E16: Service | F16: Low-Maintenance Vinyl Fence Installation | G16: Want a fence you never have to stain or paint? Vinyl is a low-maintenance option that lasts for years. Preferred Fence Solutions installs vinyl privacy fences, picket fences, ranch-style 3-rail fences and vinyl gates in OKC, Edmond, Piedmont, Nichols Hills and The Village. Tan and white are the most popular colors. Many vinyl fences can be installed in a single day. Tap Learn more to see styles and get a free quote. | H16: Learn more | I16: https://preferredfencesolutions.com/vinyl-fence/ | J16: =I16&"?utm_source="&Settings!$C$5&"&utm_medium="&Settings!$C$6&"&utm_campaign="&Settings!$C$7&"&utm_content="&Settings!C27 -> https://preferredfencesolutions.com/vinyl-fence/?utm_source=google&utm_medium=organic&utm_campaign=gbp-posts-nov-2026&utm_content=nov26-15-vinyl-fence | L16: Tag: Vinyl Fencing Headline: No Staining. No Painting. Sub-line: Vinyl privacy, picket and ranch-style fences Button: See Vinyl Styles | M16: 2026-11-20_gbp-post-15_1200x900.png | N16: https://preferredfencesolutions.com/wp-content/uploads/2022/05/6-tall-white-vinyl-privacy-fence-.jpg | O16: Business's own photo from its website (client to confirm ownership). | Q16: Not Published
B17: 4 | C17: 46349 | D17: =TEXT(C17,"ddd") -> Mon | E17: Promotional | F17: Fence Design Help With Every Free Estimate | G17: Thinking about a new fence for spring? Not sure which style, material or height is right for your property? Preferred Fence Solutions offers free estimates on all fence and gate projects, and our team helps you plan the design. We will walk your yard, talk through privacy, pets, gates and budget, and recommend the best option for your home. Financing is available for larger projects, so ask about it during your estimate. Tap View offer to book your free estimate. | H17: View offer | I17: https://preferredfencesolutions.com/fence-design-planning/ | J17: =I17&"?utm_source="&Settings!$C$5&"&utm_medium="&Settings!$C$6&"&utm_campaign="&Settings!$C$7&"&utm_content="&Settings!C28 -> https://preferredfencesolutions.com/fence-design-planning/?utm_source=google&utm_medium=organic&utm_campaign=gbp-posts-nov-2026&utm_content=nov26-16-free-design-consult | L17: Tag: Free Estimate Headline: Plan Your Spring Fence Now Sub-line: Design help with every free estimate Button: Book Your Free Estimate | M17: 2026-11-23_gbp-post-16_1200x900.png | N17: https://preferredfencesolutions.com/wp-content/uploads/2021/12/desing-and-planning.jpg | O17: Business's own photo from its website (client to confirm ownership). | P17: Offer dates: Nov 23 to Dec 31, 2026 (confirm). Terms: free estimate on all fence and gate projects (as stated on the website); no obligation. Financing available for larger projects. | Q17: Not Published
B18: 4 | C18: 46350 | D18: =TEXT(C18,"ddd") -> Tue | E18: Service | F18: Residential Gates: Width and Placement | G18: Planning a gate? The right width and location make your yard easier to use every day. A walk gate may be fine for people but too narrow for a mower, and a wide equipment gate may work better on a different side of the house. Preferred Fence Solutions builds custom wood and iron gates and helps you settle access before the posts go in. Tap Learn more to read our gate planning guide for OKC homeowners. | H18: Learn more | I18: https://preferredfencesolutions.com/residential-fence-gate-width-placement-okc/ | J18: =I18&"?utm_source="&Settings!$C$5&"&utm_medium="&Settings!$C$6&"&utm_campaign="&Settings!$C$7&"&utm_content="&Settings!C29 -> https://preferredfencesolutions.com/residential-fence-gate-width-placement-okc/?utm_source=google&utm_medium=organic&utm_campaign=gbp-posts-nov-2026&utm_content=nov26-17-gate-planning | L18: Tag: Custom Gates Headline: The Right Gate, in the Right Place Sub-line: Plan access before the posts go in Button: Read the Gate Guide | M18: 2026-11-24_gbp-post-17_1200x900.png | N18: https://preferredfencesolutions.com/wp-content/uploads/2022/04/o-3.jpg | O18: Business's own photo from its website (client to confirm ownership). | Q18: Not Published
B19: 4 | C19: 46351 | D19: =TEXT(C19,"ddd") -> Wed | E19: FAQ | F19: FAQ: Will New Cedar Boards Match My Old Fence? | G19: FAQ: Will new cedar boards blend in with my older fence? New cedar usually looks brighter or more reddish than boards that have weathered for years. A contractor can match the size, profile and spacing closely, but the exact color takes time to even out as the new wood weathers. Replacing damaged boards still restores privacy and extends the life of a sound fence. Tap Learn more to read what to expect and your options. | H19: Learn more | I19: https://preferredfencesolutions.com/new-cedar-fence-boards-blend-old-fence/ | J19: =I19&"?utm_source="&Settings!$C$5&"&utm_medium="&Settings!$C$6&"&utm_campaign="&Settings!$C$7&"&utm_content="&Settings!C30 -> https://preferredfencesolutions.com/new-cedar-fence-boards-blend-old-fence/?utm_source=google&utm_medium=organic&utm_campaign=gbp-posts-nov-2026&utm_content=nov26-18-faq-cedar-match | L19: Tag: Fence FAQ Headline: Will New Boards Match My Old Fence? Sub-line: Size and style, yes. Color evens out as new cedar weathers. Button: See What to Expect | M19: 2026-11-25_gbp-post-18_1200x900.png | N19: https://preferredfencesolutions.com/wp-content/uploads/2022/03/1x4x6-Western-Red-Cedar-with-Cap-and-Trim-scaled.jpg | O19: Business's own photo from its website (client to confirm ownership). | Q19: Not Published
B20: 4 | C20: 46352 | D20: =TEXT(C20,"ddd") -> Thu | E20: Local | F20: Happy Thanksgiving from Preferred Fence Solutions | G20: Happy Thanksgiving from the Preferred Fence Solutions team. Thank you to every homeowner and business in Oklahoma City, Edmond, Nichols Hills, Yukon and Mustang who trusted our crew with their fence this year. Our promise is to exceed your expectations with fences that are installed with precision, care and good attitudes, and your kind words keep us going. Enjoy the holiday with your family. Tap Learn more to read what our customers say. | H20: Learn more | I20: https://preferredfencesolutions.com/testimonials/ | J20: =I20&"?utm_source="&Settings!$C$5&"&utm_medium="&Settings!$C$6&"&utm_campaign="&Settings!$C$7&"&utm_content="&Settings!C31 -> https://preferredfencesolutions.com/testimonials/?utm_source=google&utm_medium=organic&utm_campaign=gbp-posts-nov-2026&utm_content=nov26-19-thanksgiving | L20: Tag: Happy Thanksgiving Headline: Thankful for Our Neighbors Sub-line: From our crew to your family Button: | M20: 2026-11-26_gbp-post-19_1200x900.png | N20: https://preferredfencesolutions.com/wp-content/uploads/2022/01/o-8.jpg | O20: Business's own photo from its website (client to confirm ownership). | Q20: Not Published
B21: 4 | C21: 46353 | D21: =TEXT(C21,"ddd") -> Fri | E21: Promotional | F21: Free Fence Repair Estimate | G21: Did fall storms or strong wind leave your fence leaning or damaged? Book a free fence repair estimate with Preferred Fence Solutions. We will check posts, panels and gates, tell you honestly whether repair or replacement makes more sense, and give you a clear quote. No job is too small. Tap View offer to schedule your free repair estimate. | H21: View offer | I21: https://preferredfencesolutions.com/fence-repair-okc/ | J21: =I21&"?utm_source="&Settings!$C$5&"&utm_medium="&Settings!$C$6&"&utm_campaign="&Settings!$C$7&"&utm_content="&Settings!C32 -> https://preferredfencesolutions.com/fence-repair-okc/?utm_source=google&utm_medium=organic&utm_campaign=gbp-posts-nov-2026&utm_content=nov26-20-free-repair-estimate | L21: Tag: Free Repair Estimate Headline: Leaning or Damaged Fence? Sub-line: Honest repair-or-replace advice Button: Book a Free Estimate | M21: 2026-11-27_gbp-post-20_1200x900.png | N21: https://unsplash.com/photos/LbkIbkMPKjg (Unsplash licence) | O21: Unsplash License: free for commercial use, no permission or credit needed. | P21: Offer dates: Nov 27 to Dec 31, 2026. Terms: free estimate within the service area; no obligation. | Q21: Not Published
B22: 5 | C22: 46356 | D22: =TEXT(C22,"ddd") -> Mon | E22: Service | F22: SimTek Fences: The Look of Stone | G22: Want the look of stone with the privacy of a solid fence? Consider a SimTek EcoStone fence. SimTek fences can be customized to your style and budget, offer high levels of security, need minimal maintenance and come with SimTek's warranty. Preferred Fence Solutions installs SimTek fences for homes in Edmond, OKC, Mustang and Yukon. Tap Learn more to see if SimTek is right for your yard. | H22: Learn more | I22: https://preferredfencesolutions.com/simtek-fence/ | J22: =I22&"?utm_source="&Settings!$C$5&"&utm_medium="&Settings!$C$6&"&utm_campaign="&Settings!$C$7&"&utm_content="&Settings!C33 -> https://preferredfencesolutions.com/simtek-fence/?utm_source=google&utm_medium=organic&utm_campaign=gbp-posts-nov-2026&utm_content=nov26-21-simtek | L22: Tag: SimTek Fencing Headline: The Look of Stone, Without the Upkeep Sub-line: SimTek fences for Edmond, OKC, Mustang and Yukon Button: Is SimTek Right for You? | M22: 2026-11-30_gbp-post-21_1200x900.png | N22: https://unsplash.com/photos/0WxjDT_3Tsw (Unsplash licence) | O22: Unsplash License: free for commercial use, no permission or credit needed. | Q22: Not Published
B23: 5 | C23: 46357 | D23: =TEXT(C23,"ddd") -> Tue | E23: Local | F23: Thank You, Oklahoma City | G23: Thank you, Oklahoma City, for another great year. We are honored to have won local awards for our fencing work, and we stand behind every fence and gate we install with a 1-year warranty. More than any award, we are grateful for customers who welcome our crew into their yards and recommend us to their neighbors. If we built or repaired your fence this year, we would love to hear how it is holding up. Tap Learn more to see our awards. | H23: Learn more | I23: https://preferredfencesolutions.com/pfs-awards/ | J23: =I23&"?utm_source="&Settings!$C$5&"&utm_medium="&Settings!$C$6&"&utm_campaign="&Settings!$C$7&"&utm_content="&Settings!C34 -> https://preferredfencesolutions.com/pfs-awards/?utm_source=google&utm_medium=organic&utm_campaign=gbp-posts-nov-2026&utm_content=nov26-22-year-end-awards | L23: Tag: Thank You, OKC Headline: Award-Winning Fence Crew Sub-line: Every fence and gate backed by a 1-year warranty Button: See Our Awards | M23: 2026-12-01_gbp-post-22_1200x900.png | N23: https://preferredfencesolutions.com/wp-content/uploads/2021/12/IMG_5887.jpg https://preferredfencesolutions.com/wp-content/uploads/2022/04/IMG_5911.jpg https://preferredfencesolutions.com/wp-content/uploads/2022/07/o-2.jpg | O23: Business's own photo from its website (client to confirm ownership). | Q23: Not Published

Sheet Settings
A1: Tracking settings
A2: Edit values in column C. Every Tracked CTA URL on the calendar tab updates automatically.
B4: Setting | C4: Value | D4: Note
B5: UTM source | C5: google | D5: Keep as google
B6: UTM medium | C6: organic | D6: Keep as organic
B7: UTM campaign | C7: gbp-posts-nov-2026 | D7: One campaign for this month
B8: Website domain | C8: preferredfencesolutions.com | D8: QA checks every landing page stays on this domain
B11: UTM content per post (unique, so each post is tracked separately in Google Analytics)
B12: Post # | C12: utm_content | D12: Post Title
B13: 1 | C13: nov26-01-fence-repair | D13: ='preferredfencesolutions.com'!F2 -> Fence Repair After Wind and Storm Damage
B14: 2 | C14: nov26-02-free-estimate | D14: ='preferredfencesolutions.com'!F3 -> Free On-Site Fence Estimate
B15: 3 | C15: nov26-03-faq-fence-height | D15: ='preferredfencesolutions.com'!F4 -> FAQ: How Tall Can My Fence Be in OKC?
B16: 4 | C16: nov26-04-edmond-installation | D16: ='preferredfencesolutions.com'!F5 -> Fence Installation in Edmond, OK
B17: 5 | C17: nov26-05-cedar-stockade | D17: ='preferredfencesolutions.com'!F6 -> Western Red Cedar Stockade Fences Built in Our Shop
B18: 6 | C18: nov26-06-faq-repair-vs-replace | D18: ='preferredfencesolutions.com'!F7 -> FAQ: Should I Repair or Replace My Fence?
B19: 7 | C19: nov26-07-ornamental-iron | D19: ='preferredfencesolutions.com'!F8 -> Ameristar Ornamental Iron Fences and Gates
B20: 8 | C20: nov26-08-oklahoma-wind | D20: ='preferredfencesolutions.com'!F9 -> The Best Fence for Oklahoma Wind
B21: 9 | C21: nov26-09-faq-post-failure | D21: ='preferredfencesolutions.com'!F10 -> FAQ: Why Do Fence Posts Lean in Oklahoma?
B22: 10 | C22: nov26-10-sheet-metal-commercial | D22: ='preferredfencesolutions.com'!F11 -> Sheet Metal Fence for Commercial Properties
B23: 11 | C23: nov26-11-doggie-window | D23: ='preferredfencesolutions.com'!F12 -> Add a Custom Doggie Window to Your Fence
B24: 12 | C24: nov26-12-chain-link | D24: ='preferredfencesolutions.com'!F13 -> Chain Link Fencing: Galvanized or Black Vinyl-Coated
... B34: 22 | C34: nov26-22-year-end-awards | D34: ='preferredfencesolutions.com'!F23 -> Thank You, Oklahoma City

Sheet Banner & Brand Kit
A1: Banner and brand kit
A2: Every banner uses the website's own logo, colours and fonts. Size 1200 x 900 px (4:3), the ratio GBP displays best.
B4: Item | C4: Value | D4: Note
B5: Logo source (website) | C5: https://preferredfencesolutions.com/wp-content/uploads/2021/03/PFS-Logo-1.png | D5: Logo name and tagline on a white rounded chip. The phone number line in the original logo is cropped out to follow GBP rules.
B6: Banner size | C6: 1200 x 900 px PNG | D6: 4:3 ratio. Files are in deliverables/gbp-calendars/banners/preferred-fence/
B7: Brand motif | C7: Yellow picket fence line along the bottom edge. | D7: Gives the series a consistent, premium look
B8: Photos | C8: Real project photos from preferredfencesolutions.com | D8: Source URL for every banner is on the calendar tab
B9: Font: Headings | C9: Rubik | D9: Same as website headings
B10: Font: Body / labels | C10: Roboto | D10: Same as website body text
B12: Colour palette (matched to the website)
B13: Colour | C13: Hex | D13: Where it comes from | E13: Used on banners for | F13: Swatch
B14: Black | C14: #000000 | D14: Website header, footer and text (Elementor global) | E14: Background panels
B15: Accent yellow | C15: #DEE101 | D15: Website buttons and highlights (Elementor global) | E15: Headline accent word, button chips, picket motif
B16: Off-white | C16: #F4F4F4 | D16: Website section backgrounds | E16: Light panels
B17: White | C17: #FFFFFF | D17: Website background | E17: Text on dark, logo chip
B19: Overlay text rules (GBP safe)
B20: Rule | C20: Detail
B21: Length | C21: Tag 2 to 4 words, headline 3 to 7 words, one sub-line, one button label.
B22: Contact details | C22: No phone numbers, emails, web addresses or social handles on any banner.
B23: Claims | C23: Only facts stated on the website (years in business, warranties, services, offers).
B24: Offers | C24: Offer banners match the GBP Offer title. Dates and terms live in the post, not on the image.
B25: Safe area | C25: Text and logo stay inside the centre 1000 x 750 px so the GBP thumbnail crop never cuts them.
B26: Templates used | C26: Split photo, offer card, FAQ question, local spotlight, glass panel, 3-up compare, diagonal, frame, before/after, project spotlight, seasonal thank-you.

Sheet Image Rights Check
A1: Image rights cross-check
A2: Every banner photo is either the business's own photo from its website or a free Unsplash photo. Checked Oct 26, 2026.
A4: Post # | B4: Date | C4: Photo | D4: Source URL | E4: Origin | F4: Evidence checked | G4: Verdict
A5: 1 | B5: 46328 | C5: unsplash_km_VQEFOV20.jpg | D5: https://unsplash.com/photos/km_VQEFOV20 (Unsplash licence) | E5: Unsplash | F5: Downloaded through the official Unsplash API; free photo, not Unsplash+; No photographer credit, stock agency tag or watermark | G5: OK: royalty-free (Unsplash License)
A6: 2 | B6: 46329 | C6: IMG_5913.jpg | D6: https://preferredfencesolutions.com/wp-content/uploads/2022/05/IMG_5913.jpg | E6: Business website | F6: In the preferredfencesolutions.com media library (wp-content/uploads); No photographer credit, stock agency tag or watermark | G6: OK: business's own photo
A7: 3 | B7: 46330 | C7: Stained-Western-Red-Cedar-with-Cap-and-Trim-with-a-1x6-Kickboard.jpg | D7: https://preferredfencesolutions.com/wp-content/uploads/2022/10/Stained-Western-Red-Cedar-with-Cap-and-Trim-with-a-1x6-Kickboard.jpg | E7: Business website | F7: In the preferredfencesolutions.com media library (wp-content/uploads); No photographer credit, stock agency tag or watermark | G7: OK: business's own photo
A8: 4 | B8: 46331 | C8: IMG_01991-2.jpg | D8: https://preferredfencesolutions.com/wp-content/uploads/2022/01/IMG_01991-2.jpg | E8: Business website | F8: In the preferredfencesolutions.com media library (wp-content/uploads); No photographer credit, stock agency tag or watermark | G8: OK: business's own photo
A9: 5 | B9: 46332 | C9: 6-tall-Cap-and-Trim-Total-Privacy-Board-on-Board.-.jpeg | D9: https://preferredfencesolutions.com/wp-content/uploads/2022/03/6-tall-Cap-and-Trim-Total-Privacy-Board-on-Board.-.jpeg | E9: Business website | F9: In the preferredfencesolutions.com media library (wp-content/uploads); No photographer credit, stock agency tag or watermark | G9: OK: business's own photo
A10: 6 | B10: 46335 | C10: new-vs-old.jpeg | D10: https://preferredfencesolutions.com/wp-content/uploads/2022/06/new-vs-old.jpeg | E10: Business website | F10: In the preferredfencesolutions.com media library (wp-content/uploads); No photographer credit, stock agency tag or watermark | G10: OK: business's own photo
A11: 7 | B11: 46336 | C11: Arched-ornamental-iron-double-gate-custom-Letter-2.jpg | D11: https://preferredfencesolutions.com/wp-content/uploads/2022/05/Arched-ornamental-iron-double-gate-custom-Letter-2.jpg | E11: Business website | F11: In the preferredfencesolutions.com media library (wp-content/uploads); No photographer credit, stock agency tag or watermark | G11: OK: business's own photo
A12: 8 | B12: 46337 | C12: IMG_8799-scaled.jpg | D12: https://preferredfencesolutions.com/wp-content/uploads/2021/12/IMG_8799-scaled.jpg | E12: Business website | F12: In the preferredfencesolutions.com media library (wp-content/uploads); No photographer credit, stock agency tag or watermark | G12: OK: business's own photo
A13: 9 | B13: 46338 | C13: IMG_5922.jpg | D13: https://preferredfencesolutions.com/wp-content/uploads/2021/12/IMG_5922.jpg | E13: Business website | F13: In the preferredfencesolutions.com media library (wp-content/uploads); No photographer credit, stock agency tag or watermark | G13: OK: business's own photo
A14: 10 | B14: 46339 | C14: 4800-S-Sunnylane-Rd_Completed-Pic-5-scaled.jpg | D14: https://preferredfencesolutions.com/wp-content/uploads/2026/05/4800-S-Sunnylane-Rd_Completed-Pic-5-scaled.jpg | E14: Business website | F14: In the preferredfencesolutions.com media library (wp-content/uploads); No photographer credit, stock agency tag or watermark | G14: OK: business's own photo
A15: 11 | B15: 46342 | C15: bassethound-doggie-window.jpeg | D15: https://preferredfencesolutions.com/wp-content/uploads/2022/07/bassethound-doggie-window.jpeg | E15: Business website | F15: In the preferredfencesolutions.com media library (wp-content/uploads); No photographer credit, stock agency tag or watermark | G15: OK: business's own photo
A16: 12 | B16: 46343 | C16: 4-black-chain-link.jpg | D16: https://preferredfencesolutions.com/wp-content/uploads/2022/01/4-black-chain-link.jpg | E16: Business website | F16: In the preferredfencesolutions.com media library (wp-content/uploads); No photographer credit, stock agency tag or watermark | G16: OK: business's own photo
... A28: 22 | B28: 46357 | C28: o-2.jpg | D28: https://preferredfencesolutions.com/wp-content/uploads/2022/07/o-2.jpg | E28: Business website | F28: In the preferredfencesolutions.com media library (wp-content/uploads); No photographer credit, stock agency tag or watermark | G28: OK: business's own photo
A30: Photos OK | B30: =COUNTIF(G5:G28,"OK*")&" of "&COUNTA(G5:G28) -> 24 of 24
A32: Photos removed during the check
A33: # | B33: Photo removed | C33: Reason | D33: Replaced with
A34: 1 | B34: fence-damage.jpg (2 banners) | C34: No camera data, uploaded in 2026 and sized 1376 x 768, which matches AI-generated images; origin cannot be confirmed | D34: IMG_5914.jpg and IMG_0730001.jpg (own project photos)
A36: Note: photos on the business's own website are treated as owned by the business. Ask the client to confirm they took these photos or hold the rights. Unsplash photos can be used commercially without credit, but do not show people or brands in a way that suggests endorsement.

Sheet Website Offers Check
A1: Offers on the website vs. this calendar
A2: Every page of preferredfencesolutions.com was checked on Oct 26, 2026. Posts only promote offers the website states.
A4: # | B4: Offer | C4: Exact wording on the website | D4: Page | E4: Used in post # | F4: Note
A5: 1 | B5: Free estimate on all projects | C5: We offer free estimates on all fence & gate requests. | D5: https://preferredfencesolutions.com/fence-installation-repair-north-okc/ | E5: 1, 2 (Offer post), 4, 12, 13, 14, 15, 16 (Offer post), 20 (Offer post) | F5: Live on many pages. This is the main offer for this business.
A6: 2 | B6: Financing for larger projects | C6: Financing options are available for larger projects; ask us during your free estimate. | D6: https://preferredfencesolutions.com/why-preferred-fence-solutions-is-oklahoma-citys-trusted-fence-contractor/ | E6: 2, 16 | F6: Added after this check. Rates and terms are not on the website, so posts do not quote any.
A7: 3 | B7: 1-year warranty on fences and gates | C7: We warranty all of our fences, including gates, for an entire year. | D7: https://preferredfencesolutions.com/faq/ | E7: 14, 22 | F7: Used as stated.
A8: 4 | B8: 20-year warranty on Ameristar iron | C8: They also come backed by a 20-year warranty | D8: https://preferredfencesolutions.com/ornamental-iron-fence/ | E8: 7 | F8: Added to the Ameristar post after this check.
A9: 5 | B9: Design and planning help | C9: If you know you are in need of a fence ... but you're unsure of what style, design, or material to use, we can help! | D9: https://preferredfencesolutions.com/fence-design-planning/ | E9: 16 | F9: The website does not call this a free consultation. Post 16 was changed from 'Free Design Consultation' to 'Design Help With Every Free Estimate'.
A10: 6 | B10: Discounts / coupons / % off | C10: None found | D10: All 141 pages checked | E10: Not used | F10: No price discount, coupon, seasonal sale or military/senior discount is on the website.

Sheet GBP Guidelines
A1: Google Business Profile post rules applied to this calendar
A2: Every post and banner was written and checked against these rules.
A4: # | B4: Rule | C4: How this calendar follows it | D4: Source
A5: 1 | B5: No phone numbers in post text. | C5: No post contains a phone number. Calls are tracked through the GBP Call button and Performance report instead. | D5: https://support.google.com/business/answer/7213077
A6: 2 | B6: Google may remove posts that contain unverified contact info such as email addresses or social media handles. | C6: No emails or social handles are written in any post. | D6: https://support.google.com/business/answer/7213077
A7: 3 | B7: Posts may not include links to websites not related to the business (Oct 2026 policy update). | C7: Every CTA links to a page on the business's own website. No links are written in the post text. | D7: https://www.relevantaudience.com/seo/google-business-profile-policy-bans-promotions-in-listings/ (reporting Google's Oct 6, 2026 update)
A8: 4 | B8: Offer posts need a title and start and end dates; coupon code, link and terms are optional. Offers get an automatic View offer button. | C8: All Offer posts have a title of 58 characters or fewer, dates and terms in the Offer Dates / Terms column. | D8: https://support.google.com/business/answer/7342169
A9: 5 | B9: Update posts can carry one action button with a link (book, order online, learn more and similar). | C9: Every Update post has one CTA button with a tracked link. | D9: https://support.google.com/business/answer/7342169
A10: 6 | B10: Post descriptions are limited to 1,500 characters. | C10: All posts are well under the limit; the QA tab checks this automatically. | D10: GBP post editor limit (Google Business Profile Manager)
A11: 7 | B11: Posts older than 6 months are archived unless a date range is set. | C11: Fresh posts go out twice a week so the profile always shows recent content. | D11: https://support.google.com/business/answer/7342169
A12: 8 | B12: Content must be relevant to the business and not low quality (no gibberish, misspellings or irrelevant content). | C12: Every post is about a real service, FAQ, local topic or offer taken from the website. | D12: https://support.google.com/business/answer/3038177
A13: 9 | B13: Promotions must clearly state their terms. | C13: Each offer lists dates and terms to confirm with the client before publishing. | D13: https://support.google.com/business/answer/3038177
A14: 10 | B14: Do not ask for personal or confidential information. | C14: CTAs send users to the website contact or booking pages; posts never ask for personal data. | D14: https://support.google.com/business/answer/3038177
A15: 11 | B15: You are responsible for making sure post content complies with applicable laws. | C15: Claims are limited to facts stated on the website. Items needing client confirmation are flagged in Notes. | D15: https://support.google.com/business/answer/7213077
A16: 12 | B16: Photos must follow the photo policy: real, relevant to the business, not misleading. | C16: Every banner uses a real photo from the business's own website (one HG post uses a licensed Unsplash photo). Overlay text is short (headline plus one line), with no phone numbers, emails, prices or claims that are not on the website. | D16: https://support.google.com/business/answer/7213077
A17: 13 | B17: Recommended post image: JPG or PNG, 10 KB to 5 MB, at least 400 x 300 px, 4:3 ratio displays best. | C17: Banners are 1200 x 900 px PNG (4:3). Key text sits inside the centre safe area so the GBP crop does not cut it. | D17: https://support.google.com/business/answer/7342169

Sheet QA Cross-Check
A1: QA cross-check (automatic)
A2: Formulas re-check every post when copy or links change. Every row should read Pass before scheduling.
A4: Post # | B4: Date | C4: Characters | D4: Max 1,500 chars | E4: No phone in text | F4: No email in text | G4: No link in text | H4: CTA set | I4: UTM on CTA link | J4: Link on business website | K4: Weekday (Mon to Fri) | L4: Banner file set | M4: Overall
A5: 1 | B5: ='preferredfencesolutions.com'!C2 -> 46328 | C5: =LEN('preferredfencesolutions.com'!G2) -> 503 | D5: =IF(LEN('preferredfencesolutions.com'!G2)<=1500,"Pass","Fail") -> Pass | E5: =IF(SUMPRODUCT(--ISNUMBER(SEARCH({"405","921-3426","473-2695","9213426"},'preferredfencesolutions.com'!G2)))=0,"Pass","Fail") -> Pass | F5: =IF(ISNUMBER(SEARCH("@",'preferredfencesolutions.com'!G2)),"Fail","Pass") -> Pass | G5: =IF(OR(ISNUMBER(SEARCH("http",'preferredfencesolutions.com'!G2)),ISNUMBER(SEARCH("www.",'preferredfencesolutions.com'!G2)),ISNUMBER(SEARCH(".com",'preferredfencesolutions.com'!G2))),"Fail","Pass") -> Pass | H5: =IF(LEN('preferredfencesolutions.com'!H2)>0,"Pass","Fail") -> Pass | I5: =IF(AND(ISNUMBER(SEARCH("utm_source=google",'preferredfencesolutions.com'!J2)),ISNUMBER(SEARCH("utm_content=",'preferredfencesolutions.com'!J2))),"Pass","Fail") -> Pass | J5: =IF(ISNUMBER(SEARCH(Settings!$C$8,'preferredfencesolutions.com'!I2)),"Pass","Fail") -> Pass | K5: =IF(WEEKDAY('preferredfencesolutions.com'!C2,2)<=5,"Pass","Fail") -> Pass | L5: =IF(LEN('preferredfencesolutions.com'!M2)>0,"Pass","Fail") -> Pass | M5: =IF(COUNTIF(D5:L5,"Fail")=0,"Pass","Fail") -> Pass
A6: 2 | B6: ='preferredfencesolutions.com'!C3 -> 46329 | C6: =LEN('preferredfencesolutions.com'!G3) -> 449 | D6: =IF(LEN('preferredfencesolutions.com'!G3)<=1500,"Pass","Fail") -> Pass | E6: =IF(SUMPRODUCT(--ISNUMBER(SEARCH({"405","921-3426","473-2695","9213426"},'preferredfencesolutions.com'!G3)))=0,"Pass","Fail") -> Pass | F6: =IF(ISNUMBER(SEARCH("@",'preferredfencesolutions.com'!G3)),"Fail","Pass") -> Pass | G6: =IF(OR(ISNUMBER(SEARCH("http",'preferredfencesolutions.com'!G3)),ISNUMBER(SEARCH("www.",'preferredfencesolutions.com'!G3)),ISNUMBER(SEARCH(".com",'preferredfencesolutions.com'!G3))),"Fail","Pass") -> Pass | H6: =IF(LEN('preferredfencesolutions.com'!H3)>0,"Pass","Fail") -> Pass | I6: =IF(AND(ISNUMBER(SEARCH("utm_source=google",'preferredfencesolutions.com'!J3)),ISNUMBER(SEARCH("utm_content=",'preferredfencesolutions.com'!J3))),"Pass","Fail") -> Pass | J6: =IF(ISNUMBER(SEARCH(Settings!$C$8,'preferredfencesolutions.com'!I3)),"Pass","Fail") -> Pass | K6: =IF(WEEKDAY('preferredfencesolutions.com'!C3,2)<=5,"Pass","Fail") -> Pass | L6: =IF(LEN('preferredfencesolutions.com'!M3)>0,"Pass","Fail") -> Pass | M6: =IF(COUNTIF(D6:L6,"Fail")=0,"Pass","Fail") -> Pass
A7: 3 | B7: ='preferredfencesolutions.com'!C4 -> 46330 | C7: =LEN('preferredfencesolutions.com'!G4) -> 462 | D7: =IF(LEN('preferredfencesolutions.com'!G4)<=1500,"Pass","Fail") -> Pass | E7: =IF(SUMPRODUCT(--ISNUMBER(SEARCH({"405","921-3426","473-2695","9213426"},'preferredfencesolutions.com'!G4)))=0,"Pass","Fail") -> Pass | F7: =IF(ISNUMBER(SEARCH("@",'preferredfencesolutions.com'!G4)),"Fail","Pass") -> Pass | G7: =IF(OR(ISNUMBER(SEARCH("http",'preferredfencesolutions.com'!G4)),ISNUMBER(SEARCH("www.",'preferredfencesolutions.com'!G4)),ISNUMBER(SEARCH(".com",'preferredfencesolutions.com'!G4))),"Fail","Pass") -> Pass | H7: =IF(LEN('preferredfencesolutions.com'!H4)>0,"Pass","Fail") -> Pass | I7: =IF(AND(ISNUMBER(SEARCH("utm_source=google",'preferredfencesolutions.com'!J4)),ISNUMBER(SEARCH("utm_content=",'preferredfencesolutions.com'!J4))),"Pass","Fail") -> Pass | J7: =IF(ISNUMBER(SEARCH(Settings!$C$8,'preferredfencesolutions.com'!I4)),"Pass","Fail") -> Pass | K7: =IF(WEEKDAY('preferredfencesolutions.com'!C4,2)<=5,"Pass","Fail") -> Pass | L7: =IF(LEN('preferredfencesolutions.com'!M4)>0,"Pass","Fail") -> Pass | M7: =IF(COUNTIF(D7:L7,"Fail")=0,"Pass","Fail") -> Pass
A8: 4 | B8: ='preferredfencesolutions.com'!C5 -> 46331 | C8: =LEN('preferredfencesolutions.com'!G5) -> 476 | D8: =IF(LEN('preferredfencesolutions.com'!G5)<=1500,"Pass","Fail") -> Pass | E8: =IF(SUMPRODUCT(--ISNUMBER(SEARCH({"405","921-3426","473-2695","9213426"},'preferredfencesolutions.com'!G5)))=0,"Pass","Fail") -> Pass | F8: =IF(ISNUMBER(SEARCH("@",'preferredfencesolutions.com'!G5)),"Fail","Pass") -> Pass | G8: =IF(OR(ISNUMBER(SEARCH("http",'preferredfencesolutions.com'!G5)),ISNUMBER(SEARCH("www.",'preferredfencesolutions.com'!G5)),ISNUMBER(SEARCH(".com",'preferredfencesolutions.com'!G5))),"Fail","Pass") -> Pass | H8: =IF(LEN('preferredfencesolutions.com'!H5)>0,"Pass","Fail") -> Pass | I8: =IF(AND(ISNUMBER(SEARCH("utm_source=google",'preferredfencesolutions.com'!J5)),ISNUMBER(SEARCH("utm_content=",'preferredfencesolutions.com'!J5))),"Pass","Fail") -> Pass | J8: =IF(ISNUMBER(SEARCH(Settings!$C$8,'preferredfencesolutions.com'!I5)),"Pass","Fail") -> Pass | K8: =IF(WEEKDAY('preferredfencesolutions.com'!C5,2)<=5,"Pass","Fail") -> Pass | L8: =IF(LEN('preferredfencesolutions.com'!M5)>0,"Pass","Fail") -> Pass | M8: =IF(COUNTIF(D8:L8,"Fail")=0,"Pass","Fail") -> Pass
A9: 5 | B9: ='preferredfencesolutions.com'!C6 -> 46332 | C9: =LEN('preferredfencesolutions.com'!G6) -> 432 | D9: =IF(LEN('preferredfencesolutions.com'!G6)<=1500,"Pass","Fail") -> Pass | E9: =IF(SUMPRODUCT(--ISNUMBER(SEARCH({"405","921-3426","473-2695","9213426"},'preferredfencesolutions.com'!G6)))=0,"Pass","Fail") -> Pass | F9: =IF(ISNUMBER(SEARCH("@",'preferredfencesolutions.com'!G6)),"Fail","Pass") -> Pass | G9: =IF(OR(ISNUMBER(SEARCH("http",'preferredfencesolutions.com'!G6)),ISNUMBER(SEARCH("www.",'preferredfencesolutions.com'!G6)),ISNUMBER(SEARCH(".com",'preferredfencesolutions.com'!G6))),"Fail","Pass") -> Pass | H9: =IF(LEN('preferredfencesolutions.com'!H6)>0,"Pass","Fail") -> Pass | I9: =IF(AND(ISNUMBER(SEARCH("utm_source=google",'preferredfencesolutions.com'!J6)),ISNUMBER(SEARCH("utm_content=",'preferredfencesolutions.com'!J6))),"Pass","Fail") -> Pass | J9: =IF(ISNUMBER(SEARCH(Settings!$C$8,'preferredfencesolutions.com'!I6)),"Pass","Fail") -> Pass | K9: =IF(WEEKDAY('preferredfencesolutions.com'!C6,2)<=5,"Pass","Fail") -> Pass | L9: =IF(LEN('preferredfencesolutions.com'!M6)>0,"Pass","Fail") -> Pass | M9: =IF(COUNTIF(D9:L9,"Fail")=0,"Pass","Fail") -> Pass
A10: 6 | B10: ='preferredfencesolutions.com'!C7 -> 46335 | C10: =LEN('preferredfencesolutions.com'!G7) -> 485 | D10: =IF(LEN('preferredfencesolutions.com'!G7)<=1500,"Pass","Fail") -> Pass | E10: =IF(SUMPRODUCT(--ISNUMBER(SEARCH({"405","921-3426","473-2695","9213426"},'preferredfencesolutions.com'!G7)))=0,"Pass","Fail") -> Pass | F10: =IF(ISNUMBER(SEARCH("@",'preferredfencesolutions.com'!G7)),"Fail","Pass") -> Pass | G10: =IF(OR(ISNUMBER(SEARCH("http",'preferredfencesolutions.com'!G7)),ISNUMBER(SEARCH("www.",'preferredfencesolutions.com'!G7)),ISNUMBER(SEARCH(".com",'preferredfencesolutions.com'!G7))),"Fail","Pass") -> Pass | H10: =IF(LEN('preferredfencesolutions.com'!H7)>0,"Pass","Fail") -> Pass | I10: =IF(AND(ISNUMBER(SEARCH("utm_source=google",'preferredfencesolutions.com'!J7)),ISNUMBER(SEARCH("utm_content=",'preferredfencesolutions.com'!J7))),"Pass","Fail") -> Pass | J10: =IF(ISNUMBER(SEARCH(Settings!$C$8,'preferredfencesolutions.com'!I7)),"Pass","Fail") -> Pass | K10: =IF(WEEKDAY('preferredfencesolutions.com'!C7,2)<=5,"Pass","Fail") -> Pass | L10: =IF(LEN('preferredfencesolutions.com'!M7)>0,"Pass","Fail") -> Pass | M10: =IF(COUNTIF(D10:L10,"Fail")=0,"Pass","Fail") -> Pass
A11: 7 | B11: ='preferredfencesolutions.com'!C8 -> 46336 | C11: =LEN('preferredfencesolutions.com'!G8) -> 487 | D11: =IF(LEN('preferredfencesolutions.com'!G8)<=1500,"Pass","Fail") -> Pass | E11: =IF(SUMPRODUCT(--ISNUMBER(SEARCH({"405","921-3426","473-2695","9213426"},'preferredfencesolutions.com'!G8)))=0,"Pass","Fail") -> Pass | F11: =IF(ISNUMBER(SEARCH("@",'preferredfencesolutions.com'!G8)),"Fail","Pass") -> Pass | G11: =IF(OR(ISNUMBER(SEARCH("http",'preferredfencesolutions.com'!G8)),ISNUMBER(SEARCH("www.",'preferredfencesolutions.com'!G8)),ISNUMBER(SEARCH(".com",'preferredfencesolutions.com'!G8))),"Fail","Pass") -> Pass | H11: =IF(LEN('preferredfencesolutions.com'!H8)>0,"Pass","Fail") -> Pass | I11: =IF(AND(ISNUMBER(SEARCH("utm_source=google",'preferredfencesolutions.com'!J8)),ISNUMBER(SEARCH("utm_content=",'preferredfencesolutions.com'!J8))),"Pass","Fail") -> Pass | J11: =IF(ISNUMBER(SEARCH(Settings!$C$8,'preferredfencesolutions.com'!I8)),"Pass","Fail") -> Pass | K11: =IF(WEEKDAY('preferredfencesolutions.com'!C8,2)<=5,"Pass","Fail") -> Pass | L11: =IF(LEN('preferredfencesolutions.com'!M8)>0,"Pass","Fail") -> Pass | M11: =IF(COUNTIF(D11:L11,"Fail")=0,"Pass","Fail") -> Pass
A12: 8 | B12: ='preferredfencesolutions.com'!C9 -> 46337 | C12: =LEN('preferredfencesolutions.com'!G9) -> 451 | D12: =IF(LEN('preferredfencesolutions.com'!G9)<=1500,"Pass","Fail") -> Pass | E12: =IF(SUMPRODUCT(--ISNUMBER(SEARCH({"405","921-3426","473-2695","9213426"},'preferredfencesolutions.com'!G9)))=0,"Pass","Fail") -> Pass | F12: =IF(ISNUMBER(SEARCH("@",'preferredfencesolutions.com'!G9)),"Fail","Pass") -> Pass | G12: =IF(OR(ISNUMBER(SEARCH("http",'preferredfencesolutions.com'!G9)),ISNUMBER(SEARCH("www.",'preferredfencesolutions.com'!G9)),ISNUMBER(SEARCH(".com",'preferredfencesolutions.com'!G9))),"Fail","Pass") -> Pass | H12: =IF(LEN('preferredfencesolutions.com'!H9)>0,"Pass","Fail") -> Pass | I12: =IF(AND(ISNUMBER(SEARCH("utm_source=google",'preferredfencesolutions.com'!J9)),ISNUMBER(SEARCH("utm_content=",'preferredfencesolutions.com'!J9))),"Pass","Fail") -> Pass | J12: =IF(ISNUMBER(SEARCH(Settings!$C$8,'preferredfencesolutions.com'!I9)),"Pass","Fail") -> Pass | K12: =IF(WEEKDAY('preferredfencesolutions.com'!C9,2)<=5,"Pass","Fail") -> Pass | L12: =IF(LEN('preferredfencesolutions.com'!M9)>0,"Pass","Fail") -> Pass | M12: =IF(COUNTIF(D12:L12,"Fail")=0,"Pass","Fail") -> Pass
A13: 9 | B13: ='preferredfencesolutions.com'!C10 -> 46338 | C13: =LEN('preferredfencesolutions.com'!G10) -> 460 | D13: =IF(LEN('preferredfencesolutions.com'!G10)<=1500,"Pass","Fail") -> Pass | E13: =IF(SUMPRODUCT(--ISNUMBER(SEARCH({"405","921-3426","473-2695","9213426"},'preferredfencesolutions.com'!G10)))=0,"Pass","Fail") -> Pass | F13: =IF(ISNUMBER(SEARCH("@",'preferredfencesolutions.com'!G10)),"Fail","Pass") -> Pass | G13: =IF(OR(ISNUMBER(SEARCH("http",'preferredfencesolutions.com'!G10)),ISNUMBER(SEARCH("www.",'preferredfencesolutions.com'!G10)),ISNUMBER(SEARCH(".com",'preferredfencesolutions.com'!G10))),"Fail","Pass") -> Pass | H13: =IF(LEN('preferredfencesolutions.com'!H10)>0,"Pass","Fail") -> Pass | I13: =IF(AND(ISNUMBER(SEARCH("utm_source=google",'preferredfencesolutions.com'!J10)),ISNUMBER(SEARCH("utm_content=",'preferredfencesolutions.com'!J10))),"Pass","Fail") -> Pass | J13: =IF(ISNUMBER(SEARCH(Settings!$C$8,'preferredfencesolutions.com'!I10)),"Pass","Fail") -> Pass | K13: =IF(WEEKDAY('preferredfencesolutions.com'!C10,2)<=5,"Pass","Fail") -> Pass | L13: =IF(LEN('preferredfencesolutions.com'!M10)>0,"Pass","Fail") -> Pass | M13: =IF(COUNTIF(D13:L13,"Fail")=0,"Pass","Fail") -> Pass
A14: 10 | B14: ='preferredfencesolutions.com'!C11 -> 46339 | C14: =LEN('preferredfencesolutions.com'!G11) -> 431 | D14: =IF(LEN('preferredfencesolutions.com'!G11)<=1500,"Pass","Fail") -> Pass | E14: =IF(SUMPRODUCT(--ISNUMBER(SEARCH({"405","921-3426","473-2695","9213426"},'preferredfencesolutions.com'!G11)))=0,"Pass","Fail") -> Pass | F14: =IF(ISNUMBER(SEARCH("@",'preferredfencesolutions.com'!G11)),"Fail","Pass") -> Pass | G14: =IF(OR(ISNUMBER(SEARCH("http",'preferredfencesolutions.com'!G11)),ISNUMBER(SEARCH("www.",'preferredfencesolutions.com'!G11)),ISNUMBER(SEARCH(".com",'preferredfencesolutions.com'!G11))),"Fail","Pass") -> Pass | H14: =IF(LEN('preferredfencesolutions.com'!H11)>0,"Pass","Fail") -> Pass | I14: =IF(AND(ISNUMBER(SEARCH("utm_source=google",'preferredfencesolutions.com'!J11)),ISNUMBER(SEARCH("utm_content=",'preferredfencesolutions.com'!J11))),"Pass","Fail") -> Pass | J14: =IF(ISNUMBER(SEARCH(Settings!$C$8,'preferredfencesolutions.com'!I11)),"Pass","Fail") -> Pass | K14: =IF(WEEKDAY('preferredfencesolutions.com'!C11,2)<=5,"Pass","Fail") -> Pass | L14: =IF(LEN('preferredfencesolutions.com'!M11)>0,"Pass","Fail") -> Pass | M14: =IF(COUNTIF(D14:L14,"Fail")=0,"Pass","Fail") -> Pass
A15: 11 | B15: ='preferredfencesolutions.com'!C12 -> 46342 | C15: =LEN('preferredfencesolutions.com'!G12) -> 405 | D15: =IF(LEN('preferredfencesolutions.com'!G12)<=1500,"Pass","Fail") -> Pass | E15: =IF(SUMPRODUCT(--ISNUMBER(SEARCH({"405","921-3426","473-2695","9213426"},'preferredfencesolutions.com'!G12)))=0,"Pass","Fail") -> Pass | F15: =IF(ISNUMBER(SEARCH("@",'preferredfencesolutions.com'!G12)),"Fail","Pass") -> Pass | G15: =IF(OR(ISNUMBER(SEARCH("http",'preferredfencesolutions.com'!G12)),ISNUMBER(SEARCH("www.",'preferredfencesolutions.com'!G12)),ISNUMBER(SEARCH(".com",'preferredfencesolutions.com'!G12))),"Fail","Pass") -> Pass | H15: =IF(LEN('preferredfencesolutions.com'!H12)>0,"Pass","Fail") -> Pass | I15: =IF(AND(ISNUMBER(SEARCH("utm_source=google",'preferredfencesolutions.com'!J12)),ISNUMBER(SEARCH("utm_content=",'preferredfencesolutions.com'!J12))),"Pass","Fail") -> Pass | J15: =IF(ISNUMBER(SEARCH(Settings!$C$8,'preferredfencesolutions.com'!I12)),"Pass","Fail") -> Pass | K15: =IF(WEEKDAY('preferredfencesolutions.com'!C12,2)<=5,"Pass","Fail") -> Pass | L15: =IF(LEN('preferredfencesolutions.com'!M12)>0,"Pass","Fail") -> Pass | M15: =IF(COUNTIF(D15:L15,"Fail")=0,"Pass","Fail") -> Pass
