Workbook

Sheet Overview
A1: Preferred Fence Solutions: GBP Content Calendar and Citations
A2: 22 Google Business Profile posts in 11 weekly batches, plus citation work. Prepared Oct 26, 2026.
A4: Business snapshot (from the website)
A5: Field | B5: Value | C5: Source / note
A6: Business name | B6: Preferred Fence Solutions, Inc. | C6: Website, FAQ and GBP links
A7: Address | B7: 8071 N. Classen Boulevard, Suite A, Oklahoma City, OK 73114 | C7: Website footer and Google link on site
A8: Phone | B8: (405) 921-3426 main line; (405) 473-2695 general administration | C8: Website footer
A9: Hours | B9: Mon to Fri 7 AM to 4 PM; Sat 7 AM to 11 AM | C9: Website footer
A10: Service area | B10: Oklahoma City, North OKC, Edmond, Yukon, Mustang, Nichols Hills, Piedmont, The Village (OKC metro) | C10: Home and service pages
A11: Main services | B11: Fence installation and repair; Western Red Cedar stockade (wood) fences; vinyl; Ameristar ornamental iron; chain link (galvanized and black vinyl-coated); SimTek; sheet metal / ribbed panel (commercial); custom gates, cantilever gates, gate operators; fence design and planning | C11: Service pages
A12: Active offers | B12: Free estimates on all projects; free design and planning help; custom doggie windows add-on | C12: Stockade, North OKC and Design pages
A13: Trust signals | B13: Licensed and insured; 1-year warranty on all fences and gates; panels custom built in their own shop; steel posts set in concrete 2 ft below grade; 100% USA fence products; local awards | C13: Service pages, Awards page
A14: Reviews | B14: 4.7 stars from 143 Google reviews; 3.9 from 7 Yelp reviews (third-party summary) | C14: https://www.expertise.com/ok/oklahoma-city/fence-companies (needs confirming in GBP)
A15: Social profiles | B15: Facebook: facebook.com/preferredfencesolutions; Instagram: instagram.com/preferredfencesolutions; Thumbtack; BBB | C15: Website header and footer
A16: Posting window | B16: Nov 3, 2026 to Jan 21, 2027: 2 posts per week (Tue and Thu, with holiday adjustments) | C16: This plan
A18: Tracking settings (edit here, all CTA links update)
A19: Setting | B19: Value | C19: Note
A20: UTM source | B20: google | C20: Keep as google
A21: UTM medium | B21: organic | C21: Keep as organic
A22: UTM campaign | B22: gbp-posts-nov26-jan27 | C22: One campaign for this 22-post run
A23: Website domain | B23: preferredfencesolutions.com | C23: Used by the QA check that every link stays on the business website
A25: Post mix (counts update from the calendar)
A26: Category | B26: Posts | C26: Share
A27: Service | B27: =COUNTIF('Content Calendar'!$E$5:$E$26,"Service") -> 8 | C27: =IFERROR(B27/B31,0) -> 0.36363636
A28: FAQ | B28: =COUNTIF('Content Calendar'!$E$5:$E$26,"FAQ") -> 5 | C28: =IFERROR(B28/B31,0) -> 0.22727273
A29: Local | B29: =COUNTIF('Content Calendar'!$E$5:$E$26,"Local") -> 5 | C29: =IFERROR(B29/B31,0) -> 0.22727273
A30: Promotional | B30: =COUNTIF('Content Calendar'!$E$5:$E$26,"Promotional") -> 4 | C30: =IFERROR(B30/B31,0) -> 0.18181818
A31: Total | B31: =SUM(B27:B30) -> 22 | C31: =SUM(C27:C30) -> 1
A33: How to use this workbook
A34: Tab / item | B34: What it is
A35: 1. Overview | B35: Business facts, tracking settings and the post mix.
A36: 2. Website & Profile Audit | B36: What we found on the website, socials and old GBP posts, with fixes to make before posting.
A37: 3. GBP Guidelines | B37: Google rules every post follows, with sources.
A38: 4. Content Calendar | B38: All 22 posts: date, type, copy, CTA button and tracked link. Edit only Post Copy, dates, Status and Notes.
A39: 5. Weekly Batches | B39: One batch per week (2 posts). Prep and schedule each batch on the Monday.
A40: 6. Citations | B40: NAP to use everywhere, plus the citation list with status tracking.
A41: 7. QA Cross-Check | B41: Automatic checks on every post (length, no phone or email in text, CTA, UTM, link domain). All rows should read Pass.
A42: Editable cells | B42: Status and Notes columns, post dates, post copy, citation Status / Date / Live URL. Tracked URLs, counts and QA cells are formulas: do not overwrite.
A43: Example row | B43: Row 5 of the Content Calendar (post 01) shows the expected format for every column.

Sheet Website & Profile Audit
A1: Website, social media and GBP audit
A2: Checked Oct 26, 2026. Fix High priority items before the first post goes live.
A4: # | B4: Area | C4: Finding | D4: Evidence (URL) | E4: Recommended action | F4: Priority
A5: 1 | B5: Old GBP posts | C5: Previous GBP posts could not be checked: posts are only visible inside the profile or on Google Search, and no manager access was available. | D5: https://g.page/preferredfencesolutions | E5: Share manager access or screenshots of the last 10 posts, so the new posts don't repeat topics. | F5: High
A6: 2 | B6: Yelp link | C6: The website's Yelp icon links to 'premier-fence-solutions-oklahoma-city-5', which looks like a different business name. | D6: https://www.yelp.com/biz/premier-fence-solutions-oklahoma-city-5 | E6: Check the Yelp listing name; correct it to Preferred Fence Solutions or fix the link on the website. | F6: High
A7: 3 | B7: Email typo | C7: The FAQ page lists 'preferredfencesoltuions@gmail.com' (letters swapped). | D7: https://preferredfencesolutions.com/faq/ | E7: Correct to the real email so customers can reach you, and use the same email on all citations. | F7: High
A8: 4 | B8: Founded year conflict | C8: Directories disagree: ThreeBestRated says since 2004, HomeGuide says founded 2017. | D8: https://threebestrated.com/fencing-contractors-in-oklahoma-city-ok ; https://homeguide.com/ok/edmond/fence-installation/preferred-fence-solutions--inc--Bg7QaScYM | E8: Confirm the correct year with the client and update the wrong directory. | F8: Medium
A9: 5 | B9: License flag | C9: BuildZoom showed 'No active license on file' (updated Oct 2024); the website says licensed and insured. | D9: https://www.buildzoom.com/contractor/preferred-fence-solutions | E9: Confirm the license number and update BuildZoom so the listing doesn't contradict the website. | F9: Medium
A10: 6 | B10: Contact page | C10: The Contact Us page returned '403 Forbidden' to our automated check. | D10: https://preferredfencesolutions.com/contact-us/ | E10: Test the page in a normal browser and on mobile. If real visitors are blocked, fix the security rule. Posts link to service pages for now. | F10: Medium
A11: 7 | B11: Two phone numbers | C11: The footer shows a main line and a general administration number. | D11: Website footer | E11: Use only the main line (405) 921-3426 on GBP and citations. | F11: Medium
A12: 8 | B12: Outdated year | C12: The fence cost guide headline says '2025 Expectations'. | D12: https://preferredfencesolutions.com/fence-cost-oklahoma-city/ | E12: Update it to 2026 before linking it from posts. It is not used in this calendar yet. | F12: Low
A13: 9 | B13: HomeAdvisor link | C13: The website's HomeAdvisor link goes to the HomeAdvisor homepage, not the company profile. | D13: https://www.homeadvisor.com/ | E13: Link it to the actual profile, or remove it. | F13: Low
A14: 10 | B14: Social media | C14: Facebook and Instagram are linked. Page content can't be read without logging in, so recent social posts were not reviewed. | D14: https://www.facebook.com/preferredfencesolutions/ | E14: Share each GBP post's photo and copy on Facebook and Instagram the same week. | F14: Low
A15: 11 | B15: Blog strength | C15: Recent, detailed local blogs (2025 to 2026) on wind, soil, gates, slopes and cedar make strong landing pages. | D15: https://preferredfencesolutions.com/fence-blog/ | E15: FAQ posts link to these blogs to build topical relevance. | F15: Low

Sheet GBP Guidelines
A1: Google Business Profile post rules applied to this calendar
A2: Every post in the calendar was written and checked against these rules.
A4: # | B4: Rule | C4: How this calendar follows it | D4: Source
A5: 1 | B5: No phone numbers in post text. | C5: No post contains a phone number. Calls are tracked through the GBP Call button and Performance report instead. | D5: https://support.google.com/business/answer/7213077
A6: 2 | B6: Google may remove posts that contain unverified contact info such as email addresses or social media handles. | C6: No emails or social handles are written in any post. | D6: https://support.google.com/business/answer/7213077
A7: 3 | B7: Posts may not include links to websites not related to the business (Oct 2026 policy update). | C7: Every CTA links to a page on the business's own website. No links are written in the post text. | D7: https://www.relevantaudience.com/seo/google-business-profile-policy-bans-promotions-in-listings/ (reporting Google's Oct 6, 2026 update)
A8: 4 | B8: Offer posts need a title and start and end dates; coupon code, link and terms are optional. Offers get an automatic View offer button. | C8: All Offer posts have a title of 58 characters or fewer, dates and terms in the Offer Dates / Terms column. | D8: https://support.google.com/business/answer/7342169
A9: 5 | B9: Update posts can carry one action button with a link (book, order online, learn more and similar). | C9: Every Update post has one CTA button with a tracked link. | D9: https://support.google.com/business/answer/7342169
A10: 6 | B10: Post descriptions are limited to 1,500 characters. | C10: All posts are well under the limit; the QA tab checks this automatically. | D10: GBP post editor limit (Google Business Profile Manager)
A11: 7 | B11: Posts older than 6 months are archived unless a date range is set. | C11: Fresh posts go out twice a week so the profile always shows recent content. | D11: https://support.google.com/business/answer/7342169
A12: 8 | B12: Content must be relevant to the business and not low quality (no gibberish, misspellings or irrelevant content). | C12: Every post is about a real service, FAQ, local topic or offer taken from the website. | D12: https://support.google.com/business/answer/3038177
A13: 9 | B13: Promotions must clearly state their terms. | C13: Each offer lists dates and terms to confirm with the client before publishing. | D13: https://support.google.com/business/answer/3038177
A14: 10 | B14: Do not ask for personal or confidential information. | C14: CTAs send users to the website contact or booking pages; posts never ask for personal data. | D14: https://support.google.com/business/answer/3038177
A15: 11 | B15: You are responsible for making sure post content complies with applicable laws. | C15: Claims are limited to facts stated on the website. Items needing client confirmation are flagged in Notes. | D15: https://support.google.com/business/answer/7213077
A16: 12 | B16: Photos must follow the photo and video policy (real, relevant, no added text-heavy overlays). | C16: Image briefs ask for real project photos, not stock images. | D16: https://support.google.com/business/answer/7213077

Sheet Content Calendar
A1: GBP Content Calendar: 22 posts
A2: Tracked CTA URL is built by formula from the landing page and the Overview tracking settings.
A4: Post ID | B4: Batch | C4: Publish Date | D4: Day | E4: Category | F4: GBP Post Type | G4: Topic | H4: Target Keyword | I4: Offer Title | J4: Post Copy | K4: Characters | L4: CTA Button | M4: Landing Page | N4: UTM Content | O4: Tracked CTA URL | P4: Offer Dates / Terms | Q4: Image Brief | R4: Status | S4: Notes / Confirm with Client
A5: PF-01 | B5: 1 | C5: 46329 | D5: =TEXT(C5,"ddd") -> Tue | E5: Service | F5: Update | G5: Fence repair after wind and storms | H5: fence repair Oklahoma City | J5: Leaning posts, broken panels or a gate that will not latch after the last windstorm? Preferred Fence Solutions repairs fences across the OKC metro, from a single leaning post to multi-section storm damage. We check whether a post can be reset and reinforced or needs replacing, and when we rebuild wood sections we use steel posts so the fence can stand up to Oklahoma wind. We give honest recommendations on repair versus replacement and free estimates on every job. Tap Learn more to schedule yours. | K5: =LEN(J5) -> 503 | L5: Learn more | M5: https://preferredfencesolutions.com/fence-repair-okc/ | N5: pf01-fence-repair | O5: =M5&"?utm_source="&Overview!$B$20&"&utm_medium="&Overview!$B$21&"&utm_campaign="&Overview!$B$22&"&utm_content="&N5 -> https://preferredfencesolutions.com/fence-repair-okc/?utm_source=google&utm_medium=organic&utm_campaign=gbp-posts-nov26-jan27&utm_content=pf01-fence-repair | Q5: Real before/after photo of a storm-damaged stockade section that the team repaired. | R5: Draft
A6: PF-02 | B6: 1 | C6: 46331 | D6: =TEXT(C6,"ddd") -> Thu | E6: FAQ | F6: Update | G6: How tall can my fence be in OKC? | H6: fence height Oklahoma City | J6: FAQ: How tall can my fence be in Oklahoma City? Residential fences in Oklahoma City can be up to 8 feet tall in most cases, and 6 feet is the most common choice for backyard privacy. HOA rules often add their own limits, especially in Edmond, Nichols Hills and newer neighborhoods, so check with your HOA before you build. Not sure what is allowed on your property? Our team can help you plan the right height and style. Tap Learn more to read more fence FAQs. | K6: =LEN(J6) -> 462 | L6: Learn more | M6: https://preferredfencesolutions.com/faq/ | N6: pf02-faq-fence-height | O6: =M6&"?utm_source="&Overview!$B$20&"&utm_medium="&Overview!$B$21&"&utm_campaign="&Overview!$B$22&"&utm_content="&N6 -> https://preferredfencesolutions.com/faq/?utm_source=google&utm_medium=organic&utm_campaign=gbp-posts-nov26-jan27&utm_content=pf02-faq-fence-height | Q6: Photo of a 6 ft stockade privacy fence installed by the team. | R6: Draft | S6: Fact check: keep wording as 'in most cases' and point to HOA and city rules.
A7: PF-03 | B7: 2 | C7: 46336 | D7: =TEXT(C7,"ddd") -> Tue | E7: Local | F7: Update | G7: Fence installation in Edmond | H7: fence installation Edmond OK | J7: Building a fence in Edmond? Preferred Fence Solutions has installed fences for Edmond homeowners for years, with local projects and references available. We install wood privacy fences, metal and decorative fencing, and custom gates, using materials chosen for Oklahoma weather. We keep job sites clean, give clear timelines, and walk the fence line with you at the end so you are 100% happy. Licensed and insured. Tap Learn more to get a free estimate for your Edmond home. | K7: =LEN(J7) -> 476 | L7: Learn more | M7: https://preferredfencesolutions.com/fence-installation-edmond-ok/ | N7: pf03-edmond-installation | O7: =M7&"?utm_source="&Overview!$B$20&"&utm_medium="&Overview!$B$21&"&utm_campaign="&Overview!$B$22&"&utm_content="&N7 -> https://preferredfencesolutions.com/fence-installation-edmond-ok/?utm_source=google&utm_medium=organic&utm_campaign=gbp-posts-nov26-jan27&utm_content=pf03-edmond-installation | Q7: Real photo of a finished fence at an Edmond home. | R7: Draft
A8: PF-04 | B8: 2 | C8: 46338 | D8: =TEXT(C8,"ddd") -> Thu | E8: Promotional | F8: Offer | G8: Free fence estimate | H8: free fence estimate OKC | I8: Free On-Site Fence Estimate | J8: Planning a new fence or a fence replacement before spring? Book a free on-site estimate with Preferred Fence Solutions. We measure your yard, talk through materials, height and gates, and give you a clear written quote. Wood, vinyl, ornamental iron, chain link and SimTek options are available across Oklahoma City, Edmond, Yukon, Mustang and Nichols Hills. Tap View offer to request your free estimate. | K8: =LEN(J8) -> 405 | L8: View offer | M8: https://preferredfencesolutions.com/ | N8: pf04-free-estimate | O8: =M8&"?utm_source="&Overview!$B$20&"&utm_medium="&Overview!$B$21&"&utm_campaign="&Overview!$B$22&"&utm_content="&N8 -> https://preferredfencesolutions.com/?utm_source=google&utm_medium=organic&utm_campaign=gbp-posts-nov26-jan27&utm_content=pf04-free-estimate | P8: Offer dates: Nov 12 to Dec 15, 2026. Terms: free estimate within the service area; no obligation. | Q8: Real photo of a team member measuring a yard or reviewing plans with a homeowner. | R8: Draft | S8: Free estimates are listed on the website for all projects.
A9: PF-05 | B9: 3 | C9: 46343 | D9: =TEXT(C9,"ddd") -> Tue | E9: Service | F9: Update | G9: Western Red Cedar stockade fences | H9: cedar fence installation OKC | J9: Our wood stockade fences are built for Oklahoma. Preferred Fence Solutions custom builds every wood fence panel and gate in our shop using Western Red Cedar, which is naturally rot and pest resistant. Each fence is installed on heavy-duty steel posts set in concrete 2 feet below grade, and we never dry set our posts. Choose dog ear, cap and trim, board on board, shadowbox, horizontal and more. Tap Learn more to see the styles. | K9: =LEN(J9) -> 432 | L9: Learn more | M9: https://preferredfencesolutions.com/stockade-wood-fence/ | N9: pf05-cedar-stockade | O9: =M9&"?utm_source="&Overview!$B$20&"&utm_medium="&Overview!$B$21&"&utm_campaign="&Overview!$B$22&"&utm_content="&N9 -> https://preferredfencesolutions.com/stockade-wood-fence/?utm_source=google&utm_medium=organic&utm_campaign=gbp-posts-nov26-jan27&utm_content=pf05-cedar-stockade | Q9: Real photo of a stained cedar cap and trim fence. | R9: Draft
A10: PF-06 | B10: 3 | C10: 46345 | D10: =TEXT(C10,"ddd") -> Thu | E10: FAQ | F10: Update | G10: Repair or replace my fence? | H10: fence repair vs replacement | J10: FAQ: Should I repair my fence or replace it? A quick rule of thumb: repair usually makes sense when the damage is limited to a few areas and the rest of the fence is still sound. Replacement is usually the smarter choice when several posts are leaning, rails are failing or sections keep moving over time. Walk your fence line and look for leaning posts, loose rails and rot at the base. Not sure what you are seeing? We will tell you honestly. Tap Learn more to read our full guide. | K10: =LEN(J10) -> 485 | L10: Learn more | M10: https://preferredfencesolutions.com/fence-repair-vs-replacement-oklahoma-city/ | N10: pf06-faq-repair-vs-replace | O10: =M10&"?utm_source="&Overview!$B$20&"&utm_medium="&Overview!$B$21&"&utm_campaign="&Overview!$B$22&"&utm_content="&N10 -> https://preferredfencesolutions.com/fence-repair-vs-replacement-oklahoma-city/?utm_source=google&utm_medium=organic&utm_campaign=gbp-posts-nov26-jan27&utm_content=pf06-faq-repair-vs-replace | Q10: Photo of a leaning fence section next to a newly rebuilt one. | R10: Draft
A11: PF-07 | B11: 4 | C11: 46350 | D11: =TEXT(C11,"ddd") -> Tue | E11: Service | F11: Update | G11: Ameristar ornamental iron fences | H11: ornamental iron fence OKC | J11: Looking for security that still looks elegant from the street? Preferred Fence Solutions installs Ameristar ornamental iron fences and gates for homes in Oklahoma City, Edmond and the surrounding metro. We have installed iron fences from 4 to 6 feet tall and can add decorative finials, scrolls and custom gates. Ornamental iron is a popular choice for front yards, pools and retaining walls. Tap Learn more to see recent projects. | K11: =LEN(J11) -> 433 | L11: Learn more | M11: https://preferredfencesolutions.com/ornamental-iron-fence/ | N11: pf07-ornamental-iron | O11: =M11&"?utm_source="&Overview!$B$20&"&utm_medium="&Overview!$B$21&"&utm_campaign="&Overview!$B$22&"&utm_content="&N11 -> https://preferredfencesolutions.com/ornamental-iron-fence/?utm_source=google&utm_medium=organic&utm_campaign=gbp-posts-nov26-jan27&utm_content=pf07-ornamental-iron | Q11: Real photo of an arched ornamental iron double gate. | R11: Draft
A12: PF-08 | B12: 4 | C12: 46351 | D12: =TEXT(C12,"ddd") -> Wed | E12: Local | F12: Update | G12: Thanksgiving thank you | H12: fence company Oklahoma City | J12: Happy Thanksgiving from the Preferred Fence Solutions team. Thank you to every homeowner and business in Oklahoma City, Edmond, Nichols Hills, Yukon and Mustang who trusted our crew with their fence this year. Our promise is to exceed your expectations with fences that are installed with precision, care and good attitudes, and your kind words keep us going. Enjoy the holiday with your family. Tap Learn more to read what our customers say. | K12: =LEN(J12) -> 444 | L12: Learn more | M12: https://preferredfencesolutions.com/testimonials/ | N12: pf08-thanksgiving | O12: =M12&"?utm_source="&Overview!$B$20&"&utm_medium="&Overview!$B$21&"&utm_campaign="&Overview!$B$22&"&utm_content="&N12 -> https://preferredfencesolutions.com/testimonials/?utm_source=google&utm_medium=organic&utm_campaign=gbp-posts-nov26-jan27&utm_content=pf08-thanksgiving | Q12: Team photo in the shop or on a job site. | R12: Draft | S12: Confirm holiday hours and add GBP special hours.
A13: PF-09 | B13: 5 | C13: 46357 | D13: =TEXT(C13,"ddd") -> Tue | E13: Service | F13: Update | G13: Sheet metal fence for commercial sites | H13: sheet metal fence Oklahoma City | J13: Need privacy and security for a storage yard, equipment area or commercial lot? Preferred Fence Solutions installs sheet metal and ribbed panel metal fences for commercial properties across Oklahoma City. The panels do not rot, warp or absorb moisture, which makes them a practical, low-maintenance choice for storage facilities, industrial sites and utility screening. Tap Learn more to request a free commercial fence estimate. | K13: =LEN(J13) -> 431 | L13: Learn more | M13: https://preferredfencesolutions.com/sheet-metal-fence-oklahoma-city/ | N13: pf09-sheet-metal-commercial | O13: =M13&"?utm_source="&Overview!$B$20&"&utm_medium="&Overview!$B$21&"&utm_campaign="&Overview!$B$22&"&utm_content="&N13 -> https://preferredfencesolutions.com/sheet-metal-fence-oklahoma-city/?utm_source=google&utm_medium=organic&utm_campaign=gbp-posts-nov26-jan27&utm_content=pf09-sheet-metal-commercial | Q13: Real photo of a ribbed metal fence on a commercial site. | R13: Draft
A14: PF-10 | B14: 5 | C14: 46359 | D14: =TEXT(C14,"ddd") -> Thu | E14: FAQ | F14: Update | G14: Why fence posts fail in Oklahoma | H14: leaning fence post repair | J14: FAQ: Why do fence posts lean in Oklahoma? Oklahoma clay soil expands and contracts as it gets wet and dries out, which loosens post footings over time. Strong wind adds more load, so a small lean can turn into a failing section. That is why we set heavy-duty steel posts in concrete 2 feet below grade on our wood fences. If your posts are already leaning, we can tell you whether they can be reset or need replacing. Tap Learn more to read the full article. | K14: =LEN(J14) -> 460 | L14: Learn more | M14: https://preferredfencesolutions.com/why-fence-posts-fail-oklahoma-soil/ | N14: pf10-faq-post-failure | O14: =M14&"?utm_source="&Overview!$B$20&"&utm_medium="&Overview!$B$21&"&utm_campaign="&Overview!$B$22&"&utm_content="&N14 -> https://preferredfencesolutions.com/why-fence-posts-fail-oklahoma-soil/?utm_source=google&utm_medium=organic&utm_campaign=gbp-posts-nov26-jan27&utm_content=pf10-faq-post-failure | Q14: Close-up photo of a leaning wood post next to a steel post set in concrete. | R14: Draft
A15: PF-11 | B15: 6 | C15: 46364 | D15: =TEXT(C15,"ddd") -> Tue | E15: Service | F15: Update | G15: Chain link fencing | H15: chain link fence installation OKC | J15: Chain link is one of the most affordable ways to secure a yard or a business. Preferred Fence Solutions installs galvanized and black vinyl-coated chain link for homes and commercial properties across OKC and Edmond. We can add walk-through gates, double drive gates, cantilever gates, automatic gate operators and telephone entry systems. We also repair existing chain link fences. Tap Learn more to get a free quote. | K15: =LEN(J15) -> 420 | L15: Learn more | M15: https://preferredfencesolutions.com/chain-link-fence/ | N15: pf11-chain-link | O15: =M15&"?utm_source="&Overview!$B$20&"&utm_medium="&Overview!$B$21&"&utm_campaign="&Overview!$B$22&"&utm_content="&N15 -> https://preferredfencesolutions.com/chain-link-fence/?utm_source=google&utm_medium=organic&utm_campaign=gbp-posts-nov26-jan27&utm_content=pf11-chain-link | Q15: Real photo of a black vinyl-coated chain link fence with a gate. | R15: Draft
A16: PF-12 | B16: 6 | C16: 46366 | D16: =TEXT(C16,"ddd") -> Thu | E16: Promotional | F16: Update | G16: Custom doggie windows | H16: dog fence OKC | J16: Give your dog a view of the neighborhood. Ask about adding a custom doggie window to any stockade fence we build. It is a small add-on that dogs love and owners enjoy, and it fits into the fence design so it looks finished, not added on later. We build every panel in our shop, so the window can be placed exactly where your dog likes to watch. Tap Learn more to see doggie windows in our fence gallery. | K16: =LEN(J16) -> 405 | L16: Learn more | M16: https://preferredfencesolutions.com/fence-gallery/ | N16: pf12-doggie-window | O16: =M16&"?utm_source="&Overview!$B$20&"&utm_medium="&Overview!$B$21&"&utm_campaign="&Overview!$B$22&"&utm_content="&N16 -> https://preferredfencesolutions.com/fence-gallery/?utm_source=google&utm_medium=organic&utm_campaign=gbp-posts-nov26-jan27&utm_content=pf12-doggie-window | Q16: Real photo of a dog looking through a doggie window in a cedar fence. | R16: Draft | S16: Do not add pricing unless the client confirms it.
A17: PF-13 | B17: 7 | C17: 46371 | D17: =TEXT(C17,"ddd") -> Tue | E17: Local | F17: Update | G17: Best fence for Oklahoma wind | H17: best fence for Oklahoma wind | J17: Oklahoma wind is hard on fences. Between spring storms, sudden gusts and shifting clay soil, the wrong fence or install method can lead to leaning posts and broken panels. For homes in Oklahoma City, Edmond and Yukon, the biggest difference usually comes from how the fence is built: post type, post depth and concrete, plus a material that suits your yard. We wrote a local guide on what actually holds up in OKC weather. Tap Learn more to read it. | K17: =LEN(J17) -> 451 | L17: Learn more | M17: https://preferredfencesolutions.com/best-fence-oklahoma-wind-okc/ | N17: pf13-oklahoma-wind | O17: =M17&"?utm_source="&Overview!$B$20&"&utm_medium="&Overview!$B$21&"&utm_campaign="&Overview!$B$22&"&utm_content="&N17 -> https://preferredfencesolutions.com/best-fence-oklahoma-wind-okc/?utm_source=google&utm_medium=organic&utm_campaign=gbp-posts-nov26-jan27&utm_content=pf13-oklahoma-wind | Q17: Photo of a solid fence line on a windy day, or a stockade fence on steel posts. | R17: Draft
A18: PF-14 | B18: 7 | C18: 46373 | D18: =TEXT(C18,"ddd") -> Thu | E18: FAQ | F18: Update | G18: What is the most affordable fence? | H18: cheapest fence Oklahoma City | J18: FAQ: What is the most affordable fence option in OKC? Galvanized chain link is our most budget-friendly option for both homes and businesses. If you want wood, our most affordable choice is Western Red Cedar on metal posts. We do not install cheaper woods like white spruce because the quality is not there, and cedar is naturally pest resistant and lasts longer. Tap Learn more to see more answers, or request a free estimate for your yard. | K18: =LEN(J18) -> 443 | L18: Learn more | M18: https://preferredfencesolutions.com/faq/ | N18: pf14-faq-affordable-fence | O18: =M18&"?utm_source="&Overview!$B$20&"&utm_medium="&Overview!$B$21&"&utm_campaign="&Overview!$B$22&"&utm_content="&N18 -> https://preferredfencesolutions.com/faq/?utm_source=google&utm_medium=organic&utm_campaign=gbp-posts-nov26-jan27&utm_content=pf14-faq-affordable-fence | Q18: Side-by-side photo of a galvanized chain link fence and a cedar fence. | R18: Draft
A19: PF-15 | B19: 8 | C19: 46378 | D19: =TEXT(C19,"ddd") -> Tue | E19: Service | F19: Update | G19: Residential gates: width and placement | H19: fence gate installation OKC | J19: Planning a gate? The right width and location make your yard easier to use every day. A walk gate may be fine for people but too narrow for a mower, and a wide equipment gate may work better on a different side of the house. Preferred Fence Solutions builds custom wood and iron gates and helps you settle access before the posts go in. Tap Learn more to read our gate planning guide for OKC homeowners. | K19: =LEN(J19) -> 405 | L19: Learn more | M19: https://preferredfencesolutions.com/residential-fence-gate-width-placement-okc/ | N19: pf15-gate-planning | O19: =M19&"?utm_source="&Overview!$B$20&"&utm_medium="&Overview!$B$21&"&utm_campaign="&Overview!$B$22&"&utm_content="&N19 -> https://preferredfencesolutions.com/residential-fence-gate-width-placement-okc/?utm_source=google&utm_medium=organic&utm_campaign=gbp-posts-nov26-jan27&utm_content=pf15-gate-planning | Q19: Real photo of a custom double-drive wood gate. | R19: Draft
A20: PF-16 | B20: 8 | C20: 46385 | D20: =TEXT(C20,"ddd") -> Tue | E20: Local | F20: Update | G20: Year-end thank you and awards | H20: best fence contractor Oklahoma | J20: Thank you, Oklahoma City, for another great year. We are honored to have won local awards for our fencing work, and we stand behind every fence and gate we install with a 1-year warranty. More than any award, we are grateful for customers who welcome our crew into their yards and recommend us to their neighbors. If we built or repaired your fence this year, we would love to hear how it is holding up. Tap Learn more to see our awards. | K20: =LEN(J20) -> 439 | L20: Learn more | M20: https://preferredfencesolutions.com/pfs-awards/ | N20: pf16-year-end-awards | O20: =M20&"?utm_source="&Overview!$B$20&"&utm_medium="&Overview!$B$21&"&utm_campaign="&Overview!$B$22&"&utm_content="&N20 -> https://preferredfencesolutions.com/pfs-awards/?utm_source=google&utm_medium=organic&utm_campaign=gbp-posts-nov26-jan27&utm_content=pf16-year-end-awards | Q20: Photo of the team with an award, or a collage of this year's projects. | R20: Draft | S20: Review request allowed. Do not offer incentives for reviews.
A21: PF-17 | B21: 9 | C21: 46392 | D21: =TEXT(C21,"ddd") -> Tue | E21: Promotional | F21: Offer | G21: Free design and planning consultation | H21: fence design Oklahoma City | I21: Free Fence Design & Planning Consultation | J21: New year, new fence. Not sure which style, material or height is right for your property? Book a free design and planning consultation with Preferred Fence Solutions. We will walk your yard, talk through privacy, pets, gates and budget, and recommend the best option for your home before we schedule your install. Tap View offer to book your consultation. | K21: =LEN(J21) -> 357 | L21: View offer | M21: https://preferredfencesolutions.com/fence-design-planning/ | N21: pf17-free-design-consult | O21: =M21&"?utm_source="&Overview!$B$20&"&utm_medium="&Overview!$B$21&"&utm_campaign="&Overview!$B$22&"&utm_content="&N21 -> https://preferredfencesolutions.com/fence-design-planning/?utm_source=google&utm_medium=organic&utm_campaign=gbp-posts-nov26-jan27&utm_content=pf17-free-design-consult | P21: Offer dates: Jan 5 to Feb 15, 2027 (confirm). Terms: consultation and estimate are free; no obligation. | Q21: Photo of a fence layout sketch or a team member walking a yard with a homeowner. | R21: Draft | S21: Confirm the client is happy to label the consultation as free.
A22: PF-18 | B22: 9 | C22: 46394 | D22: =TEXT(C22,"ddd") -> Thu | E22: Service | F22: Update | G22: Vinyl fence installation | H22: vinyl fence installation OKC | J22: Want a fence you never have to stain or paint? Vinyl is a low-maintenance option that lasts for years. Preferred Fence Solutions installs vinyl privacy fences, picket fences, ranch-style 3-rail fences and vinyl gates in OKC, Edmond, Piedmont, Nichols Hills and The Village. Tan and white are the most popular colors. Many vinyl fences can be installed in a single day. Tap Learn more to see styles and get a free quote. | K22: =LEN(J22) -> 421 | L22: Learn more | M22: https://preferredfencesolutions.com/vinyl-fence/ | N22: pf18-vinyl-fence | O22: =M22&"?utm_source="&Overview!$B$20&"&utm_medium="&Overview!$B$21&"&utm_campaign="&Overview!$B$22&"&utm_content="&N22 -> https://preferredfencesolutions.com/vinyl-fence/?utm_source=google&utm_medium=organic&utm_campaign=gbp-posts-nov26-jan27&utm_content=pf18-vinyl-fence | Q22: Real photo of a white vinyl privacy fence in Edmond. | R22: Draft
A23: PF-19 | B23: 10 | C23: 46399 | D23: =TEXT(C23,"ddd") -> Tue | E23: FAQ | F23: Update | G23: Will new cedar boards match my old fence? | H23: cedar fence board replacement | J23: FAQ: Will new cedar boards blend in with my older fence? New cedar usually looks brighter or more reddish than boards that have weathered for years. A contractor can match the size, profile and spacing closely, but the exact color takes time to even out as the new wood weathers. Replacing damaged boards still restores privacy and extends the life of a sound fence. Tap Learn more to read what to expect and your options. | K23: =LEN(J23) -> 424 | L23: Learn more | M23: https://preferredfencesolutions.com/new-cedar-fence-boards-blend-old-fence/ | N23: pf19-faq-cedar-match | O23: =M23&"?utm_source="&Overview!$B$20&"&utm_medium="&Overview!$B$21&"&utm_campaign="&Overview!$B$22&"&utm_content="&N23 -> https://preferredfencesolutions.com/new-cedar-fence-boards-blend-old-fence/?utm_source=google&utm_medium=organic&utm_campaign=gbp-posts-nov26-jan27&utm_content=pf19-faq-cedar-match | Q23: Real photo of a repaired cedar section next to older boards. | R23: Draft
A24: PF-20 | B24: 10 | C24: 46401 | D24: =TEXT(C24,"ddd") -> Thu | E24: Service | F24: Update | G24: SimTek fences | H24: SimTek fence installer OKC | J24: Want the look of stone with the privacy of a solid fence? Consider a SimTek EcoStone fence. SimTek fences can be customized to your style and budget, offer high levels of security, need minimal maintenance and come with SimTek's warranty. Preferred Fence Solutions installs SimTek fences for homes in Edmond, OKC, Mustang and Yukon. Tap Learn more to see if SimTek is right for your yard. | K24: =LEN(J24) -> 390 | L24: Learn more | M24: https://preferredfencesolutions.com/simtek-fence/ | N24: pf20-simtek | O24: =M24&"?utm_source="&Overview!$B$20&"&utm_medium="&Overview!$B$21&"&utm_campaign="&Overview!$B$22&"&utm_content="&N24 -> https://preferredfencesolutions.com/simtek-fence/?utm_source=google&utm_medium=organic&utm_campaign=gbp-posts-nov26-jan27&utm_content=pf20-simtek | Q24: Real photo of a SimTek fence installed by the team (gallery has SimTek photos). | R24: Draft
A25: PF-21 | B25: 11 | C25: 46406 | D25: =TEXT(C25,"ddd") -> Tue | E25: Promotional | F25: Offer | G25: Free fence repair estimate after winter weather | H25: fence repair estimate OKC | I25: Free Fence Repair Estimate | J25: Did winter wind or ice leave your fence leaning or damaged? Book a free fence repair estimate with Preferred Fence Solutions. We will check posts, panels and gates, tell you honestly whether repair or replacement makes more sense, and give you a clear quote. No job is too small. Tap View offer to schedule your free repair estimate. | K25: =LEN(J25) -> 335 | L25: View offer | M25: https://preferredfencesolutions.com/fence-repair-okc/ | N25: pf21-free-repair-estimate | O25: =M25&"?utm_source="&Overview!$B$20&"&utm_medium="&Overview!$B$21&"&utm_campaign="&Overview!$B$22&"&utm_content="&N25 -> https://preferredfencesolutions.com/fence-repair-okc/?utm_source=google&utm_medium=organic&utm_campaign=gbp-posts-nov26-jan27&utm_content=pf21-free-repair-estimate | P25: Offer dates: Jan 19 to Feb 28, 2027. Terms: free estimate within the service area; no obligation. | Q25: Real photo of a gate or section after a repair. | R25: Draft
A26: PF-22 | B26: 11 | C26: 46408 | D26: =TEXT(C26,"ddd") -> Thu | E26: Local | F26: Update | G26: North OKC fence installation and repair | H26: fence company North OKC | J26: Preferred Fence Solutions is based just north of OKC, and North OKC homeowners are some of our longest-standing customers. We custom make each fence panel in our shop, install stockade fences on heavy-duty metal posts, use 100% USA fence products and back every fence and gate with a 1-year warranty. We never turn away a job because of its size. Tap Learn more to get a free estimate for your North OKC fence. | K26: =LEN(J26) -> 412 | L26: Learn more | M26: https://preferredfencesolutions.com/fence-installation-repair-north-okc/ | N26: pf22-north-okc | O26: =M26&"?utm_source="&Overview!$B$20&"&utm_medium="&Overview!$B$21&"&utm_campaign="&Overview!$B$22&"&utm_content="&N26 -> https://preferredfencesolutions.com/fence-installation-repair-north-okc/?utm_source=google&utm_medium=organic&utm_campaign=gbp-posts-nov26-jan27&utm_content=pf22-north-okc | Q26: Real photo of a North OKC project. | R26: Draft

Sheet Weekly Batches
A1: Weekly batch plan
A2: Each batch = 2 posts. Content goes to the client 2 working days before the batch week, then is scheduled on the Monday. Batch 8 covers the two holiday weeks (Dec 22 and Dec 29).
A4: Batch | B4: Week Of (Mon) | C4: Posts in Batch | D4: Posts | E4: Service | F4: FAQ | G4: Local | H4: Promotional | I4: Content Due to Client | J4: Batch Status
A5: 1 | B5: 46328 | C5: PF-01, PF-02 | D5: =COUNTIF('Content Calendar'!$B$5:$B$26,A5) -> 2 | E5: =COUNTIFS('Content Calendar'!$B$5:$B$26,A5,'Content Calendar'!$E$5:$E$26,"Service") -> 1 | F5: =COUNTIFS('Content Calendar'!$B$5:$B$26,A5,'Content Calendar'!$E$5:$E$26,"FAQ") -> 1 | G5: =COUNTIFS('Content Calendar'!$B$5:$B$26,A5,'Content Calendar'!$E$5:$E$26,"Local") -> 0 | H5: =COUNTIFS('Content Calendar'!$B$5:$B$26,A5,'Content Calendar'!$E$5:$E$26,"Promotional") -> 0 | I5: =WORKDAY(B5,-2) -> 46324 | J5: Not started
A6: 2 | B6: 46335 | C6: PF-03, PF-04 | D6: =COUNTIF('Content Calendar'!$B$5:$B$26,A6) -> 2 | E6: =COUNTIFS('Content Calendar'!$B$5:$B$26,A6,'Content Calendar'!$E$5:$E$26,"Service") -> 0 | F6: =COUNTIFS('Content Calendar'!$B$5:$B$26,A6,'Content Calendar'!$E$5:$E$26,"FAQ") -> 0 | G6: =COUNTIFS('Content Calendar'!$B$5:$B$26,A6,'Content Calendar'!$E$5:$E$26,"Local") -> 1 | H6: =COUNTIFS('Content Calendar'!$B$5:$B$26,A6,'Content Calendar'!$E$5:$E$26,"Promotional") -> 1 | I6: =WORKDAY(B6,-2) -> 46331 | J6: Not started
A7: 3 | B7: 46342 | C7: PF-05, PF-06 | D7: =COUNTIF('Content Calendar'!$B$5:$B$26,A7) -> 2 | E7: =COUNTIFS('Content Calendar'!$B$5:$B$26,A7,'Content Calendar'!$E$5:$E$26,"Service") -> 1 | F7: =COUNTIFS('Content Calendar'!$B$5:$B$26,A7,'Content Calendar'!$E$5:$E$26,"FAQ") -> 1 | G7: =COUNTIFS('Content Calendar'!$B$5:$B$26,A7,'Content Calendar'!$E$5:$E$26,"Local") -> 0 | H7: =COUNTIFS('Content Calendar'!$B$5:$B$26,A7,'Content Calendar'!$E$5:$E$26,"Promotional") -> 0 | I7: =WORKDAY(B7,-2) -> 46338 | J7: Not started
A8: 4 | B8: 46349 | C8: PF-07, PF-08 | D8: =COUNTIF('Content Calendar'!$B$5:$B$26,A8) -> 2 | E8: =COUNTIFS('Content Calendar'!$B$5:$B$26,A8,'Content Calendar'!$E$5:$E$26,"Service") -> 1 | F8: =COUNTIFS('Content Calendar'!$B$5:$B$26,A8,'Content Calendar'!$E$5:$E$26,"FAQ") -> 0 | G8: =COUNTIFS('Content Calendar'!$B$5:$B$26,A8,'Content Calendar'!$E$5:$E$26,"Local") -> 1 | H8: =COUNTIFS('Content Calendar'!$B$5:$B$26,A8,'Content Calendar'!$E$5:$E$26,"Promotional") -> 0 | I8: =WORKDAY(B8,-2) -> 46345 | J8: Not started
A9: 5 | B9: 46356 | C9: PF-09, PF-10 | D9: =COUNTIF('Content Calendar'!$B$5:$B$26,A9) -> 2 | E9: =COUNTIFS('Content Calendar'!$B$5:$B$26,A9,'Content Calendar'!$E$5:$E$26,"Service") -> 1 | F9: =COUNTIFS('Content Calendar'!$B$5:$B$26,A9,'Content Calendar'!$E$5:$E$26,"FAQ") -> 1 | G9: =COUNTIFS('Content Calendar'!$B$5:$B$26,A9,'Content Calendar'!$E$5:$E$26,"Local") -> 0 | H9: =COUNTIFS('Content Calendar'!$B$5:$B$26,A9,'Content Calendar'!$E$5:$E$26,"Promotional") -> 0 | I9: =WORKDAY(B9,-2) -> 46352 | J9: Not started
A10: 6 | B10: 46363 | C10: PF-11, PF-12 | D10: =COUNTIF('Content Calendar'!$B$5:$B$26,A10) -> 2 | E10: =COUNTIFS('Content Calendar'!$B$5:$B$26,A10,'Content Calendar'!$E$5:$E$26,"Service") -> 1 | F10: =COUNTIFS('Content Calendar'!$B$5:$B$26,A10,'Content Calendar'!$E$5:$E$26,"FAQ") -> 0 | G10: =COUNTIFS('Content Calendar'!$B$5:$B$26,A10,'Content Calendar'!$E$5:$E$26,"Local") -> 0 | H10: =COUNTIFS('Content Calendar'!$B$5:$B$26,A10,'Content Calendar'!$E$5:$E$26,"Promotional") -> 1 | I10: =WORKDAY(B10,-2) -> 46359 | J10: Not started
A11: 7 | B11: 46370 | C11: PF-13, PF-14 | D11: =COUNTIF('Content Calendar'!$B$5:$B$26,A11) -> 2 | E11: =COUNTIFS('Content Calendar'!$B$5:$B$26,A11,'Content Calendar'!$E$5:$E$26,"Service") -> 0 | F11: =COUNTIFS('Content Calendar'!$B$5:$B$26,A11,'Content Calendar'!$E$5:$E$26,"FAQ") -> 1 | G11: =COUNTIFS('Content Calendar'!$B$5:$B$26,A11,'Content Calendar'!$E$5:$E$26,"Local") -> 1 | H11: =COUNTIFS('Content Calendar'!$B$5:$B$26,A11,'Content Calendar'!$E$5:$E$26,"Promotional") -> 0 | I11: =WORKDAY(B11,-2) -> 46366 | J11: Not started
A12: 8 | B12: 46377 | C12: PF-15, PF-16 | D12: =COUNTIF('Content Calendar'!$B$5:$B$26,A12) -> 2 | E12: =COUNTIFS('Content Calendar'!$B$5:$B$26,A12,'Content Calendar'!$E$5:$E$26,"Service") -> 1 | F12: =COUNTIFS('Content Calendar'!$B$5:$B$26,A12,'Content Calendar'!$E$5:$E$26,"FAQ") -> 0 | G12: =COUNTIFS('Content Calendar'!$B$5:$B$26,A12,'Content Calendar'!$E$5:$E$26,"Local") -> 1 | H12: =COUNTIFS('Content Calendar'!$B$5:$B$26,A12,'Content Calendar'!$E$5:$E$26,"Promotional") -> 0 | I12: =WORKDAY(B12,-2) -> 46373 | J12: Not started
A13: 9 | B13: 46391 | C13: PF-17, PF-18 | D13: =COUNTIF('Content Calendar'!$B$5:$B$26,A13) -> 2 | E13: =COUNTIFS('Content Calendar'!$B$5:$B$26,A13,'Content Calendar'!$E$5:$E$26,"Service") -> 1 | F13: =COUNTIFS('Content Calendar'!$B$5:$B$26,A13,'Content Calendar'!$E$5:$E$26,"FAQ") -> 0 | G13: =COUNTIFS('Content Calendar'!$B$5:$B$26,A13,'Content Calendar'!$E$5:$E$26,"Local") -> 0 | H13: =COUNTIFS('Content Calendar'!$B$5:$B$26,A13,'Content Calendar'!$E$5:$E$26,"Promotional") -> 1 | I13: =WORKDAY(B13,-2) -> 46387 | J13: Not started
A14: 10 | B14: 46398 | C14: PF-19, PF-20 | D14: =COUNTIF('Content Calendar'!$B$5:$B$26,A14) -> 2 | E14: =COUNTIFS('Content Calendar'!$B$5:$B$26,A14,'Content Calendar'!$E$5:$E$26,"Service") -> 1 | F14: =COUNTIFS('Content Calendar'!$B$5:$B$26,A14,'Content Calendar'!$E$5:$E$26,"FAQ") -> 1 | G14: =COUNTIFS('Content Calendar'!$B$5:$B$26,A14,'Content Calendar'!$E$5:$E$26,"Local") -> 0 | H14: =COUNTIFS('Content Calendar'!$B$5:$B$26,A14,'Content Calendar'!$E$5:$E$26,"Promotional") -> 0 | I14: =WORKDAY(B14,-2) -> 46394 | J14: Not started
A15: 11 | B15: 46405 | C15: PF-21, PF-22 | D15: =COUNTIF('Content Calendar'!$B$5:$B$26,A15) -> 2 | E15: =COUNTIFS('Content Calendar'!$B$5:$B$26,A15,'Content Calendar'!$E$5:$E$26,"Service") -> 0 | F15: =COUNTIFS('Content Calendar'!$B$5:$B$26,A15,'Content Calendar'!$E$5:$E$26,"FAQ") -> 0 | G15: =COUNTIFS('Content Calendar'!$B$5:$B$26,A15,'Content Calendar'!$E$5:$E$26,"Local") -> 1 | H15: =COUNTIFS('Content Calendar'!$B$5:$B$26,A15,'Content Calendar'!$E$5:$E$26,"Promotional") -> 1 | I15: =WORKDAY(B15,-2) -> 46401 | J15: Not started
A16: Total | D16: =SUM(D5:D15) -> 22 | E16: =SUM(E5:E15) -> 8 | F16: =SUM(F5:F15) -> 5 | G16: =SUM(G5:G15) -> 5 | H16: =SUM(H5:H15) -> 4

Sheet Citations
A1: Citation work
A2: Use the NAP below exactly, character for character, on every listing.
B4: NAP field | C4: Use exactly
B5: Business name | C5: Preferred Fence Solutions, Inc. (confirm this matches the GBP name exactly)
B6: Street address | C6: 8071 N. Classen Blvd., Suite A
B7: City, State ZIP | C7: Oklahoma City, OK 73114
B8: Primary phone | C8: (405) 921-3426
B9: Website | C9: https://preferredfencesolutions.com/
B10: Email | C10: Confirm with client (FAQ shows a misspelled Gmail address)
B11: Hours | C11: Mon to Fri 7:00 AM to 4:00 PM; Sat 7:00 AM to 11:00 AM; Sun closed
B12: Primary category (suggested) | C12: Fence contractor (confirm against current GBP category)
B13: Short description (for directories) | C13: Locally owned fence contractor in Oklahoma City. Custom wood, vinyl, ornamental iron, chain link, SimTek and commercial fence installation and repair for OKC, Edmond, Yukon, Mustang and Nichols Hills. Licensed and insured, with a 1-year warranty on all fences and gates.
B15: Citation list
A16: # | B16: Platform | C16: Type | D16: Priority | E16: Where to claim / submit | F16: Current Status (Oct 26) | G16: Issue / Note | H16: Action | I16: Work Status | J16: Date Done | K16: Live Listing URL
A17: 1 | B17: Google Business Profile | C17: Core | D17: High | E17: https://business.google.com | F17: Found (4.7, 143 reviews per third-party summary) | H17: Confirm name, categories, hours, services and photos | I17: Not started
A18: 2 | B18: Bing Places for Business | C18: Core | D18: High | E18: https://www.bingplaces.com | F18: To verify | H18: Import from GBP and verify | I18: Not started
A19: 3 | B19: Apple Business Connect | C19: Core | D19: High | E19: https://businessconnect.apple.com | F19: To verify | H19: Claim and verify for Apple Maps | I19: Not started
A20: 4 | B20: Facebook Page | C20: Core / Social | D20: High | E20: https://www.facebook.com/preferredfencesolutions/ | F20: Found | H20: Check that the About section NAP matches | I20: Not started
A21: 5 | B21: Instagram | C21: Social | D21: Medium | E21: https://www.instagram.com/preferredfencesolutions/ | F21: Found | H21: Add address and website in the bio | I21: Not started
A22: 6 | B22: Yelp | C22: Core | D22: High | E22: https://biz.yelp.com | F22: Found, needs fix (3.9, 7 reviews) | G22: Website links to 'premier-fence-solutions-oklahoma-city-5' | H22: Correct the business name on Yelp or fix the website link | I22: Not started
A23: 7 | B23: Better Business Bureau | C23: Core | D23: High | E23: https://www.bbb.org/us/ok/oklahoma-city/profile/fence-contractors/preferred-fence-solutions-inc-0995-90054341 | F23: Found | H23: Check NAP, hours and services | I23: Not started
A24: 8 | B24: Thumbtack | C24: Home services | D24: Medium | E24: https://www.thumbtack.com/ok/oklahoma-city/fences/preferred-fence-solutions-inc/service/290383331289604102 | F24: Found | H24: Check NAP and add recent photos | I24: Not started
A25: 9 | B25: HomeAdvisor / Angi | C25: Home services | D25: Medium | E25: https://pro.homeadvisor.com | F25: To verify | G25: Website link points to the HomeAdvisor homepage | H25: Find the actual profile and fix the website link | I25: Not started
A26: 10 | B26: HomeGuide | C26: Home services | D26: Medium | E26: https://homeguide.com/ok/edmond/fence-installation/preferred-fence-solutions--inc--Bg7QaScYM | F26: Found | G26: Says 'Founded 2017'; city shown as Edmond | H26: Claim; correct the founded year and city if wrong | I26: Not started
A27: 11 | B27: BuildZoom | C27: Home services | D27: Medium | E27: https://www.buildzoom.com/contractor/preferred-fence-solutions | F27: Found, needs fix | G27: Shows 'No active license on file' | H27: Submit the current license to update the record | I27: Not started
A28: 12 | B28: Porch | C28: Home services | D28: Medium | E28: https://pro.porch.com/oklahoma-city-ok/fencing-contractors/cp | F28: Found | G28: Has one negative review | H28: Claim the listing and reply to the review professionally | I28: Not started
A29: 13 | B29: Expertise.com | C29: Directory | D29: Low | E29: https://www.expertise.com/ok/oklahoma-city/fence-companies | F29: Found | H29: Check NAP | I29: Not started
A30: 14 | B30: ThreeBestRated | C30: Directory | D30: Low | E30: https://threebestrated.com/fencing-contractors-in-oklahoma-city-ok | F30: Found | G30: Says 'since 2004' | H30: Confirm the founded year | I30: Not started
A31: 15 | B31: The Blue Book | C31: Industry | D31: Low | E31: https://www.thebluebook.com/iProView/1566095 | F31: Found | H31: Check NAP for commercial leads | I31: Not started
A32: 16 | B32: Nextdoor Business | C32: Local | D32: High | E32: https://business.nextdoor.com | F32: To verify | G32: Strong for homeowner referrals | H32: Claim business page | I32: Not started
A33: 17 | B33: Houzz | C33: Home services | D33: Medium | E33: https://www.houzz.com/pro | F33: To verify | H33: Create profile with gallery photos | I33: Not started
A34: 18 | B34: Yellow Pages | C34: Directory | D34: Medium | E34: https://adsolutions.yp.com/free-listing | F34: To verify | H34: Claim free listing | I34: Not started
A35: 19 | B35: MapQuest | C35: Maps | D35: Medium | E35: https://www.mapquest.com | F35: To verify | H35: Check NAP | I35: Not started
A36: 20 | B36: Foursquare | C36: Data aggregator | D36: High | E36: https://foursquare.com/venue/claim | F36: To verify | G36: Feeds many apps and maps | H36: Claim and correct NAP | I36: Not started
A37: 21 | B37: Data Axle (Infogroup) | C37: Data aggregator | D37: High | E37: https://www.data-axle.com/our-data/business-data/business-listing/ | F37: To verify | H37: Submit NAP | I37: Not started
A38: 22 | B38: Neustar Localeze | C38: Data aggregator | D38: High | E38: https://www.neustarlocaleze.biz | F38: To verify | H38: Submit NAP | I38: Not started
A39: 23 | B39: Manta | C39: Directory | D39: Low | E39: https://www.manta.com | F39: To verify | H39: Claim free listing | I39: Not started
A40: 24 | B40: Hotfrog | C40: Directory | D40: Low | E40: https://www.hotfrog.com | F40: To verify | H40: Create free listing | I40: Not started
A41: 25 | B41: Brownbook | C41: Directory | D41: Low | E41: https://www.brownbook.net | F41: To verify | H41: Create free listing | I41: Not started
A42: 26 | B42: EZlocal | C42: Directory | D42: Low | E42: https://www.ezlocal.com | F42: To verify | H42: Create free listing | I42: Not started
...

Sheet QA Cross-Check
A1: QA cross-check (automatic)
A2: Formulas re-check every post when copy or links change. Every row should read Pass before scheduling.
A4: Post ID | B4: Max 1,500 chars | C4: No phone number in text | D4: No email in text | E4: No link in text | F4: CTA button set | G4: UTM on CTA link | H4: Link on business website | I4: Offer title max 58 chars | J4: Category set | K4: Overall
A5: ='Content Calendar'!A5 -> PF-01 | B5: =IF(LEN('Content Calendar'!J5)<=1500,"Pass","Fail") -> Pass | C5: =IF(SUMPRODUCT(--ISNUMBER(SEARCH({"405","921-3426","473-2695","9213426"},'Content Calendar'!J5)))=0,"Pass","Fail") -> Pass | D5: =IF(ISNUMBER(SEARCH("@",'Content Calendar'!J5)),"Fail","Pass") -> Pass | E5: =IF(OR(ISNUMBER(SEARCH("http",'Content Calendar'!J5)),ISNUMBER(SEARCH("www.",'Content Calendar'!J5)),ISNUMBER(SEARCH(".com",'Content Calendar'!J5))),"Fail","Pass") -> Pass | F5: =IF(LEN('Content Calendar'!L5)>0,"Pass","Fail") -> Pass | G5: =IF(AND(ISNUMBER(SEARCH("utm_source=google",'Content Calendar'!O5)),ISNUMBER(SEARCH("utm_content=",'Content Calendar'!O5))),"Pass","Fail") -> Pass | H5: =IF(ISNUMBER(SEARCH(Overview!$B$23,'Content Calendar'!M5)),"Pass","Fail") -> Pass | I5: =IF('Content Calendar'!F5="Offer",IF(AND(LEN('Content Calendar'!I5)>0,LEN('Content Calendar'!I5)<=58),"Pass","Fail"),"N/A") -> N/A | J5: =IF(OR('Content Calendar'!E5="Service",'Content Calendar'!E5="FAQ",'Content Calendar'!E5="Local",'Content Calendar'!E5="Promotional"),"Pass","Fail") -> Pass | K5: =IF(COUNTIF(B5:J5,"Fail")=0,"Pass","Fail") -> Pass
A6: ='Content Calendar'!A6 -> PF-02 | B6: =IF(LEN('Content Calendar'!J6)<=1500,"Pass","Fail") -> Pass | C6: =IF(SUMPRODUCT(--ISNUMBER(SEARCH({"405","921-3426","473-2695","9213426"},'Content Calendar'!J6)))=0,"Pass","Fail") -> Pass | D6: =IF(ISNUMBER(SEARCH("@",'Content Calendar'!J6)),"Fail","Pass") -> Pass | E6: =IF(OR(ISNUMBER(SEARCH("http",'Content Calendar'!J6)),ISNUMBER(SEARCH("www.",'Content Calendar'!J6)),ISNUMBER(SEARCH(".com",'Content Calendar'!J6))),"Fail","Pass") -> Pass | F6: =IF(LEN('Content Calendar'!L6)>0,"Pass","Fail") -> Pass | G6: =IF(AND(ISNUMBER(SEARCH("utm_source=google",'Content Calendar'!O6)),ISNUMBER(SEARCH("utm_content=",'Content Calendar'!O6))),"Pass","Fail") -> Pass | H6: =IF(ISNUMBER(SEARCH(Overview!$B$23,'Content Calendar'!M6)),"Pass","Fail") -> Pass | I6: =IF('Content Calendar'!F6="Offer",IF(AND(LEN('Content Calendar'!I6)>0,LEN('Content Calendar'!I6)<=58),"Pass","Fail"),"N/A") -> N/A | J6: =IF(OR('Content Calendar'!E6="Service",'Content Calendar'!E6="FAQ",'Content Calendar'!E6="Local",'Content Calendar'!E6="Promotional"),"Pass","Fail") -> Pass | K6: =IF(COUNTIF(B6:J6,"Fail")=0,"Pass","Fail") -> Pass
A7: ='Content Calendar'!A7 -> PF-03 | B7: =IF(LEN('Content Calendar'!J7)<=1500,"Pass","Fail") -> Pass | C7: =IF(SUMPRODUCT(--ISNUMBER(SEARCH({"405","921-3426","473-2695","9213426"},'Content Calendar'!J7)))=0,"Pass","Fail") -> Pass | D7: =IF(ISNUMBER(SEARCH("@",'Content Calendar'!J7)),"Fail","Pass") -> Pass | E7: =IF(OR(ISNUMBER(SEARCH("http",'Content Calendar'!J7)),ISNUMBER(SEARCH("www.",'Content Calendar'!J7)),ISNUMBER(SEARCH(".com",'Content Calendar'!J7))),"Fail","Pass") -> Pass | F7: =IF(LEN('Content Calendar'!L7)>0,"Pass","Fail") -> Pass | G7: =IF(AND(ISNUMBER(SEARCH("utm_source=google",'Content Calendar'!O7)),ISNUMBER(SEARCH("utm_content=",'Content Calendar'!O7))),"Pass","Fail") -> Pass | H7: =IF(ISNUMBER(SEARCH(Overview!$B$23,'Content Calendar'!M7)),"Pass","Fail") -> Pass | I7: =IF('Content Calendar'!F7="Offer",IF(AND(LEN('Content Calendar'!I7)>0,LEN('Content Calendar'!I7)<=58),"Pass","Fail"),"N/A") -> N/A | J7: =IF(OR('Content Calendar'!E7="Service",'Content Calendar'!E7="FAQ",'Content Calendar'!E7="Local",'Content Calendar'!E7="Promotional"),"Pass","Fail") -> Pass | K7: =IF(COUNTIF(B7:J7,"Fail")=0,"Pass","Fail") -> Pass
A8: ='Content Calendar'!A8 -> PF-04 | B8: =IF(LEN('Content Calendar'!J8)<=1500,"Pass","Fail") -> Pass | C8: =IF(SUMPRODUCT(--ISNUMBER(SEARCH({"405","921-3426","473-2695","9213426"},'Content Calendar'!J8)))=0,"Pass","Fail") -> Pass | D8: =IF(ISNUMBER(SEARCH("@",'Content Calendar'!J8)),"Fail","Pass") -> Pass | E8: =IF(OR(ISNUMBER(SEARCH("http",'Content Calendar'!J8)),ISNUMBER(SEARCH("www.",'Content Calendar'!J8)),ISNUMBER(SEARCH(".com",'Content Calendar'!J8))),"Fail","Pass") -> Pass | F8: =IF(LEN('Content Calendar'!L8)>0,"Pass","Fail") -> Pass | G8: =IF(AND(ISNUMBER(SEARCH("utm_source=google",'Content Calendar'!O8)),ISNUMBER(SEARCH("utm_content=",'Content Calendar'!O8))),"Pass","Fail") -> Pass | H8: =IF(ISNUMBER(SEARCH(Overview!$B$23,'Content Calendar'!M8)),"Pass","Fail") -> Pass | I8: =IF('Content Calendar'!F8="Offer",IF(AND(LEN('Content Calendar'!I8)>0,LEN('Content Calendar'!I8)<=58),"Pass","Fail"),"N/A") -> Pass | J8: =IF(OR('Content Calendar'!E8="Service",'Content Calendar'!E8="FAQ",'Content Calendar'!E8="Local",'Content Calendar'!E8="Promotional"),"Pass","Fail") -> Pass | K8: =IF(COUNTIF(B8:J8,"Fail")=0,"Pass","Fail") -> Pass
A9: ='Content Calendar'!A9 -> PF-05 | B9: =IF(LEN('Content Calendar'!J9)<=1500,"Pass","Fail") -> Pass | C9: =IF(SUMPRODUCT(--ISNUMBER(SEARCH({"405","921-3426","473-2695","9213426"},'Content Calendar'!J9)))=0,"Pass","Fail") -> Pass | D9: =IF(ISNUMBER(SEARCH("@",'Content Calendar'!J9)),"Fail","Pass") -> Pass | E9: =IF(OR(ISNUMBER(SEARCH("http",'Content Calendar'!J9)),ISNUMBER(SEARCH("www.",'Content Calendar'!J9)),ISNUMBER(SEARCH(".com",'Content Calendar'!J9))),"Fail","Pass") -> Pass | F9: =IF(LEN('Content Calendar'!L9)>0,"Pass","Fail") -> Pass | G9: =IF(AND(ISNUMBER(SEARCH("utm_source=google",'Content Calendar'!O9)),ISNUMBER(SEARCH("utm_content=",'Content Calendar'!O9))),"Pass","Fail") -> Pass | H9: =IF(ISNUMBER(SEARCH(Overview!$B$23,'Content Calendar'!M9)),"Pass","Fail") -> Pass | I9: =IF('Content Calendar'!F9="Offer",IF(AND(LEN('Content Calendar'!I9)>0,LEN('Content Calendar'!I9)<=58),"Pass","Fail"),"N/A") -> N/A | J9: =IF(OR('Content Calendar'!E9="Service",'Content Calendar'!E9="FAQ",'Content Calendar'!E9="Local",'Content Calendar'!E9="Promotional"),"Pass","Fail") -> Pass | K9: =IF(COUNTIF(B9:J9,"Fail")=0,"Pass","Fail") -> Pass
A10: ='Content Calendar'!A10 -> PF-06 | B10: =IF(LEN('Content Calendar'!J10)<=1500,"Pass","Fail") -> Pass | C10: =IF(SUMPRODUCT(--ISNUMBER(SEARCH({"405","921-3426","473-2695","9213426"},'Content Calendar'!J10)))=0,"Pass","Fail") -> Pass | D10: =IF(ISNUMBER(SEARCH("@",'Content Calendar'!J10)),"Fail","Pass") -> Pass | E10: =IF(OR(ISNUMBER(SEARCH("http",'Content Calendar'!J10)),ISNUMBER(SEARCH("www.",'Content Calendar'!J10)),ISNUMBER(SEARCH(".com",'Content Calendar'!J10))),"Fail","Pass") -> Pass | F10: =IF(LEN('Content Calendar'!L10)>0,"Pass","Fail") -> Pass | G10: =IF(AND(ISNUMBER(SEARCH("utm_source=google",'Content Calendar'!O10)),ISNUMBER(SEARCH("utm_content=",'Content Calendar'!O10))),"Pass","Fail") -> Pass | H10: =IF(ISNUMBER(SEARCH(Overview!$B$23,'Content Calendar'!M10)),"Pass","Fail") -> Pass | I10: =IF('Content Calendar'!F10="Offer",IF(AND(LEN('Content Calendar'!I10)>0,LEN('Content Calendar'!I10)<=58),"Pass","Fail"),"N/A") -> N/A | J10: =IF(OR('Content Calendar'!E10="Service",'Content Calendar'!E10="FAQ",'Content Calendar'!E10="Local",'Content Calendar'!E10="Promotional"),"Pass","Fail") -> Pass | K10: =IF(COUNTIF(B10:J10,"Fail")=0,"Pass","Fail") -> Pass
A11: ='Content Calendar'!A11 -> PF-07 | B11: =IF(LEN('Content Calendar'!J11)<=1500,"Pass","Fail") -> Pass | C11: =IF(SUMPRODUCT(--ISNUMBER(SEARCH({"405","921-3426","473-2695","9213426"},'Content Calendar'!J11)))=0,"Pass","Fail") -> Pass | D11: =IF(ISNUMBER(SEARCH("@",'Content Calendar'!J11)),"Fail","Pass") -> Pass | E11: =IF(OR(ISNUMBER(SEARCH("http",'Content Calendar'!J11)),ISNUMBER(SEARCH("www.",'Content Calendar'!J11)),ISNUMBER(SEARCH(".com",'Content Calendar'!J11))),"Fail","Pass") -> Pass | F11: =IF(LEN('Content Calendar'!L11)>0,"Pass","Fail") -> Pass | G11: =IF(AND(ISNUMBER(SEARCH("utm_source=google",'Content Calendar'!O11)),ISNUMBER(SEARCH("utm_content=",'Content Calendar'!O11))),"Pass","Fail") -> Pass | H11: =IF(ISNUMBER(SEARCH(Overview!$B$23,'Content Calendar'!M11)),"Pass","Fail") -> Pass | I11: =IF('Content Calendar'!F11="Offer",IF(AND(LEN('Content Calendar'!I11)>0,LEN('Content Calendar'!I11)<=58),"Pass","Fail"),"N/A") -> N/A | J11: =IF(OR('Content Calendar'!E11="Service",'Content Calendar'!E11="FAQ",'Content Calendar'!E11="Local",'Content Calendar'!E11="Promotional"),"Pass","Fail") -> Pass | K11: =IF(COUNTIF(B11:J11,"Fail")=0,"Pass","Fail") -> Pass
A12: ='Content Calendar'!A12 -> PF-08 | B12: =IF(LEN('Content Calendar'!J12)<=1500,"Pass","Fail") -> Pass | C12: =IF(SUMPRODUCT(--ISNUMBER(SEARCH({"405","921-3426","473-2695","9213426"},'Content Calendar'!J12)))=0,"Pass","Fail") -> Pass | D12: =IF(ISNUMBER(SEARCH("@",'Content Calendar'!J12)),"Fail","Pass") -> Pass | E12: =IF(OR(ISNUMBER(SEARCH("http",'Content Calendar'!J12)),ISNUMBER(SEARCH("www.",'Content Calendar'!J12)),ISNUMBER(SEARCH(".com",'Content Calendar'!J12))),"Fail","Pass") -> Pass | F12: =IF(LEN('Content Calendar'!L12)>0,"Pass","Fail") -> Pass | G12: =IF(AND(ISNUMBER(SEARCH("utm_source=google",'Content Calendar'!O12)),ISNUMBER(SEARCH("utm_content=",'Content Calendar'!O12))),"Pass","Fail") -> Pass | H12: =IF(ISNUMBER(SEARCH(Overview!$B$23,'Content Calendar'!M12)),"Pass","Fail") -> Pass | I12: =IF('Content Calendar'!F12="Offer",IF(AND(LEN('Content Calendar'!I12)>0,LEN('Content Calendar'!I12)<=58),"Pass","Fail"),"N/A") -> N/A | J12: =IF(OR('Content Calendar'!E12="Service",'Content Calendar'!E12="FAQ",'Content Calendar'!E12="Local",'Content Calendar'!E12="Promotional"),"Pass","Fail") -> Pass | K12: =IF(COUNTIF(B12:J12,"Fail")=0,"Pass","Fail") -> Pass
